2023-08-03 16:18:00 ERROR An error occurred: JSON parse error - Expecting ',' delimiter: line 8 column 5 (char 192)
2023-08-03 16:18:00 ERROR Internal Server Error: /user/
2023-08-03 16:18:00 ERROR "POST /user/ HTTP/1.1" 500 49
2023-08-03 16:18:00 ERROR "POST /user/ HTTP/1.1" 500 49
2023-08-03 16:20:55 ERROR An error occurred: JSON parse error - Expecting ',' delimiter: line 8 column 5 (char 192)
2023-08-03 16:20:55 ERROR Internal Server Error: /user/
2023-08-03 16:20:55 ERROR "POST /user/ HTTP/1.1" 500 49
2023-08-03 18:05:01 ERROR password and confirm password must be same , please check it and try again
2023-08-03 19:18:11 ERROR Internal Server Error: /get_orm_foreignKey_relation/
Traceback (most recent call last):
  File "/home/aakash/PROJECTS/LOGIN_AUTHENTICATION/myenv/lib/python3.8/site-packages/django/db/models/sql/query.py", line 2150, in add_fields
    join_info = self.setup_joins(
  File "/home/aakash/PROJECTS/LOGIN_AUTHENTICATION/myenv/lib/python3.8/site-packages/django/db/models/sql/query.py", line 1812, in setup_joins
    path, final_field, targets, rest = self.names_to_path(
  File "/home/aakash/PROJECTS/LOGIN_AUTHENTICATION/myenv/lib/python3.8/site-packages/django/db/models/sql/query.py", line 1713, in names_to_path
    raise FieldError(
django.core.exceptions.FieldError: Cannot resolve keyword 'dep_count' into field. Choices are: departments, id, university_name

During handling of the above exception, another exception occurred:

Traceback (most recent call last):
  File "/home/aakash/PROJECTS/LOGIN_AUTHENTICATION/myenv/lib/python3.8/site-packages/django/core/handlers/exception.py", line 55, in inner
    response = get_response(request)
  File "/home/aakash/PROJECTS/LOGIN_AUTHENTICATION/myenv/lib/python3.8/site-packages/django/core/handlers/base.py", line 197, in _get_response
    response = wrapped_callback(request, *callback_args, **callback_kwargs)
  File "/home/aakash/PROJECTS/LOGIN_AUTHENTICATION/myenv/lib/python3.8/site-packages/django/views/decorators/csrf.py", line 56, in wrapper_view
    return view_func(*args, **kwargs)
  File "/home/aakash/PROJECTS/LOGIN_AUTHENTICATION/myenv/lib/python3.8/site-packages/django/views/generic/base.py", line 104, in view
    return self.dispatch(request, *args, **kwargs)
  File "/home/aakash/PROJECTS/LOGIN_AUTHENTICATION/myenv/lib/python3.8/site-packages/rest_framework/views.py", line 509, in dispatch
    response = self.handle_exception(exc)
  File "/home/aakash/PROJECTS/LOGIN_AUTHENTICATION/myenv/lib/python3.8/site-packages/rest_framework/views.py", line 469, in handle_exception
    self.raise_uncaught_exception(exc)
  File "/home/aakash/PROJECTS/LOGIN_AUTHENTICATION/myenv/lib/python3.8/site-packages/rest_framework/views.py", line 480, in raise_uncaught_exception
    raise exc
  File "/home/aakash/PROJECTS/LOGIN_AUTHENTICATION/myenv/lib/python3.8/site-packages/rest_framework/views.py", line 506, in dispatch
    response = handler(request, *args, **kwargs)
  File "/home/aakash/PROJECTS/LOGIN_AUTHENTICATION/Authentication_System/myapp/views.py", line 1141, in get
    universities_with_depsrtments_with_all_students = University.objects.all().annotate(dept_count=Count('departments'), total_stu=Sum('departments__students')).values('university_name', 'dep_count','departments__students')
  File "/home/aakash/PROJECTS/LOGIN_AUTHENTICATION/myenv/lib/python3.8/site-packages/django/db/models/query.py", line 1313, in values
    clone = self._values(*fields, **expressions)
  File "/home/aakash/PROJECTS/LOGIN_AUTHENTICATION/myenv/lib/python3.8/site-packages/django/db/models/query.py", line 1308, in _values
    clone.query.set_values(fields)
  File "/home/aakash/PROJECTS/LOGIN_AUTHENTICATION/myenv/lib/python3.8/site-packages/django/db/models/sql/query.py", line 2449, in set_values
    self.add_fields(field_names, True)
  File "/home/aakash/PROJECTS/LOGIN_AUTHENTICATION/myenv/lib/python3.8/site-packages/django/db/models/sql/query.py", line 2183, in add_fields
    raise FieldError(
django.core.exceptions.FieldError: Cannot resolve keyword 'dep_count' into field. Choices are: departments, id, university_name
2023-08-03 19:18:11 ERROR "GET /get_orm_foreignKey_relation/ HTTP/1.1" 500 144540
2023-08-03 19:25:44 ERROR Internal Server Error: /get_orm_foreignKey_relation/
Traceback (most recent call last):
  File "/home/aakash/PROJECTS/LOGIN_AUTHENTICATION/myenv/lib/python3.8/site-packages/django/core/handlers/exception.py", line 55, in inner
    response = get_response(request)
  File "/home/aakash/PROJECTS/LOGIN_AUTHENTICATION/myenv/lib/python3.8/site-packages/django/core/handlers/base.py", line 197, in _get_response
    response = wrapped_callback(request, *callback_args, **callback_kwargs)
  File "/home/aakash/PROJECTS/LOGIN_AUTHENTICATION/myenv/lib/python3.8/site-packages/django/views/decorators/csrf.py", line 56, in wrapper_view
    return view_func(*args, **kwargs)
  File "/home/aakash/PROJECTS/LOGIN_AUTHENTICATION/myenv/lib/python3.8/site-packages/django/views/generic/base.py", line 104, in view
    return self.dispatch(request, *args, **kwargs)
  File "/home/aakash/PROJECTS/LOGIN_AUTHENTICATION/myenv/lib/python3.8/site-packages/rest_framework/views.py", line 509, in dispatch
    response = self.handle_exception(exc)
  File "/home/aakash/PROJECTS/LOGIN_AUTHENTICATION/myenv/lib/python3.8/site-packages/rest_framework/views.py", line 469, in handle_exception
    self.raise_uncaught_exception(exc)
  File "/home/aakash/PROJECTS/LOGIN_AUTHENTICATION/myenv/lib/python3.8/site-packages/rest_framework/views.py", line 480, in raise_uncaught_exception
    raise exc
  File "/home/aakash/PROJECTS/LOGIN_AUTHENTICATION/myenv/lib/python3.8/site-packages/rest_framework/views.py", line 506, in dispatch
    response = handler(request, *args, **kwargs)
  File "/home/aakash/PROJECTS/LOGIN_AUTHENTICATION/Authentication_System/myapp/views.py", line 1148, in get
    print(no_of_DEPT.dep_count)
AttributeError: 'QuerySet' object has no attribute 'dep_count'
2023-08-03 19:25:44 ERROR "GET /get_orm_foreignKey_relation/ HTTP/1.1" 500 106848
