2023-08-03 16:18:00 ERROR An error occurred: JSON parse error - Expecting ',' delimiter: line 8 column 5 (char 192)
2023-08-03 16:18:00 ERROR Internal Server Error: /user/
2023-08-03 16:18:00 ERROR "POST /user/ HTTP/1.1" 500 49
2023-08-03 16:18:00 ERROR "POST /user/ HTTP/1.1" 500 49
2023-08-03 16:20:55 ERROR An error occurred: JSON parse error - Expecting ',' delimiter: line 8 column 5 (char 192)
2023-08-03 16:20:55 ERROR Internal Server Error: /user/
2023-08-03 16:20:55 ERROR "POST /user/ HTTP/1.1" 500 49
2023-08-03 18:05:01 ERROR password and confirm password must be same , please check it and try again
2023-08-03 19:18:11 ERROR Internal Server Error: /get_orm_foreignKey_relation/
Traceback (most recent call last):
  File "/home/aakash/PROJECTS/LOGIN_AUTHENTICATION/myenv/lib/python3.8/site-packages/django/db/models/sql/query.py", line 2150, in add_fields
    join_info = self.setup_joins(
  File "/home/aakash/PROJECTS/LOGIN_AUTHENTICATION/myenv/lib/python3.8/site-packages/django/db/models/sql/query.py", line 1812, in setup_joins
    path, final_field, targets, rest = self.names_to_path(
  File "/home/aakash/PROJECTS/LOGIN_AUTHENTICATION/myenv/lib/python3.8/site-packages/django/db/models/sql/query.py", line 1713, in names_to_path
    raise FieldError(
django.core.exceptions.FieldError: Cannot resolve keyword 'dep_count' into field. Choices are: departments, id, university_name

During handling of the above exception, another exception occurred:

Traceback (most recent call last):
  File "/home/aakash/PROJECTS/LOGIN_AUTHENTICATION/myenv/lib/python3.8/site-packages/django/core/handlers/exception.py", line 55, in inner
    response = get_response(request)
  File "/home/aakash/PROJECTS/LOGIN_AUTHENTICATION/myenv/lib/python3.8/site-packages/django/core/handlers/base.py", line 197, in _get_response
    response = wrapped_callback(request, *callback_args, **callback_kwargs)
  File "/home/aakash/PROJECTS/LOGIN_AUTHENTICATION/myenv/lib/python3.8/site-packages/django/views/decorators/csrf.py", line 56, in wrapper_view
    return view_func(*args, **kwargs)
  File "/home/aakash/PROJECTS/LOGIN_AUTHENTICATION/myenv/lib/python3.8/site-packages/django/views/generic/base.py", line 104, in view
    return self.dispatch(request, *args, **kwargs)
  File "/home/aakash/PROJECTS/LOGIN_AUTHENTICATION/myenv/lib/python3.8/site-packages/rest_framework/views.py", line 509, in dispatch
    response = self.handle_exception(exc)
  File "/home/aakash/PROJECTS/LOGIN_AUTHENTICATION/myenv/lib/python3.8/site-packages/rest_framework/views.py", line 469, in handle_exception
    self.raise_uncaught_exception(exc)
  File "/home/aakash/PROJECTS/LOGIN_AUTHENTICATION/myenv/lib/python3.8/site-packages/rest_framework/views.py", line 480, in raise_uncaught_exception
    raise exc
  File "/home/aakash/PROJECTS/LOGIN_AUTHENTICATION/myenv/lib/python3.8/site-packages/rest_framework/views.py", line 506, in dispatch
    response = handler(request, *args, **kwargs)
  File "/home/aakash/PROJECTS/LOGIN_AUTHENTICATION/Authentication_System/myapp/views.py", line 1141, in get
    universities_with_depsrtments_with_all_students = University.objects.all().annotate(dept_count=Count('departments'), total_stu=Sum('departments__students')).values('university_name', 'dep_count','departments__students')
  File "/home/aakash/PROJECTS/LOGIN_AUTHENTICATION/myenv/lib/python3.8/site-packages/django/db/models/query.py", line 1313, in values
    clone = self._values(*fields, **expressions)
  File "/home/aakash/PROJECTS/LOGIN_AUTHENTICATION/myenv/lib/python3.8/site-packages/django/db/models/query.py", line 1308, in _values
    clone.query.set_values(fields)
  File "/home/aakash/PROJECTS/LOGIN_AUTHENTICATION/myenv/lib/python3.8/site-packages/django/db/models/sql/query.py", line 2449, in set_values
    self.add_fields(field_names, True)
  File "/home/aakash/PROJECTS/LOGIN_AUTHENTICATION/myenv/lib/python3.8/site-packages/django/db/models/sql/query.py", line 2183, in add_fields
    raise FieldError(
django.core.exceptions.FieldError: Cannot resolve keyword 'dep_count' into field. Choices are: departments, id, university_name
2023-08-03 19:18:11 ERROR "GET /get_orm_foreignKey_relation/ HTTP/1.1" 500 144540
2023-08-03 19:25:44 ERROR Internal Server Error: /get_orm_foreignKey_relation/
Traceback (most recent call last):
  File "/home/aakash/PROJECTS/LOGIN_AUTHENTICATION/myenv/lib/python3.8/site-packages/django/core/handlers/exception.py", line 55, in inner
    response = get_response(request)
  File "/home/aakash/PROJECTS/LOGIN_AUTHENTICATION/myenv/lib/python3.8/site-packages/django/core/handlers/base.py", line 197, in _get_response
    response = wrapped_callback(request, *callback_args, **callback_kwargs)
  File "/home/aakash/PROJECTS/LOGIN_AUTHENTICATION/myenv/lib/python3.8/site-packages/django/views/decorators/csrf.py", line 56, in wrapper_view
    return view_func(*args, **kwargs)
  File "/home/aakash/PROJECTS/LOGIN_AUTHENTICATION/myenv/lib/python3.8/site-packages/django/views/generic/base.py", line 104, in view
    return self.dispatch(request, *args, **kwargs)
  File "/home/aakash/PROJECTS/LOGIN_AUTHENTICATION/myenv/lib/python3.8/site-packages/rest_framework/views.py", line 509, in dispatch
    response = self.handle_exception(exc)
  File "/home/aakash/PROJECTS/LOGIN_AUTHENTICATION/myenv/lib/python3.8/site-packages/rest_framework/views.py", line 469, in handle_exception
    self.raise_uncaught_exception(exc)
  File "/home/aakash/PROJECTS/LOGIN_AUTHENTICATION/myenv/lib/python3.8/site-packages/rest_framework/views.py", line 480, in raise_uncaught_exception
    raise exc
  File "/home/aakash/PROJECTS/LOGIN_AUTHENTICATION/myenv/lib/python3.8/site-packages/rest_framework/views.py", line 506, in dispatch
    response = handler(request, *args, **kwargs)
  File "/home/aakash/PROJECTS/LOGIN_AUTHENTICATION/Authentication_System/myapp/views.py", line 1148, in get
    print(no_of_DEPT.dep_count)
AttributeError: 'QuerySet' object has no attribute 'dep_count'
2023-08-03 19:25:44 ERROR "GET /get_orm_foreignKey_relation/ HTTP/1.1" 500 106848
2023-08-04 14:38:21 ERROR Internal Server Error: /get_orm_foreignKey_relation/
Traceback (most recent call last):
  File "/home/aakash/PROJECTS/LOGIN_AUTHENTICATION/myenv/lib/python3.8/site-packages/django/core/handlers/exception.py", line 55, in inner
    response = get_response(request)
  File "/home/aakash/PROJECTS/LOGIN_AUTHENTICATION/myenv/lib/python3.8/site-packages/django/core/handlers/base.py", line 197, in _get_response
    response = wrapped_callback(request, *callback_args, **callback_kwargs)
  File "/home/aakash/PROJECTS/LOGIN_AUTHENTICATION/myenv/lib/python3.8/site-packages/django/views/decorators/csrf.py", line 56, in wrapper_view
    return view_func(*args, **kwargs)
  File "/home/aakash/PROJECTS/LOGIN_AUTHENTICATION/myenv/lib/python3.8/site-packages/django/views/generic/base.py", line 104, in view
    return self.dispatch(request, *args, **kwargs)
  File "/home/aakash/PROJECTS/LOGIN_AUTHENTICATION/myenv/lib/python3.8/site-packages/rest_framework/views.py", line 509, in dispatch
    response = self.handle_exception(exc)
  File "/home/aakash/PROJECTS/LOGIN_AUTHENTICATION/myenv/lib/python3.8/site-packages/rest_framework/views.py", line 469, in handle_exception
    self.raise_uncaught_exception(exc)
  File "/home/aakash/PROJECTS/LOGIN_AUTHENTICATION/myenv/lib/python3.8/site-packages/rest_framework/views.py", line 480, in raise_uncaught_exception
    raise exc
  File "/home/aakash/PROJECTS/LOGIN_AUTHENTICATION/myenv/lib/python3.8/site-packages/rest_framework/views.py", line 506, in dispatch
    response = handler(request, *args, **kwargs)
  File "/home/aakash/PROJECTS/LOGIN_AUTHENTICATION/Authentication_System/myapp/views.py", line 1152, in get
    return JsonResponse(
  File "/home/aakash/PROJECTS/LOGIN_AUTHENTICATION/myenv/lib/python3.8/site-packages/django/http/response.py", line 731, in __init__
    data = json.dumps(data, cls=encoder, **json_dumps_params)
  File "/usr/lib/python3.8/json/__init__.py", line 234, in dumps
    return cls(
  File "/usr/lib/python3.8/json/encoder.py", line 199, in encode
    chunks = self.iterencode(o, _one_shot=True)
  File "/usr/lib/python3.8/json/encoder.py", line 257, in iterencode
    return _iterencode(o, 0)
  File "/home/aakash/PROJECTS/LOGIN_AUTHENTICATION/myenv/lib/python3.8/site-packages/django/core/serializers/json.py", line 106, in default
    return super().default(o)
  File "/usr/lib/python3.8/json/encoder.py", line 179, in default
    raise TypeError(f'Object of type {o.__class__.__name__} '
TypeError: Object of type QuerySet is not JSON serializable
2023-08-04 14:38:21 ERROR "GET /get_orm_foreignKey_relation/ HTTP/1.1" 500 156162
2023-08-04 15:14:30 ERROR Internal Server Error: /get_orm_foreignKey_relation/
Traceback (most recent call last):
  File "/home/aakash/PROJECTS/LOGIN_AUTHENTICATION/myenv/lib/python3.8/site-packages/django/db/models/sql/query.py", line 2150, in add_fields
    join_info = self.setup_joins(
  File "/home/aakash/PROJECTS/LOGIN_AUTHENTICATION/myenv/lib/python3.8/site-packages/django/db/models/sql/query.py", line 1812, in setup_joins
    path, final_field, targets, rest = self.names_to_path(
  File "/home/aakash/PROJECTS/LOGIN_AUTHENTICATION/myenv/lib/python3.8/site-packages/django/db/models/sql/query.py", line 1713, in names_to_path
    raise FieldError(
django.core.exceptions.FieldError: Cannot resolve keyword 'department_department_name' into field. Choices are: department, department_id, id, student_name

During handling of the above exception, another exception occurred:

Traceback (most recent call last):
  File "/home/aakash/PROJECTS/LOGIN_AUTHENTICATION/myenv/lib/python3.8/site-packages/django/core/handlers/exception.py", line 55, in inner
    response = get_response(request)
  File "/home/aakash/PROJECTS/LOGIN_AUTHENTICATION/myenv/lib/python3.8/site-packages/django/core/handlers/base.py", line 197, in _get_response
    response = wrapped_callback(request, *callback_args, **callback_kwargs)
  File "/home/aakash/PROJECTS/LOGIN_AUTHENTICATION/myenv/lib/python3.8/site-packages/django/views/decorators/csrf.py", line 56, in wrapper_view
    return view_func(*args, **kwargs)
  File "/home/aakash/PROJECTS/LOGIN_AUTHENTICATION/myenv/lib/python3.8/site-packages/django/views/generic/base.py", line 104, in view
    return self.dispatch(request, *args, **kwargs)
  File "/home/aakash/PROJECTS/LOGIN_AUTHENTICATION/myenv/lib/python3.8/site-packages/rest_framework/views.py", line 509, in dispatch
    response = self.handle_exception(exc)
  File "/home/aakash/PROJECTS/LOGIN_AUTHENTICATION/myenv/lib/python3.8/site-packages/rest_framework/views.py", line 469, in handle_exception
    self.raise_uncaught_exception(exc)
  File "/home/aakash/PROJECTS/LOGIN_AUTHENTICATION/myenv/lib/python3.8/site-packages/rest_framework/views.py", line 480, in raise_uncaught_exception
    raise exc
  File "/home/aakash/PROJECTS/LOGIN_AUTHENTICATION/myenv/lib/python3.8/site-packages/rest_framework/views.py", line 506, in dispatch
    response = handler(request, *args, **kwargs)
  File "/home/aakash/PROJECTS/LOGIN_AUTHENTICATION/Authentication_System/myapp/views.py", line 1159, in get
    students_with_respective_dept_name = Student.objects.all().values('student_name', 'department_department_name')
  File "/home/aakash/PROJECTS/LOGIN_AUTHENTICATION/myenv/lib/python3.8/site-packages/django/db/models/query.py", line 1313, in values
    clone = self._values(*fields, **expressions)
  File "/home/aakash/PROJECTS/LOGIN_AUTHENTICATION/myenv/lib/python3.8/site-packages/django/db/models/query.py", line 1308, in _values
    clone.query.set_values(fields)
  File "/home/aakash/PROJECTS/LOGIN_AUTHENTICATION/myenv/lib/python3.8/site-packages/django/db/models/sql/query.py", line 2449, in set_values
    self.add_fields(field_names, True)
  File "/home/aakash/PROJECTS/LOGIN_AUTHENTICATION/myenv/lib/python3.8/site-packages/django/db/models/sql/query.py", line 2183, in add_fields
    raise FieldError(
django.core.exceptions.FieldError: Cannot resolve keyword 'department_department_name' into field. Choices are: department, department_id, id, student_name
2023-08-04 15:14:30 ERROR "GET /get_orm_foreignKey_relation/ HTTP/1.1" 500 146499
2023-08-04 17:53:09 ERROR Internal Server Error: /get_orm_foreignKey_relation/
Traceback (most recent call last):
  File "/home/aakash/PROJECTS/LOGIN_AUTHENTICATION/myenv/lib/python3.8/site-packages/django/db/models/sql/query.py", line 1835, in transform
    return self.try_transform(wrapped, name)
  File "/home/aakash/PROJECTS/LOGIN_AUTHENTICATION/myenv/lib/python3.8/site-packages/django/db/models/sql/query.py", line 1345, in try_transform
    raise FieldError(
django.core.exceptions.FieldError: Unsupported lookup 'university_nam' for BigAutoField or join on the field not permitted.

During handling of the above exception, another exception occurred:

Traceback (most recent call last):
  File "/home/aakash/PROJECTS/LOGIN_AUTHENTICATION/myenv/lib/python3.8/site-packages/django/core/handlers/exception.py", line 55, in inner
    response = get_response(request)
  File "/home/aakash/PROJECTS/LOGIN_AUTHENTICATION/myenv/lib/python3.8/site-packages/django/core/handlers/base.py", line 197, in _get_response
    response = wrapped_callback(request, *callback_args, **callback_kwargs)
  File "/home/aakash/PROJECTS/LOGIN_AUTHENTICATION/myenv/lib/python3.8/site-packages/django/views/decorators/csrf.py", line 56, in wrapper_view
    return view_func(*args, **kwargs)
  File "/home/aakash/PROJECTS/LOGIN_AUTHENTICATION/myenv/lib/python3.8/site-packages/django/views/generic/base.py", line 104, in view
    return self.dispatch(request, *args, **kwargs)
  File "/home/aakash/PROJECTS/LOGIN_AUTHENTICATION/myenv/lib/python3.8/site-packages/rest_framework/views.py", line 509, in dispatch
    response = self.handle_exception(exc)
  File "/home/aakash/PROJECTS/LOGIN_AUTHENTICATION/myenv/lib/python3.8/site-packages/rest_framework/views.py", line 469, in handle_exception
    self.raise_uncaught_exception(exc)
  File "/home/aakash/PROJECTS/LOGIN_AUTHENTICATION/myenv/lib/python3.8/site-packages/rest_framework/views.py", line 480, in raise_uncaught_exception
    raise exc
  File "/home/aakash/PROJECTS/LOGIN_AUTHENTICATION/myenv/lib/python3.8/site-packages/rest_framework/views.py", line 506, in dispatch
    response = handler(request, *args, **kwargs)
  File "/home/aakash/PROJECTS/LOGIN_AUTHENTICATION/Authentication_System/myapp/views.py", line 1170, in get
    university_of_specific_student_2 = Student.objects.filter(student_name='Akash Kashyap').values('student_name', 'department__university__university_nam')
  File "/home/aakash/PROJECTS/LOGIN_AUTHENTICATION/myenv/lib/python3.8/site-packages/django/db/models/query.py", line 1313, in values
    clone = self._values(*fields, **expressions)
  File "/home/aakash/PROJECTS/LOGIN_AUTHENTICATION/myenv/lib/python3.8/site-packages/django/db/models/query.py", line 1308, in _values
    clone.query.set_values(fields)
  File "/home/aakash/PROJECTS/LOGIN_AUTHENTICATION/myenv/lib/python3.8/site-packages/django/db/models/sql/query.py", line 2449, in set_values
    self.add_fields(field_names, True)
  File "/home/aakash/PROJECTS/LOGIN_AUTHENTICATION/myenv/lib/python3.8/site-packages/django/db/models/sql/query.py", line 2159, in add_fields
    cols.append(join_info.transform_function(target, final_alias))
  File "/home/aakash/PROJECTS/LOGIN_AUTHENTICATION/myenv/lib/python3.8/site-packages/django/db/models/sql/query.py", line 1839, in transform
    raise last_field_exception
  File "/home/aakash/PROJECTS/LOGIN_AUTHENTICATION/myenv/lib/python3.8/site-packages/django/db/models/sql/query.py", line 1812, in setup_joins
    path, final_field, targets, rest = self.names_to_path(
  File "/home/aakash/PROJECTS/LOGIN_AUTHENTICATION/myenv/lib/python3.8/site-packages/django/db/models/sql/query.py", line 1713, in names_to_path
    raise FieldError(
django.core.exceptions.FieldError: Cannot resolve keyword 'university_nam' into field. Choices are: departments, id, university_name
2023-08-04 17:53:09 ERROR "GET /get_orm_foreignKey_relation/ HTTP/1.1" 500 164599
2023-08-04 17:57:33 ERROR Internal Server Error: /get_orm_foreignKey_relation/
Traceback (most recent call last):
  File "/home/aakash/PROJECTS/LOGIN_AUTHENTICATION/myenv/lib/python3.8/site-packages/django/core/handlers/exception.py", line 55, in inner
    response = get_response(request)
  File "/home/aakash/PROJECTS/LOGIN_AUTHENTICATION/myenv/lib/python3.8/site-packages/django/core/handlers/base.py", line 197, in _get_response
    response = wrapped_callback(request, *callback_args, **callback_kwargs)
  File "/home/aakash/PROJECTS/LOGIN_AUTHENTICATION/myenv/lib/python3.8/site-packages/django/views/decorators/csrf.py", line 56, in wrapper_view
    return view_func(*args, **kwargs)
  File "/home/aakash/PROJECTS/LOGIN_AUTHENTICATION/myenv/lib/python3.8/site-packages/django/views/generic/base.py", line 104, in view
    return self.dispatch(request, *args, **kwargs)
  File "/home/aakash/PROJECTS/LOGIN_AUTHENTICATION/myenv/lib/python3.8/site-packages/rest_framework/views.py", line 509, in dispatch
    response = self.handle_exception(exc)
  File "/home/aakash/PROJECTS/LOGIN_AUTHENTICATION/myenv/lib/python3.8/site-packages/rest_framework/views.py", line 469, in handle_exception
    self.raise_uncaught_exception(exc)
  File "/home/aakash/PROJECTS/LOGIN_AUTHENTICATION/myenv/lib/python3.8/site-packages/rest_framework/views.py", line 480, in raise_uncaught_exception
    raise exc
  File "/home/aakash/PROJECTS/LOGIN_AUTHENTICATION/myenv/lib/python3.8/site-packages/rest_framework/views.py", line 506, in dispatch
    response = handler(request, *args, **kwargs)
  File "/home/aakash/PROJECTS/LOGIN_AUTHENTICATION/Authentication_System/myapp/views.py", line 1172, in get
    return JsonResponse(
  File "/home/aakash/PROJECTS/LOGIN_AUTHENTICATION/myenv/lib/python3.8/site-packages/django/http/response.py", line 731, in __init__
    data = json.dumps(data, cls=encoder, **json_dumps_params)
  File "/usr/lib/python3.8/json/__init__.py", line 234, in dumps
    return cls(
  File "/usr/lib/python3.8/json/encoder.py", line 199, in encode
    chunks = self.iterencode(o, _one_shot=True)
  File "/usr/lib/python3.8/json/encoder.py", line 257, in iterencode
    return _iterencode(o, 0)
  File "/home/aakash/PROJECTS/LOGIN_AUTHENTICATION/myenv/lib/python3.8/site-packages/django/core/serializers/json.py", line 106, in default
    return super().default(o)
  File "/usr/lib/python3.8/json/encoder.py", line 179, in default
    raise TypeError(f'Object of type {o.__class__.__name__} '
TypeError: Object of type University is not JSON serializable
2023-08-04 17:57:33 ERROR "GET /get_orm_foreignKey_relation/ HTTP/1.1" 500 158787
2023-08-04 18:37:29 ERROR Internal Server Error: /get_orm_foreignKey_relation/
Traceback (most recent call last):
  File "/home/aakash/PROJECTS/LOGIN_AUTHENTICATION/myenv/lib/python3.8/site-packages/django/core/handlers/exception.py", line 55, in inner
    response = get_response(request)
  File "/home/aakash/PROJECTS/LOGIN_AUTHENTICATION/myenv/lib/python3.8/site-packages/django/core/handlers/base.py", line 197, in _get_response
    response = wrapped_callback(request, *callback_args, **callback_kwargs)
  File "/home/aakash/PROJECTS/LOGIN_AUTHENTICATION/myenv/lib/python3.8/site-packages/django/views/decorators/csrf.py", line 56, in wrapper_view
    return view_func(*args, **kwargs)
  File "/home/aakash/PROJECTS/LOGIN_AUTHENTICATION/myenv/lib/python3.8/site-packages/django/views/generic/base.py", line 104, in view
    return self.dispatch(request, *args, **kwargs)
  File "/home/aakash/PROJECTS/LOGIN_AUTHENTICATION/myenv/lib/python3.8/site-packages/rest_framework/views.py", line 509, in dispatch
    response = self.handle_exception(exc)
  File "/home/aakash/PROJECTS/LOGIN_AUTHENTICATION/myenv/lib/python3.8/site-packages/rest_framework/views.py", line 469, in handle_exception
    self.raise_uncaught_exception(exc)
  File "/home/aakash/PROJECTS/LOGIN_AUTHENTICATION/myenv/lib/python3.8/site-packages/rest_framework/views.py", line 480, in raise_uncaught_exception
    raise exc
  File "/home/aakash/PROJECTS/LOGIN_AUTHENTICATION/myenv/lib/python3.8/site-packages/rest_framework/views.py", line 506, in dispatch
    response = handler(request, *args, **kwargs)
  File "/home/aakash/PROJECTS/LOGIN_AUTHENTICATION/Authentication_System/myapp/views.py", line 1175, in get
    print(all_departments_with_university_names)
UnboundLocalError: local variable 'all_departments_with_university_names' referenced before assignment
2023-08-04 18:37:29 ERROR "GET /get_orm_foreignKey_relation/ HTTP/1.1" 500 110478
2023-08-04 20:11:46 ERROR Internal Server Error: /get_orm_foreignKey_relation/
Traceback (most recent call last):
  File "/home/aakash/PROJECTS/LOGIN_AUTHENTICATION/myenv/lib/python3.8/site-packages/django/core/handlers/exception.py", line 55, in inner
    response = get_response(request)
  File "/home/aakash/PROJECTS/LOGIN_AUTHENTICATION/myenv/lib/python3.8/site-packages/django/core/handlers/base.py", line 197, in _get_response
    response = wrapped_callback(request, *callback_args, **callback_kwargs)
  File "/home/aakash/PROJECTS/LOGIN_AUTHENTICATION/myenv/lib/python3.8/site-packages/django/views/decorators/csrf.py", line 56, in wrapper_view
    return view_func(*args, **kwargs)
  File "/home/aakash/PROJECTS/LOGIN_AUTHENTICATION/myenv/lib/python3.8/site-packages/django/views/generic/base.py", line 104, in view
    return self.dispatch(request, *args, **kwargs)
  File "/home/aakash/PROJECTS/LOGIN_AUTHENTICATION/myenv/lib/python3.8/site-packages/rest_framework/views.py", line 509, in dispatch
    response = self.handle_exception(exc)
  File "/home/aakash/PROJECTS/LOGIN_AUTHENTICATION/myenv/lib/python3.8/site-packages/rest_framework/views.py", line 469, in handle_exception
    self.raise_uncaught_exception(exc)
  File "/home/aakash/PROJECTS/LOGIN_AUTHENTICATION/myenv/lib/python3.8/site-packages/rest_framework/views.py", line 480, in raise_uncaught_exception
    raise exc
  File "/home/aakash/PROJECTS/LOGIN_AUTHENTICATION/myenv/lib/python3.8/site-packages/rest_framework/views.py", line 506, in dispatch
    response = handler(request, *args, **kwargs)
  File "/home/aakash/PROJECTS/LOGIN_AUTHENTICATION/Authentication_System/myapp/views.py", line 1180, in get
    all_students_of_specific_university = University.objects.get(university_name='Sri RamSwaroop Memorial University').values('departments__students__student_name')
  File "/home/aakash/PROJECTS/LOGIN_AUTHENTICATION/myenv/lib/python3.8/site-packages/django/db/models/manager.py", line 87, in manager_method
    return getattr(self.get_queryset(), name)(*args, **kwargs)
  File "/home/aakash/PROJECTS/LOGIN_AUTHENTICATION/myenv/lib/python3.8/site-packages/django/db/models/query.py", line 637, in get
    raise self.model.DoesNotExist(
myapp.models.University.DoesNotExist: University matching query does not exist.
2023-08-04 20:11:46 ERROR "GET /get_orm_foreignKey_relation/ HTTP/1.1" 500 121956
2023-08-04 20:12:18 ERROR Internal Server Error: /get_orm_foreignKey_relation/
Traceback (most recent call last):
  File "/home/aakash/PROJECTS/LOGIN_AUTHENTICATION/myenv/lib/python3.8/site-packages/django/core/handlers/exception.py", line 55, in inner
    response = get_response(request)
  File "/home/aakash/PROJECTS/LOGIN_AUTHENTICATION/myenv/lib/python3.8/site-packages/django/core/handlers/base.py", line 197, in _get_response
    response = wrapped_callback(request, *callback_args, **callback_kwargs)
  File "/home/aakash/PROJECTS/LOGIN_AUTHENTICATION/myenv/lib/python3.8/site-packages/django/views/decorators/csrf.py", line 56, in wrapper_view
    return view_func(*args, **kwargs)
  File "/home/aakash/PROJECTS/LOGIN_AUTHENTICATION/myenv/lib/python3.8/site-packages/django/views/generic/base.py", line 104, in view
    return self.dispatch(request, *args, **kwargs)
  File "/home/aakash/PROJECTS/LOGIN_AUTHENTICATION/myenv/lib/python3.8/site-packages/rest_framework/views.py", line 509, in dispatch
    response = self.handle_exception(exc)
  File "/home/aakash/PROJECTS/LOGIN_AUTHENTICATION/myenv/lib/python3.8/site-packages/rest_framework/views.py", line 469, in handle_exception
    self.raise_uncaught_exception(exc)
  File "/home/aakash/PROJECTS/LOGIN_AUTHENTICATION/myenv/lib/python3.8/site-packages/rest_framework/views.py", line 480, in raise_uncaught_exception
    raise exc
  File "/home/aakash/PROJECTS/LOGIN_AUTHENTICATION/myenv/lib/python3.8/site-packages/rest_framework/views.py", line 506, in dispatch
    response = handler(request, *args, **kwargs)
  File "/home/aakash/PROJECTS/LOGIN_AUTHENTICATION/Authentication_System/myapp/views.py", line 1180, in get
    all_students_of_specific_university = University.objects.get(university_name='Sri RamSwaroop Memorial University')
  File "/home/aakash/PROJECTS/LOGIN_AUTHENTICATION/myenv/lib/python3.8/site-packages/django/db/models/manager.py", line 87, in manager_method
    return getattr(self.get_queryset(), name)(*args, **kwargs)
  File "/home/aakash/PROJECTS/LOGIN_AUTHENTICATION/myenv/lib/python3.8/site-packages/django/db/models/query.py", line 637, in get
    raise self.model.DoesNotExist(
myapp.models.University.DoesNotExist: University matching query does not exist.
2023-08-04 20:12:18 ERROR "GET /get_orm_foreignKey_relation/ HTTP/1.1" 500 121844
2023-08-04 20:12:22 ERROR Internal Server Error: /get_orm_foreignKey_relation/
Traceback (most recent call last):
  File "/home/aakash/PROJECTS/LOGIN_AUTHENTICATION/myenv/lib/python3.8/site-packages/django/core/handlers/exception.py", line 55, in inner
    response = get_response(request)
  File "/home/aakash/PROJECTS/LOGIN_AUTHENTICATION/myenv/lib/python3.8/site-packages/django/core/handlers/base.py", line 197, in _get_response
    response = wrapped_callback(request, *callback_args, **callback_kwargs)
  File "/home/aakash/PROJECTS/LOGIN_AUTHENTICATION/myenv/lib/python3.8/site-packages/django/views/decorators/csrf.py", line 56, in wrapper_view
    return view_func(*args, **kwargs)
  File "/home/aakash/PROJECTS/LOGIN_AUTHENTICATION/myenv/lib/python3.8/site-packages/django/views/generic/base.py", line 104, in view
    return self.dispatch(request, *args, **kwargs)
  File "/home/aakash/PROJECTS/LOGIN_AUTHENTICATION/myenv/lib/python3.8/site-packages/rest_framework/views.py", line 509, in dispatch
    response = self.handle_exception(exc)
  File "/home/aakash/PROJECTS/LOGIN_AUTHENTICATION/myenv/lib/python3.8/site-packages/rest_framework/views.py", line 469, in handle_exception
    self.raise_uncaught_exception(exc)
  File "/home/aakash/PROJECTS/LOGIN_AUTHENTICATION/myenv/lib/python3.8/site-packages/rest_framework/views.py", line 480, in raise_uncaught_exception
    raise exc
  File "/home/aakash/PROJECTS/LOGIN_AUTHENTICATION/myenv/lib/python3.8/site-packages/rest_framework/views.py", line 506, in dispatch
    response = handler(request, *args, **kwargs)
  File "/home/aakash/PROJECTS/LOGIN_AUTHENTICATION/Authentication_System/myapp/views.py", line 1180, in get
    all_students_of_specific_university = University.objects.get(university_name='Sri RamSwaroop Memorial University')
  File "/home/aakash/PROJECTS/LOGIN_AUTHENTICATION/myenv/lib/python3.8/site-packages/django/db/models/manager.py", line 87, in manager_method
    return getattr(self.get_queryset(), name)(*args, **kwargs)
  File "/home/aakash/PROJECTS/LOGIN_AUTHENTICATION/myenv/lib/python3.8/site-packages/django/db/models/query.py", line 637, in get
    raise self.model.DoesNotExist(
myapp.models.University.DoesNotExist: University matching query does not exist.
2023-08-04 20:12:22 ERROR "GET /get_orm_foreignKey_relation/ HTTP/1.1" 500 121844
2023-08-04 20:13:41 ERROR Internal Server Error: /get_orm_foreignKey_relation/
Traceback (most recent call last):
  File "/home/aakash/PROJECTS/LOGIN_AUTHENTICATION/myenv/lib/python3.8/site-packages/django/core/handlers/exception.py", line 55, in inner
    response = get_response(request)
  File "/home/aakash/PROJECTS/LOGIN_AUTHENTICATION/myenv/lib/python3.8/site-packages/django/core/handlers/base.py", line 197, in _get_response
    response = wrapped_callback(request, *callback_args, **callback_kwargs)
  File "/home/aakash/PROJECTS/LOGIN_AUTHENTICATION/myenv/lib/python3.8/site-packages/django/views/decorators/csrf.py", line 56, in wrapper_view
    return view_func(*args, **kwargs)
  File "/home/aakash/PROJECTS/LOGIN_AUTHENTICATION/myenv/lib/python3.8/site-packages/django/views/generic/base.py", line 104, in view
    return self.dispatch(request, *args, **kwargs)
  File "/home/aakash/PROJECTS/LOGIN_AUTHENTICATION/myenv/lib/python3.8/site-packages/rest_framework/views.py", line 509, in dispatch
    response = self.handle_exception(exc)
  File "/home/aakash/PROJECTS/LOGIN_AUTHENTICATION/myenv/lib/python3.8/site-packages/rest_framework/views.py", line 469, in handle_exception
    self.raise_uncaught_exception(exc)
  File "/home/aakash/PROJECTS/LOGIN_AUTHENTICATION/myenv/lib/python3.8/site-packages/rest_framework/views.py", line 480, in raise_uncaught_exception
    raise exc
  File "/home/aakash/PROJECTS/LOGIN_AUTHENTICATION/myenv/lib/python3.8/site-packages/rest_framework/views.py", line 506, in dispatch
    response = handler(request, *args, **kwargs)
  File "/home/aakash/PROJECTS/LOGIN_AUTHENTICATION/Authentication_System/myapp/views.py", line 1180, in get
    all_students_of_specific_university = University.objects.get(university_name='Babu Banarsi Das University').values('departments__students__student_name')
AttributeError: 'University' object has no attribute 'values'
2023-08-04 20:13:41 ERROR "GET /get_orm_foreignKey_relation/ HTTP/1.1" 500 112861
2023-08-04 20:20:35 ERROR Internal Server Error: /get_orm_foreignKey_relation/
Traceback (most recent call last):
  File "/home/aakash/PROJECTS/LOGIN_AUTHENTICATION/myenv/lib/python3.8/site-packages/django/db/models/sql/query.py", line 1441, in build_filter
    join_info = self.setup_joins(
  File "/home/aakash/PROJECTS/LOGIN_AUTHENTICATION/myenv/lib/python3.8/site-packages/django/db/models/sql/query.py", line 1812, in setup_joins
    path, final_field, targets, rest = self.names_to_path(
  File "/home/aakash/PROJECTS/LOGIN_AUTHENTICATION/myenv/lib/python3.8/site-packages/django/db/models/sql/query.py", line 1737, in names_to_path
    raise MultiJoin(pos + 1, names_with_path)
django.db.models.sql.datastructures.MultiJoin: (1, [('departments', [PathInfo(from_opts=<Options for University>, to_opts=<Options for Department>, target_fields=(<django.db.models.fields.BigAutoField: id>,), join_field=<ManyToOneRel: myapp.department>, m2m=True, direct=False, filtered_relation=None)])])

During handling of the above exception, another exception occurred:

Traceback (most recent call last):
  File "/home/aakash/PROJECTS/LOGIN_AUTHENTICATION/myenv/lib/python3.8/site-packages/django/db/models/fields/__init__.py", line 2053, in get_prep_value
    return int(value)
ValueError: invalid literal for int() with base 10: 'None'

The above exception was the direct cause of the following exception:

Traceback (most recent call last):
  File "/home/aakash/PROJECTS/LOGIN_AUTHENTICATION/myenv/lib/python3.8/site-packages/django/core/handlers/exception.py", line 55, in inner
    response = get_response(request)
  File "/home/aakash/PROJECTS/LOGIN_AUTHENTICATION/myenv/lib/python3.8/site-packages/django/core/handlers/base.py", line 197, in _get_response
    response = wrapped_callback(request, *callback_args, **callback_kwargs)
  File "/home/aakash/PROJECTS/LOGIN_AUTHENTICATION/myenv/lib/python3.8/site-packages/django/views/decorators/csrf.py", line 56, in wrapper_view
    return view_func(*args, **kwargs)
  File "/home/aakash/PROJECTS/LOGIN_AUTHENTICATION/myenv/lib/python3.8/site-packages/django/views/generic/base.py", line 104, in view
    return self.dispatch(request, *args, **kwargs)
  File "/home/aakash/PROJECTS/LOGIN_AUTHENTICATION/myenv/lib/python3.8/site-packages/rest_framework/views.py", line 509, in dispatch
    response = self.handle_exception(exc)
  File "/home/aakash/PROJECTS/LOGIN_AUTHENTICATION/myenv/lib/python3.8/site-packages/rest_framework/views.py", line 469, in handle_exception
    self.raise_uncaught_exception(exc)
  File "/home/aakash/PROJECTS/LOGIN_AUTHENTICATION/myenv/lib/python3.8/site-packages/rest_framework/views.py", line 480, in raise_uncaught_exception
    raise exc
  File "/home/aakash/PROJECTS/LOGIN_AUTHENTICATION/myenv/lib/python3.8/site-packages/rest_framework/views.py", line 506, in dispatch
    response = handler(request, *args, **kwargs)
  File "/home/aakash/PROJECTS/LOGIN_AUTHENTICATION/Authentication_System/myapp/views.py", line 1180, in get
    all_students_of_specific_university = University.objects.filter(university_name='Babu Banarsi Das University').values('departments__students__student_name').exclude(departments__students='None')
  File "/home/aakash/PROJECTS/LOGIN_AUTHENTICATION/myenv/lib/python3.8/site-packages/django/db/models/query.py", line 1444, in exclude
    return self._filter_or_exclude(True, args, kwargs)
  File "/home/aakash/PROJECTS/LOGIN_AUTHENTICATION/myenv/lib/python3.8/site-packages/django/db/models/query.py", line 1454, in _filter_or_exclude
    clone._filter_or_exclude_inplace(negate, args, kwargs)
  File "/home/aakash/PROJECTS/LOGIN_AUTHENTICATION/myenv/lib/python3.8/site-packages/django/db/models/query.py", line 1459, in _filter_or_exclude_inplace
    self._query.add_q(~Q(*args, **kwargs))
  File "/home/aakash/PROJECTS/LOGIN_AUTHENTICATION/myenv/lib/python3.8/site-packages/django/db/models/sql/query.py", line 1534, in add_q
    clause, _ = self._add_q(q_object, self.used_aliases)
  File "/home/aakash/PROJECTS/LOGIN_AUTHENTICATION/myenv/lib/python3.8/site-packages/django/db/models/sql/query.py", line 1565, in _add_q
    child_clause, needed_inner = self.build_filter(
  File "/home/aakash/PROJECTS/LOGIN_AUTHENTICATION/myenv/lib/python3.8/site-packages/django/db/models/sql/query.py", line 1459, in build_filter
    return self.split_exclude(filter_expr, can_reuse, e.names_with_path)
  File "/home/aakash/PROJECTS/LOGIN_AUTHENTICATION/myenv/lib/python3.8/site-packages/django/db/models/sql/query.py", line 2013, in split_exclude
    query.add_filter(filter_lhs, filter_rhs)
  File "/home/aakash/PROJECTS/LOGIN_AUTHENTICATION/myenv/lib/python3.8/site-packages/django/db/models/sql/query.py", line 1518, in add_filter
    self.add_q(Q((filter_lhs, filter_rhs)))
  File "/home/aakash/PROJECTS/LOGIN_AUTHENTICATION/myenv/lib/python3.8/site-packages/django/db/models/sql/query.py", line 1534, in add_q
    clause, _ = self._add_q(q_object, self.used_aliases)
  File "/home/aakash/PROJECTS/LOGIN_AUTHENTICATION/myenv/lib/python3.8/site-packages/django/db/models/sql/query.py", line 1565, in _add_q
    child_clause, needed_inner = self.build_filter(
  File "/home/aakash/PROJECTS/LOGIN_AUTHENTICATION/myenv/lib/python3.8/site-packages/django/db/models/sql/query.py", line 1480, in build_filter
    condition = self.build_lookup(lookups, col, value)
  File "/home/aakash/PROJECTS/LOGIN_AUTHENTICATION/myenv/lib/python3.8/site-packages/django/db/models/sql/query.py", line 1307, in build_lookup
    lookup = lookup_class(lhs, rhs)
  File "/home/aakash/PROJECTS/LOGIN_AUTHENTICATION/myenv/lib/python3.8/site-packages/django/db/models/lookups.py", line 27, in __init__
    self.rhs = self.get_prep_lookup()
  File "/home/aakash/PROJECTS/LOGIN_AUTHENTICATION/myenv/lib/python3.8/site-packages/django/db/models/fields/related_lookups.py", line 166, in get_prep_lookup
    self.rhs = target_field.get_prep_value(self.rhs)
  File "/home/aakash/PROJECTS/LOGIN_AUTHENTICATION/myenv/lib/python3.8/site-packages/django/db/models/fields/__init__.py", line 2055, in get_prep_value
    raise e.__class__(
ValueError: Field 'id' expected a number but got 'None'.
2023-08-04 20:20:35 ERROR "GET /get_orm_foreignKey_relation/ HTTP/1.1" 500 217240
