2023-08-11 11:40:11 ERROR Internal Server Error: /update_developers_second_db/1/
Traceback (most recent call last):
  File "/home/aakash/PROJECTS/LOGIN_AUTHENTICATION/myenv/lib/python3.8/site-packages/django/core/handlers/exception.py", line 55, in inner
    response = get_response(request)
  File "/home/aakash/PROJECTS/LOGIN_AUTHENTICATION/myenv/lib/python3.8/site-packages/django/core/handlers/base.py", line 197, in _get_response
    response = wrapped_callback(request, *callback_args, **callback_kwargs)
  File "/home/aakash/PROJECTS/LOGIN_AUTHENTICATION/myenv/lib/python3.8/site-packages/django/views/decorators/csrf.py", line 56, in wrapper_view
    return view_func(*args, **kwargs)
  File "/home/aakash/PROJECTS/LOGIN_AUTHENTICATION/myenv/lib/python3.8/site-packages/django/views/generic/base.py", line 104, in view
    return self.dispatch(request, *args, **kwargs)
  File "/home/aakash/PROJECTS/LOGIN_AUTHENTICATION/myenv/lib/python3.8/site-packages/rest_framework/views.py", line 511, in dispatch
    self.response = self.finalize_response(request, response, *args, **kwargs)
  File "/home/aakash/PROJECTS/LOGIN_AUTHENTICATION/myenv/lib/python3.8/site-packages/rest_framework/views.py", line 423, in finalize_response
    assert isinstance(response, HttpResponseBase), (
AssertionError: Expected a `Response`, `HttpResponse` or `HttpStreamingResponse` to be returned from the view, but received a `<class 'NoneType'>`
2023-08-11 11:40:11 ERROR "PUT /update_developers_second_db/1/ HTTP/1.1" 500 82664
2023-08-11 11:40:38 ERROR Internal Server Error: /update_developers_second_db/1/
Traceback (most recent call last):
  File "/home/aakash/PROJECTS/LOGIN_AUTHENTICATION/myenv/lib/python3.8/site-packages/django/core/handlers/exception.py", line 55, in inner
    response = get_response(request)
  File "/home/aakash/PROJECTS/LOGIN_AUTHENTICATION/myenv/lib/python3.8/site-packages/django/core/handlers/base.py", line 197, in _get_response
    response = wrapped_callback(request, *callback_args, **callback_kwargs)
  File "/home/aakash/PROJECTS/LOGIN_AUTHENTICATION/myenv/lib/python3.8/site-packages/django/views/decorators/csrf.py", line 56, in wrapper_view
    return view_func(*args, **kwargs)
  File "/home/aakash/PROJECTS/LOGIN_AUTHENTICATION/myenv/lib/python3.8/site-packages/django/views/generic/base.py", line 104, in view
    return self.dispatch(request, *args, **kwargs)
  File "/home/aakash/PROJECTS/LOGIN_AUTHENTICATION/myenv/lib/python3.8/site-packages/rest_framework/views.py", line 511, in dispatch
    self.response = self.finalize_response(request, response, *args, **kwargs)
  File "/home/aakash/PROJECTS/LOGIN_AUTHENTICATION/myenv/lib/python3.8/site-packages/rest_framework/views.py", line 423, in finalize_response
    assert isinstance(response, HttpResponseBase), (
AssertionError: Expected a `Response`, `HttpResponse` or `HttpStreamingResponse` to be returned from the view, but received a `<class 'NoneType'>`
2023-08-11 11:40:38 ERROR "PUT /update_developers_second_db/1/ HTTP/1.1" 500 82667
2023-08-11 11:40:38 ERROR "PUT /update_developers_second_db/1/ HTTP/1.1" 500 82667
2023-08-11 11:45:56 ERROR Internal Server Error: /update_developers_second_db/1/
Traceback (most recent call last):
  File "/home/aakash/PROJECTS/LOGIN_AUTHENTICATION/myenv/lib/python3.8/site-packages/django/core/handlers/exception.py", line 55, in inner
    response = get_response(request)
  File "/home/aakash/PROJECTS/LOGIN_AUTHENTICATION/myenv/lib/python3.8/site-packages/django/core/handlers/base.py", line 197, in _get_response
    response = wrapped_callback(request, *callback_args, **callback_kwargs)
  File "/home/aakash/PROJECTS/LOGIN_AUTHENTICATION/myenv/lib/python3.8/site-packages/django/views/decorators/csrf.py", line 56, in wrapper_view
    return view_func(*args, **kwargs)
  File "/home/aakash/PROJECTS/LOGIN_AUTHENTICATION/myenv/lib/python3.8/site-packages/django/views/generic/base.py", line 104, in view
    return self.dispatch(request, *args, **kwargs)
  File "/home/aakash/PROJECTS/LOGIN_AUTHENTICATION/myenv/lib/python3.8/site-packages/rest_framework/views.py", line 511, in dispatch
    self.response = self.finalize_response(request, response, *args, **kwargs)
  File "/home/aakash/PROJECTS/LOGIN_AUTHENTICATION/myenv/lib/python3.8/site-packages/rest_framework/views.py", line 423, in finalize_response
    assert isinstance(response, HttpResponseBase), (
AssertionError: Expected a `Response`, `HttpResponse` or `HttpStreamingResponse` to be returned from the view, but received a `<class 'NoneType'>`
2023-08-11 11:45:56 ERROR "PUT /update_developers_second_db/1/ HTTP/1.1" 500 82667
2023-08-11 11:45:56 ERROR "PUT /update_developers_second_db/1/ HTTP/1.1" 500 82667
2023-08-11 11:47:36 ERROR Internal Server Error: /update_developers_second_db/1/
Traceback (most recent call last):
  File "/home/aakash/PROJECTS/LOGIN_AUTHENTICATION/myenv/lib/python3.8/site-packages/django/core/handlers/exception.py", line 55, in inner
    response = get_response(request)
  File "/home/aakash/PROJECTS/LOGIN_AUTHENTICATION/myenv/lib/python3.8/site-packages/django/core/handlers/base.py", line 197, in _get_response
    response = wrapped_callback(request, *callback_args, **callback_kwargs)
  File "/home/aakash/PROJECTS/LOGIN_AUTHENTICATION/myenv/lib/python3.8/site-packages/django/views/decorators/csrf.py", line 56, in wrapper_view
    return view_func(*args, **kwargs)
  File "/home/aakash/PROJECTS/LOGIN_AUTHENTICATION/myenv/lib/python3.8/site-packages/django/views/generic/base.py", line 104, in view
    return self.dispatch(request, *args, **kwargs)
  File "/home/aakash/PROJECTS/LOGIN_AUTHENTICATION/myenv/lib/python3.8/site-packages/rest_framework/views.py", line 511, in dispatch
    self.response = self.finalize_response(request, response, *args, **kwargs)
  File "/home/aakash/PROJECTS/LOGIN_AUTHENTICATION/myenv/lib/python3.8/site-packages/rest_framework/views.py", line 423, in finalize_response
    assert isinstance(response, HttpResponseBase), (
AssertionError: Expected a `Response`, `HttpResponse` or `HttpStreamingResponse` to be returned from the view, but received a `<class 'NoneType'>`
2023-08-11 11:47:36 ERROR "PUT /update_developers_second_db/1/ HTTP/1.1" 500 82601
