2023-08-11 11:40:11 ERROR Internal Server Error: /update_developers_second_db/1/
Traceback (most recent call last):
  File "/home/aakash/PROJECTS/LOGIN_AUTHENTICATION/myenv/lib/python3.8/site-packages/django/core/handlers/exception.py", line 55, in inner
    response = get_response(request)
  File "/home/aakash/PROJECTS/LOGIN_AUTHENTICATION/myenv/lib/python3.8/site-packages/django/core/handlers/base.py", line 197, in _get_response
    response = wrapped_callback(request, *callback_args, **callback_kwargs)
  File "/home/aakash/PROJECTS/LOGIN_AUTHENTICATION/myenv/lib/python3.8/site-packages/django/views/decorators/csrf.py", line 56, in wrapper_view
    return view_func(*args, **kwargs)
  File "/home/aakash/PROJECTS/LOGIN_AUTHENTICATION/myenv/lib/python3.8/site-packages/django/views/generic/base.py", line 104, in view
    return self.dispatch(request, *args, **kwargs)
  File "/home/aakash/PROJECTS/LOGIN_AUTHENTICATION/myenv/lib/python3.8/site-packages/rest_framework/views.py", line 511, in dispatch
    self.response = self.finalize_response(request, response, *args, **kwargs)
  File "/home/aakash/PROJECTS/LOGIN_AUTHENTICATION/myenv/lib/python3.8/site-packages/rest_framework/views.py", line 423, in finalize_response
    assert isinstance(response, HttpResponseBase), (
AssertionError: Expected a `Response`, `HttpResponse` or `HttpStreamingResponse` to be returned from the view, but received a `<class 'NoneType'>`
2023-08-11 11:40:11 ERROR "PUT /update_developers_second_db/1/ HTTP/1.1" 500 82664
2023-08-11 11:40:38 ERROR Internal Server Error: /update_developers_second_db/1/
Traceback (most recent call last):
  File "/home/aakash/PROJECTS/LOGIN_AUTHENTICATION/myenv/lib/python3.8/site-packages/django/core/handlers/exception.py", line 55, in inner
    response = get_response(request)
  File "/home/aakash/PROJECTS/LOGIN_AUTHENTICATION/myenv/lib/python3.8/site-packages/django/core/handlers/base.py", line 197, in _get_response
    response = wrapped_callback(request, *callback_args, **callback_kwargs)
  File "/home/aakash/PROJECTS/LOGIN_AUTHENTICATION/myenv/lib/python3.8/site-packages/django/views/decorators/csrf.py", line 56, in wrapper_view
    return view_func(*args, **kwargs)
  File "/home/aakash/PROJECTS/LOGIN_AUTHENTICATION/myenv/lib/python3.8/site-packages/django/views/generic/base.py", line 104, in view
    return self.dispatch(request, *args, **kwargs)
  File "/home/aakash/PROJECTS/LOGIN_AUTHENTICATION/myenv/lib/python3.8/site-packages/rest_framework/views.py", line 511, in dispatch
    self.response = self.finalize_response(request, response, *args, **kwargs)
  File "/home/aakash/PROJECTS/LOGIN_AUTHENTICATION/myenv/lib/python3.8/site-packages/rest_framework/views.py", line 423, in finalize_response
    assert isinstance(response, HttpResponseBase), (
AssertionError: Expected a `Response`, `HttpResponse` or `HttpStreamingResponse` to be returned from the view, but received a `<class 'NoneType'>`
2023-08-11 11:40:38 ERROR "PUT /update_developers_second_db/1/ HTTP/1.1" 500 82667
2023-08-11 11:40:38 ERROR "PUT /update_developers_second_db/1/ HTTP/1.1" 500 82667
2023-08-11 11:45:56 ERROR Internal Server Error: /update_developers_second_db/1/
Traceback (most recent call last):
  File "/home/aakash/PROJECTS/LOGIN_AUTHENTICATION/myenv/lib/python3.8/site-packages/django/core/handlers/exception.py", line 55, in inner
    response = get_response(request)
  File "/home/aakash/PROJECTS/LOGIN_AUTHENTICATION/myenv/lib/python3.8/site-packages/django/core/handlers/base.py", line 197, in _get_response
    response = wrapped_callback(request, *callback_args, **callback_kwargs)
  File "/home/aakash/PROJECTS/LOGIN_AUTHENTICATION/myenv/lib/python3.8/site-packages/django/views/decorators/csrf.py", line 56, in wrapper_view
    return view_func(*args, **kwargs)
  File "/home/aakash/PROJECTS/LOGIN_AUTHENTICATION/myenv/lib/python3.8/site-packages/django/views/generic/base.py", line 104, in view
    return self.dispatch(request, *args, **kwargs)
  File "/home/aakash/PROJECTS/LOGIN_AUTHENTICATION/myenv/lib/python3.8/site-packages/rest_framework/views.py", line 511, in dispatch
    self.response = self.finalize_response(request, response, *args, **kwargs)
  File "/home/aakash/PROJECTS/LOGIN_AUTHENTICATION/myenv/lib/python3.8/site-packages/rest_framework/views.py", line 423, in finalize_response
    assert isinstance(response, HttpResponseBase), (
AssertionError: Expected a `Response`, `HttpResponse` or `HttpStreamingResponse` to be returned from the view, but received a `<class 'NoneType'>`
2023-08-11 11:45:56 ERROR "PUT /update_developers_second_db/1/ HTTP/1.1" 500 82667
2023-08-11 11:45:56 ERROR "PUT /update_developers_second_db/1/ HTTP/1.1" 500 82667
2023-08-11 11:47:36 ERROR Internal Server Error: /update_developers_second_db/1/
Traceback (most recent call last):
  File "/home/aakash/PROJECTS/LOGIN_AUTHENTICATION/myenv/lib/python3.8/site-packages/django/core/handlers/exception.py", line 55, in inner
    response = get_response(request)
  File "/home/aakash/PROJECTS/LOGIN_AUTHENTICATION/myenv/lib/python3.8/site-packages/django/core/handlers/base.py", line 197, in _get_response
    response = wrapped_callback(request, *callback_args, **callback_kwargs)
  File "/home/aakash/PROJECTS/LOGIN_AUTHENTICATION/myenv/lib/python3.8/site-packages/django/views/decorators/csrf.py", line 56, in wrapper_view
    return view_func(*args, **kwargs)
  File "/home/aakash/PROJECTS/LOGIN_AUTHENTICATION/myenv/lib/python3.8/site-packages/django/views/generic/base.py", line 104, in view
    return self.dispatch(request, *args, **kwargs)
  File "/home/aakash/PROJECTS/LOGIN_AUTHENTICATION/myenv/lib/python3.8/site-packages/rest_framework/views.py", line 511, in dispatch
    self.response = self.finalize_response(request, response, *args, **kwargs)
  File "/home/aakash/PROJECTS/LOGIN_AUTHENTICATION/myenv/lib/python3.8/site-packages/rest_framework/views.py", line 423, in finalize_response
    assert isinstance(response, HttpResponseBase), (
AssertionError: Expected a `Response`, `HttpResponse` or `HttpStreamingResponse` to be returned from the view, but received a `<class 'NoneType'>`
2023-08-11 11:47:36 ERROR "PUT /update_developers_second_db/1/ HTTP/1.1" 500 82601
2023-08-14 06:39:59 ERROR Internal Server Error: /Create_Horse/
Traceback (most recent call last):
  File "/home/aakash/PROJECTS/LOGIN_AUTHENTICATION/myenv/lib/python3.8/site-packages/django/core/handlers/exception.py", line 55, in inner
    response = get_response(request)
  File "/home/aakash/PROJECTS/LOGIN_AUTHENTICATION/myenv/lib/python3.8/site-packages/django/core/handlers/base.py", line 197, in _get_response
    response = wrapped_callback(request, *callback_args, **callback_kwargs)
  File "/home/aakash/PROJECTS/LOGIN_AUTHENTICATION/myenv/lib/python3.8/site-packages/django/views/decorators/csrf.py", line 56, in wrapper_view
    return view_func(*args, **kwargs)
  File "/home/aakash/PROJECTS/LOGIN_AUTHENTICATION/myenv/lib/python3.8/site-packages/django/views/generic/base.py", line 104, in view
    return self.dispatch(request, *args, **kwargs)
  File "/home/aakash/PROJECTS/LOGIN_AUTHENTICATION/myenv/lib/python3.8/site-packages/rest_framework/views.py", line 509, in dispatch
    response = self.handle_exception(exc)
  File "/home/aakash/PROJECTS/LOGIN_AUTHENTICATION/myenv/lib/python3.8/site-packages/rest_framework/views.py", line 469, in handle_exception
    self.raise_uncaught_exception(exc)
  File "/home/aakash/PROJECTS/LOGIN_AUTHENTICATION/myenv/lib/python3.8/site-packages/rest_framework/views.py", line 480, in raise_uncaught_exception
    raise exc
  File "/home/aakash/PROJECTS/LOGIN_AUTHENTICATION/myenv/lib/python3.8/site-packages/rest_framework/views.py", line 506, in dispatch
    response = handler(request, *args, **kwargs)
  File "/home/aakash/PROJECTS/LOGIN_AUTHENTICATION/myenv/lib/python3.8/site-packages/rest_framework/decorators.py", line 50, in handler
    return func(*args, **kwargs)
TypeError: Create_Horse() missing 1 required positional argument: 'request'
2023-08-14 06:39:59 ERROR "POST /Create_Horse/ HTTP/1.1" 500 96576
2023-08-14 06:39:59 ERROR "POST /Create_Horse/ HTTP/1.1" 500 96576
2023-08-14 07:05:52 ERROR An error occurred: 'Horse' object is not iterable
2023-08-14 07:05:52 ERROR Internal Server Error: /get_horse_by_id/1/
2023-08-14 07:05:52 ERROR "GET /get_horse_by_id/1/ HTTP/1.1" 500 49
2023-08-14 07:05:52 ERROR "GET /get_horse_by_id/1/ HTTP/1.1" 500 49
2023-08-14 07:06:34 ERROR An error occurred: 'Horse' object is not iterable
2023-08-14 07:06:34 ERROR Internal Server Error: /get_horse_by_id/1/
2023-08-14 07:06:34 ERROR "GET /get_horse_by_id/1/ HTTP/1.1" 500 49
2023-08-14 07:06:34 ERROR "GET /get_horse_by_id/1/ HTTP/1.1" 500 49
2023-08-14 07:07:02 ERROR An error occurred: 'Horse' object is not iterable
2023-08-14 07:07:02 ERROR Internal Server Error: /get_horse_by_id/1/
2023-08-14 07:07:02 ERROR "GET /get_horse_by_id/1/ HTTP/1.1" 500 49
2023-08-14 07:07:02 ERROR "GET /get_horse_by_id/1/ HTTP/1.1" 500 49
2023-08-16 08:05:33 ERROR Internal Server Error: /MANY_TO_MANY_ORM/
Traceback (most recent call last):
  File "/home/aakash/PROJECTS/LOGIN_AUTHENTICATION/myenv/lib/python3.8/site-packages/django/db/backends/utils.py", line 89, in _execute
    return self.cursor.execute(sql, params)
  File "/home/aakash/PROJECTS/LOGIN_AUTHENTICATION/myenv/lib/python3.8/site-packages/django/db/backends/mysql/base.py", line 75, in execute
    return self.cursor.execute(query, args)
  File "/home/aakash/PROJECTS/LOGIN_AUTHENTICATION/myenv/lib/python3.8/site-packages/MySQLdb/cursors.py", line 179, in execute
    res = self._query(mogrified_query)
  File "/home/aakash/PROJECTS/LOGIN_AUTHENTICATION/myenv/lib/python3.8/site-packages/MySQLdb/cursors.py", line 330, in _query
    db.query(q)
  File "/home/aakash/PROJECTS/LOGIN_AUTHENTICATION/myenv/lib/python3.8/site-packages/MySQLdb/connections.py", line 255, in query
    _mysql.connection.query(self, query)
MySQLdb.ProgrammingError: (1146, "Table 'Demo_db.Author' doesn't exist")

The above exception was the direct cause of the following exception:

Traceback (most recent call last):
  File "/home/aakash/PROJECTS/LOGIN_AUTHENTICATION/myenv/lib/python3.8/site-packages/django/core/handlers/exception.py", line 55, in inner
    response = get_response(request)
  File "/home/aakash/PROJECTS/LOGIN_AUTHENTICATION/myenv/lib/python3.8/site-packages/django/core/handlers/base.py", line 197, in _get_response
    response = wrapped_callback(request, *callback_args, **callback_kwargs)
  File "/home/aakash/PROJECTS/LOGIN_AUTHENTICATION/myenv/lib/python3.8/site-packages/django/views/decorators/csrf.py", line 56, in wrapper_view
    return view_func(*args, **kwargs)
  File "/home/aakash/PROJECTS/LOGIN_AUTHENTICATION/myenv/lib/python3.8/site-packages/django/views/generic/base.py", line 104, in view
    return self.dispatch(request, *args, **kwargs)
  File "/home/aakash/PROJECTS/LOGIN_AUTHENTICATION/myenv/lib/python3.8/site-packages/rest_framework/views.py", line 509, in dispatch
    response = self.handle_exception(exc)
  File "/home/aakash/PROJECTS/LOGIN_AUTHENTICATION/myenv/lib/python3.8/site-packages/rest_framework/views.py", line 469, in handle_exception
    self.raise_uncaught_exception(exc)
  File "/home/aakash/PROJECTS/LOGIN_AUTHENTICATION/myenv/lib/python3.8/site-packages/rest_framework/views.py", line 480, in raise_uncaught_exception
    raise exc
  File "/home/aakash/PROJECTS/LOGIN_AUTHENTICATION/myenv/lib/python3.8/site-packages/rest_framework/views.py", line 506, in dispatch
    response = handler(request, *args, **kwargs)
  File "/home/aakash/PROJECTS/LOGIN_AUTHENTICATION/Authentication_System/myapp/views.py", line 1349, in get
    for author in raw_query:
  File "/home/aakash/PROJECTS/LOGIN_AUTHENTICATION/myenv/lib/python3.8/site-packages/django/db/models/query.py", line 2080, in __iter__
    self._fetch_all()
  File "/home/aakash/PROJECTS/LOGIN_AUTHENTICATION/myenv/lib/python3.8/site-packages/django/db/models/query.py", line 2067, in _fetch_all
    self._result_cache = list(self.iterator())
  File "/home/aakash/PROJECTS/LOGIN_AUTHENTICATION/myenv/lib/python3.8/site-packages/django/db/models/query.py", line 2094, in iterator
    yield from RawModelIterable(self)
  File "/home/aakash/PROJECTS/LOGIN_AUTHENTICATION/myenv/lib/python3.8/site-packages/django/db/models/query.py", line 158, in __iter__
    query_iterator = iter(query)
  File "/home/aakash/PROJECTS/LOGIN_AUTHENTICATION/myenv/lib/python3.8/site-packages/django/db/models/sql/query.py", line 112, in __iter__
    self._execute_query()
  File "/home/aakash/PROJECTS/LOGIN_AUTHENTICATION/myenv/lib/python3.8/site-packages/django/db/models/sql/query.py", line 152, in _execute_query
    self.cursor.execute(self.sql, params)
  File "/home/aakash/PROJECTS/LOGIN_AUTHENTICATION/myenv/lib/python3.8/site-packages/django/db/backends/utils.py", line 102, in execute
    return super().execute(sql, params)
  File "/home/aakash/PROJECTS/LOGIN_AUTHENTICATION/myenv/lib/python3.8/site-packages/django/db/backends/utils.py", line 67, in execute
    return self._execute_with_wrappers(
  File "/home/aakash/PROJECTS/LOGIN_AUTHENTICATION/myenv/lib/python3.8/site-packages/django/db/backends/utils.py", line 80, in _execute_with_wrappers
    return executor(sql, params, many, context)
  File "/home/aakash/PROJECTS/LOGIN_AUTHENTICATION/myenv/lib/python3.8/site-packages/django/db/backends/utils.py", line 89, in _execute
    return self.cursor.execute(sql, params)
  File "/home/aakash/PROJECTS/LOGIN_AUTHENTICATION/myenv/lib/python3.8/site-packages/django/db/utils.py", line 91, in __exit__
    raise dj_exc_value.with_traceback(traceback) from exc_value
  File "/home/aakash/PROJECTS/LOGIN_AUTHENTICATION/myenv/lib/python3.8/site-packages/django/db/backends/utils.py", line 89, in _execute
    return self.cursor.execute(sql, params)
  File "/home/aakash/PROJECTS/LOGIN_AUTHENTICATION/myenv/lib/python3.8/site-packages/django/db/backends/mysql/base.py", line 75, in execute
    return self.cursor.execute(query, args)
  File "/home/aakash/PROJECTS/LOGIN_AUTHENTICATION/myenv/lib/python3.8/site-packages/MySQLdb/cursors.py", line 179, in execute
    res = self._query(mogrified_query)
  File "/home/aakash/PROJECTS/LOGIN_AUTHENTICATION/myenv/lib/python3.8/site-packages/MySQLdb/cursors.py", line 330, in _query
    db.query(q)
  File "/home/aakash/PROJECTS/LOGIN_AUTHENTICATION/myenv/lib/python3.8/site-packages/MySQLdb/connections.py", line 255, in query
    _mysql.connection.query(self, query)
django.db.utils.ProgrammingError: (1146, "Table 'Demo_db.Author' doesn't exist")
2023-08-16 08:05:33 ERROR "GET /MANY_TO_MANY_ORM/ HTTP/1.1" 500 184682
2023-08-16 08:05:33 ERROR "GET /MANY_TO_MANY_ORM/ HTTP/1.1" 500 184682
2023-08-16 08:11:08 ERROR Internal Server Error: /MANY_TO_MANY_ORM/
Traceback (most recent call last):
  File "/home/aakash/PROJECTS/LOGIN_AUTHENTICATION/myenv/lib/python3.8/site-packages/django/db/backends/utils.py", line 89, in _execute
    return self.cursor.execute(sql, params)
  File "/home/aakash/PROJECTS/LOGIN_AUTHENTICATION/myenv/lib/python3.8/site-packages/django/db/backends/mysql/base.py", line 75, in execute
    return self.cursor.execute(query, args)
  File "/home/aakash/PROJECTS/LOGIN_AUTHENTICATION/myenv/lib/python3.8/site-packages/MySQLdb/cursors.py", line 179, in execute
    res = self._query(mogrified_query)
  File "/home/aakash/PROJECTS/LOGIN_AUTHENTICATION/myenv/lib/python3.8/site-packages/MySQLdb/cursors.py", line 330, in _query
    db.query(q)
  File "/home/aakash/PROJECTS/LOGIN_AUTHENTICATION/myenv/lib/python3.8/site-packages/MySQLdb/connections.py", line 255, in query
    _mysql.connection.query(self, query)
MySQLdb.OperationalError: (1054, "Unknown column 'books' in 'field list'")

The above exception was the direct cause of the following exception:

Traceback (most recent call last):
  File "/home/aakash/PROJECTS/LOGIN_AUTHENTICATION/myenv/lib/python3.8/site-packages/django/core/handlers/exception.py", line 55, in inner
    response = get_response(request)
  File "/home/aakash/PROJECTS/LOGIN_AUTHENTICATION/myenv/lib/python3.8/site-packages/django/core/handlers/base.py", line 197, in _get_response
    response = wrapped_callback(request, *callback_args, **callback_kwargs)
  File "/home/aakash/PROJECTS/LOGIN_AUTHENTICATION/myenv/lib/python3.8/site-packages/django/views/decorators/csrf.py", line 56, in wrapper_view
    return view_func(*args, **kwargs)
  File "/home/aakash/PROJECTS/LOGIN_AUTHENTICATION/myenv/lib/python3.8/site-packages/django/views/generic/base.py", line 104, in view
    return self.dispatch(request, *args, **kwargs)
  File "/home/aakash/PROJECTS/LOGIN_AUTHENTICATION/myenv/lib/python3.8/site-packages/rest_framework/views.py", line 509, in dispatch
    response = self.handle_exception(exc)
  File "/home/aakash/PROJECTS/LOGIN_AUTHENTICATION/myenv/lib/python3.8/site-packages/rest_framework/views.py", line 469, in handle_exception
    self.raise_uncaught_exception(exc)
  File "/home/aakash/PROJECTS/LOGIN_AUTHENTICATION/myenv/lib/python3.8/site-packages/rest_framework/views.py", line 480, in raise_uncaught_exception
    raise exc
  File "/home/aakash/PROJECTS/LOGIN_AUTHENTICATION/myenv/lib/python3.8/site-packages/rest_framework/views.py", line 506, in dispatch
    response = handler(request, *args, **kwargs)
  File "/home/aakash/PROJECTS/LOGIN_AUTHENTICATION/Authentication_System/myapp/views.py", line 1349, in get
    print(list(raw_query))
  File "/home/aakash/PROJECTS/LOGIN_AUTHENTICATION/myenv/lib/python3.8/site-packages/django/db/models/query.py", line 2072, in __len__
    self._fetch_all()
  File "/home/aakash/PROJECTS/LOGIN_AUTHENTICATION/myenv/lib/python3.8/site-packages/django/db/models/query.py", line 2067, in _fetch_all
    self._result_cache = list(self.iterator())
  File "/home/aakash/PROJECTS/LOGIN_AUTHENTICATION/myenv/lib/python3.8/site-packages/django/db/models/query.py", line 2094, in iterator
    yield from RawModelIterable(self)
  File "/home/aakash/PROJECTS/LOGIN_AUTHENTICATION/myenv/lib/python3.8/site-packages/django/db/models/query.py", line 158, in __iter__
    query_iterator = iter(query)
  File "/home/aakash/PROJECTS/LOGIN_AUTHENTICATION/myenv/lib/python3.8/site-packages/django/db/models/sql/query.py", line 112, in __iter__
    self._execute_query()
  File "/home/aakash/PROJECTS/LOGIN_AUTHENTICATION/myenv/lib/python3.8/site-packages/django/db/models/sql/query.py", line 152, in _execute_query
    self.cursor.execute(self.sql, params)
  File "/home/aakash/PROJECTS/LOGIN_AUTHENTICATION/myenv/lib/python3.8/site-packages/django/db/backends/utils.py", line 102, in execute
    return super().execute(sql, params)
  File "/home/aakash/PROJECTS/LOGIN_AUTHENTICATION/myenv/lib/python3.8/site-packages/django/db/backends/utils.py", line 67, in execute
    return self._execute_with_wrappers(
  File "/home/aakash/PROJECTS/LOGIN_AUTHENTICATION/myenv/lib/python3.8/site-packages/django/db/backends/utils.py", line 80, in _execute_with_wrappers
    return executor(sql, params, many, context)
  File "/home/aakash/PROJECTS/LOGIN_AUTHENTICATION/myenv/lib/python3.8/site-packages/django/db/backends/utils.py", line 89, in _execute
    return self.cursor.execute(sql, params)
  File "/home/aakash/PROJECTS/LOGIN_AUTHENTICATION/myenv/lib/python3.8/site-packages/django/db/utils.py", line 91, in __exit__
    raise dj_exc_value.with_traceback(traceback) from exc_value
  File "/home/aakash/PROJECTS/LOGIN_AUTHENTICATION/myenv/lib/python3.8/site-packages/django/db/backends/utils.py", line 89, in _execute
    return self.cursor.execute(sql, params)
  File "/home/aakash/PROJECTS/LOGIN_AUTHENTICATION/myenv/lib/python3.8/site-packages/django/db/backends/mysql/base.py", line 75, in execute
    return self.cursor.execute(query, args)
  File "/home/aakash/PROJECTS/LOGIN_AUTHENTICATION/myenv/lib/python3.8/site-packages/MySQLdb/cursors.py", line 179, in execute
    res = self._query(mogrified_query)
  File "/home/aakash/PROJECTS/LOGIN_AUTHENTICATION/myenv/lib/python3.8/site-packages/MySQLdb/cursors.py", line 330, in _query
    db.query(q)
  File "/home/aakash/PROJECTS/LOGIN_AUTHENTICATION/myenv/lib/python3.8/site-packages/MySQLdb/connections.py", line 255, in query
    _mysql.connection.query(self, query)
django.db.utils.OperationalError: (1054, "Unknown column 'books' in 'field list'")
2023-08-16 08:11:08 ERROR "GET /MANY_TO_MANY_ORM/ HTTP/1.1" 500 185914
2023-08-16 08:11:08 ERROR "GET /MANY_TO_MANY_ORM/ HTTP/1.1" 500 185914
2023-08-16 08:12:14 ERROR Internal Server Error: /MANY_TO_MANY_ORM/
Traceback (most recent call last):
  File "/home/aakash/PROJECTS/LOGIN_AUTHENTICATION/myenv/lib/python3.8/site-packages/django/core/handlers/exception.py", line 55, in inner
    response = get_response(request)
  File "/home/aakash/PROJECTS/LOGIN_AUTHENTICATION/myenv/lib/python3.8/site-packages/django/core/handlers/base.py", line 197, in _get_response
    response = wrapped_callback(request, *callback_args, **callback_kwargs)
  File "/home/aakash/PROJECTS/LOGIN_AUTHENTICATION/myenv/lib/python3.8/site-packages/django/views/decorators/csrf.py", line 56, in wrapper_view
    return view_func(*args, **kwargs)
  File "/home/aakash/PROJECTS/LOGIN_AUTHENTICATION/myenv/lib/python3.8/site-packages/django/views/generic/base.py", line 104, in view
    return self.dispatch(request, *args, **kwargs)
  File "/home/aakash/PROJECTS/LOGIN_AUTHENTICATION/myenv/lib/python3.8/site-packages/rest_framework/views.py", line 509, in dispatch
    response = self.handle_exception(exc)
  File "/home/aakash/PROJECTS/LOGIN_AUTHENTICATION/myenv/lib/python3.8/site-packages/rest_framework/views.py", line 469, in handle_exception
    self.raise_uncaught_exception(exc)
  File "/home/aakash/PROJECTS/LOGIN_AUTHENTICATION/myenv/lib/python3.8/site-packages/rest_framework/views.py", line 480, in raise_uncaught_exception
    raise exc
  File "/home/aakash/PROJECTS/LOGIN_AUTHENTICATION/myenv/lib/python3.8/site-packages/rest_framework/views.py", line 506, in dispatch
    response = handler(request, *args, **kwargs)
  File "/home/aakash/PROJECTS/LOGIN_AUTHENTICATION/Authentication_System/myapp/views.py", line 1349, in get
    print(list(raw_query))
  File "/home/aakash/PROJECTS/LOGIN_AUTHENTICATION/myenv/lib/python3.8/site-packages/django/db/models/query.py", line 2072, in __len__
    self._fetch_all()
  File "/home/aakash/PROJECTS/LOGIN_AUTHENTICATION/myenv/lib/python3.8/site-packages/django/db/models/query.py", line 2067, in _fetch_all
    self._result_cache = list(self.iterator())
  File "/home/aakash/PROJECTS/LOGIN_AUTHENTICATION/myenv/lib/python3.8/site-packages/django/db/models/query.py", line 2094, in iterator
    yield from RawModelIterable(self)
  File "/home/aakash/PROJECTS/LOGIN_AUTHENTICATION/myenv/lib/python3.8/site-packages/django/db/models/query.py", line 168, in __iter__
    raise exceptions.FieldDoesNotExist(
django.core.exceptions.FieldDoesNotExist: Raw query must include the primary key
2023-08-16 08:12:14 ERROR "GET /MANY_TO_MANY_ORM/ HTTP/1.1" 500 112743
2023-08-16 08:12:14 ERROR "GET /MANY_TO_MANY_ORM/ HTTP/1.1" 500 112743
2023-08-16 08:19:45 ERROR Internal Server Error: /MANY_TO_MANY_ORM/
Traceback (most recent call last):
  File "/home/aakash/PROJECTS/LOGIN_AUTHENTICATION/myenv/lib/python3.8/site-packages/django/db/backends/utils.py", line 89, in _execute
    return self.cursor.execute(sql, params)
  File "/home/aakash/PROJECTS/LOGIN_AUTHENTICATION/myenv/lib/python3.8/site-packages/django/db/backends/mysql/base.py", line 75, in execute
    return self.cursor.execute(query, args)
  File "/home/aakash/PROJECTS/LOGIN_AUTHENTICATION/myenv/lib/python3.8/site-packages/MySQLdb/cursors.py", line 179, in execute
    res = self._query(mogrified_query)
  File "/home/aakash/PROJECTS/LOGIN_AUTHENTICATION/myenv/lib/python3.8/site-packages/MySQLdb/cursors.py", line 330, in _query
    db.query(q)
  File "/home/aakash/PROJECTS/LOGIN_AUTHENTICATION/myenv/lib/python3.8/site-packages/MySQLdb/connections.py", line 255, in query
    _mysql.connection.query(self, query)
MySQLdb.ProgrammingError: (1064, "You have an error in your SQL syntax; check the manual that corresponds to your MySQL server version for the right syntax to use near 'on myapp_author.id and myapp_book.id WHERE myapp_author.id=1' at line 1")

The above exception was the direct cause of the following exception:

Traceback (most recent call last):
  File "/home/aakash/PROJECTS/LOGIN_AUTHENTICATION/myenv/lib/python3.8/site-packages/django/core/handlers/exception.py", line 55, in inner
    response = get_response(request)
  File "/home/aakash/PROJECTS/LOGIN_AUTHENTICATION/myenv/lib/python3.8/site-packages/django/core/handlers/base.py", line 197, in _get_response
    response = wrapped_callback(request, *callback_args, **callback_kwargs)
  File "/home/aakash/PROJECTS/LOGIN_AUTHENTICATION/myenv/lib/python3.8/site-packages/django/views/decorators/csrf.py", line 56, in wrapper_view
    return view_func(*args, **kwargs)
  File "/home/aakash/PROJECTS/LOGIN_AUTHENTICATION/myenv/lib/python3.8/site-packages/django/views/generic/base.py", line 104, in view
    return self.dispatch(request, *args, **kwargs)
  File "/home/aakash/PROJECTS/LOGIN_AUTHENTICATION/myenv/lib/python3.8/site-packages/rest_framework/views.py", line 509, in dispatch
    response = self.handle_exception(exc)
  File "/home/aakash/PROJECTS/LOGIN_AUTHENTICATION/myenv/lib/python3.8/site-packages/rest_framework/views.py", line 469, in handle_exception
    self.raise_uncaught_exception(exc)
  File "/home/aakash/PROJECTS/LOGIN_AUTHENTICATION/myenv/lib/python3.8/site-packages/rest_framework/views.py", line 480, in raise_uncaught_exception
    raise exc
  File "/home/aakash/PROJECTS/LOGIN_AUTHENTICATION/myenv/lib/python3.8/site-packages/rest_framework/views.py", line 506, in dispatch
    response = handler(request, *args, **kwargs)
  File "/home/aakash/PROJECTS/LOGIN_AUTHENTICATION/Authentication_System/myapp/views.py", line 1349, in get
    print(list(raw_query))
  File "/home/aakash/PROJECTS/LOGIN_AUTHENTICATION/myenv/lib/python3.8/site-packages/django/db/models/query.py", line 2072, in __len__
    self._fetch_all()
  File "/home/aakash/PROJECTS/LOGIN_AUTHENTICATION/myenv/lib/python3.8/site-packages/django/db/models/query.py", line 2067, in _fetch_all
    self._result_cache = list(self.iterator())
  File "/home/aakash/PROJECTS/LOGIN_AUTHENTICATION/myenv/lib/python3.8/site-packages/django/db/models/query.py", line 2094, in iterator
    yield from RawModelIterable(self)
  File "/home/aakash/PROJECTS/LOGIN_AUTHENTICATION/myenv/lib/python3.8/site-packages/django/db/models/query.py", line 158, in __iter__
    query_iterator = iter(query)
  File "/home/aakash/PROJECTS/LOGIN_AUTHENTICATION/myenv/lib/python3.8/site-packages/django/db/models/sql/query.py", line 112, in __iter__
    self._execute_query()
  File "/home/aakash/PROJECTS/LOGIN_AUTHENTICATION/myenv/lib/python3.8/site-packages/django/db/models/sql/query.py", line 152, in _execute_query
    self.cursor.execute(self.sql, params)
  File "/home/aakash/PROJECTS/LOGIN_AUTHENTICATION/myenv/lib/python3.8/site-packages/django/db/backends/utils.py", line 102, in execute
    return super().execute(sql, params)
  File "/home/aakash/PROJECTS/LOGIN_AUTHENTICATION/myenv/lib/python3.8/site-packages/django/db/backends/utils.py", line 67, in execute
    return self._execute_with_wrappers(
  File "/home/aakash/PROJECTS/LOGIN_AUTHENTICATION/myenv/lib/python3.8/site-packages/django/db/backends/utils.py", line 80, in _execute_with_wrappers
    return executor(sql, params, many, context)
  File "/home/aakash/PROJECTS/LOGIN_AUTHENTICATION/myenv/lib/python3.8/site-packages/django/db/backends/utils.py", line 89, in _execute
    return self.cursor.execute(sql, params)
  File "/home/aakash/PROJECTS/LOGIN_AUTHENTICATION/myenv/lib/python3.8/site-packages/django/db/utils.py", line 91, in __exit__
    raise dj_exc_value.with_traceback(traceback) from exc_value
  File "/home/aakash/PROJECTS/LOGIN_AUTHENTICATION/myenv/lib/python3.8/site-packages/django/db/backends/utils.py", line 89, in _execute
    return self.cursor.execute(sql, params)
  File "/home/aakash/PROJECTS/LOGIN_AUTHENTICATION/myenv/lib/python3.8/site-packages/django/db/backends/mysql/base.py", line 75, in execute
    return self.cursor.execute(query, args)
  File "/home/aakash/PROJECTS/LOGIN_AUTHENTICATION/myenv/lib/python3.8/site-packages/MySQLdb/cursors.py", line 179, in execute
    res = self._query(mogrified_query)
  File "/home/aakash/PROJECTS/LOGIN_AUTHENTICATION/myenv/lib/python3.8/site-packages/MySQLdb/cursors.py", line 330, in _query
    db.query(q)
  File "/home/aakash/PROJECTS/LOGIN_AUTHENTICATION/myenv/lib/python3.8/site-packages/MySQLdb/connections.py", line 255, in query
    _mysql.connection.query(self, query)
django.db.utils.ProgrammingError: (1064, "You have an error in your SQL syntax; check the manual that corresponds to your MySQL server version for the right syntax to use near 'on myapp_author.id and myapp_book.id WHERE myapp_author.id=1' at line 1")
2023-08-16 08:19:45 ERROR "GET /MANY_TO_MANY_ORM/ HTTP/1.1" 500 189148
2023-08-16 08:19:45 ERROR "GET /MANY_TO_MANY_ORM/ HTTP/1.1" 500 189148
2023-08-16 08:22:22 ERROR Internal Server Error: /MANY_TO_MANY_ORM/
Traceback (most recent call last):
  File "/home/aakash/PROJECTS/LOGIN_AUTHENTICATION/myenv/lib/python3.8/site-packages/django/db/backends/utils.py", line 89, in _execute
    return self.cursor.execute(sql, params)
  File "/home/aakash/PROJECTS/LOGIN_AUTHENTICATION/myenv/lib/python3.8/site-packages/django/db/backends/mysql/base.py", line 75, in execute
    return self.cursor.execute(query, args)
  File "/home/aakash/PROJECTS/LOGIN_AUTHENTICATION/myenv/lib/python3.8/site-packages/MySQLdb/cursors.py", line 179, in execute
    res = self._query(mogrified_query)
  File "/home/aakash/PROJECTS/LOGIN_AUTHENTICATION/myenv/lib/python3.8/site-packages/MySQLdb/cursors.py", line 330, in _query
    db.query(q)
  File "/home/aakash/PROJECTS/LOGIN_AUTHENTICATION/myenv/lib/python3.8/site-packages/MySQLdb/connections.py", line 255, in query
    _mysql.connection.query(self, query)
MySQLdb.ProgrammingError: (1064, "You have an error in your SQL syntax; check the manual that corresponds to your MySQL server version for the right syntax to use near 'on myapp_author.id and myapp_book.author_id WHERE myapp_author.id=1' at line 1")

The above exception was the direct cause of the following exception:

Traceback (most recent call last):
  File "/home/aakash/PROJECTS/LOGIN_AUTHENTICATION/myenv/lib/python3.8/site-packages/django/core/handlers/exception.py", line 55, in inner
    response = get_response(request)
  File "/home/aakash/PROJECTS/LOGIN_AUTHENTICATION/myenv/lib/python3.8/site-packages/django/core/handlers/base.py", line 197, in _get_response
    response = wrapped_callback(request, *callback_args, **callback_kwargs)
  File "/home/aakash/PROJECTS/LOGIN_AUTHENTICATION/myenv/lib/python3.8/site-packages/django/views/decorators/csrf.py", line 56, in wrapper_view
    return view_func(*args, **kwargs)
  File "/home/aakash/PROJECTS/LOGIN_AUTHENTICATION/myenv/lib/python3.8/site-packages/django/views/generic/base.py", line 104, in view
    return self.dispatch(request, *args, **kwargs)
  File "/home/aakash/PROJECTS/LOGIN_AUTHENTICATION/myenv/lib/python3.8/site-packages/rest_framework/views.py", line 509, in dispatch
    response = self.handle_exception(exc)
  File "/home/aakash/PROJECTS/LOGIN_AUTHENTICATION/myenv/lib/python3.8/site-packages/rest_framework/views.py", line 469, in handle_exception
    self.raise_uncaught_exception(exc)
  File "/home/aakash/PROJECTS/LOGIN_AUTHENTICATION/myenv/lib/python3.8/site-packages/rest_framework/views.py", line 480, in raise_uncaught_exception
    raise exc
  File "/home/aakash/PROJECTS/LOGIN_AUTHENTICATION/myenv/lib/python3.8/site-packages/rest_framework/views.py", line 506, in dispatch
    response = handler(request, *args, **kwargs)
  File "/home/aakash/PROJECTS/LOGIN_AUTHENTICATION/Authentication_System/myapp/views.py", line 1349, in get
    print(list(raw_query))
  File "/home/aakash/PROJECTS/LOGIN_AUTHENTICATION/myenv/lib/python3.8/site-packages/django/db/models/query.py", line 2072, in __len__
    self._fetch_all()
  File "/home/aakash/PROJECTS/LOGIN_AUTHENTICATION/myenv/lib/python3.8/site-packages/django/db/models/query.py", line 2067, in _fetch_all
    self._result_cache = list(self.iterator())
  File "/home/aakash/PROJECTS/LOGIN_AUTHENTICATION/myenv/lib/python3.8/site-packages/django/db/models/query.py", line 2094, in iterator
    yield from RawModelIterable(self)
  File "/home/aakash/PROJECTS/LOGIN_AUTHENTICATION/myenv/lib/python3.8/site-packages/django/db/models/query.py", line 158, in __iter__
    query_iterator = iter(query)
  File "/home/aakash/PROJECTS/LOGIN_AUTHENTICATION/myenv/lib/python3.8/site-packages/django/db/models/sql/query.py", line 112, in __iter__
    self._execute_query()
  File "/home/aakash/PROJECTS/LOGIN_AUTHENTICATION/myenv/lib/python3.8/site-packages/django/db/models/sql/query.py", line 152, in _execute_query
    self.cursor.execute(self.sql, params)
  File "/home/aakash/PROJECTS/LOGIN_AUTHENTICATION/myenv/lib/python3.8/site-packages/django/db/backends/utils.py", line 102, in execute
    return super().execute(sql, params)
  File "/home/aakash/PROJECTS/LOGIN_AUTHENTICATION/myenv/lib/python3.8/site-packages/django/db/backends/utils.py", line 67, in execute
    return self._execute_with_wrappers(
  File "/home/aakash/PROJECTS/LOGIN_AUTHENTICATION/myenv/lib/python3.8/site-packages/django/db/backends/utils.py", line 80, in _execute_with_wrappers
    return executor(sql, params, many, context)
  File "/home/aakash/PROJECTS/LOGIN_AUTHENTICATION/myenv/lib/python3.8/site-packages/django/db/backends/utils.py", line 89, in _execute
    return self.cursor.execute(sql, params)
  File "/home/aakash/PROJECTS/LOGIN_AUTHENTICATION/myenv/lib/python3.8/site-packages/django/db/utils.py", line 91, in __exit__
    raise dj_exc_value.with_traceback(traceback) from exc_value
  File "/home/aakash/PROJECTS/LOGIN_AUTHENTICATION/myenv/lib/python3.8/site-packages/django/db/backends/utils.py", line 89, in _execute
    return self.cursor.execute(sql, params)
  File "/home/aakash/PROJECTS/LOGIN_AUTHENTICATION/myenv/lib/python3.8/site-packages/django/db/backends/mysql/base.py", line 75, in execute
    return self.cursor.execute(query, args)
  File "/home/aakash/PROJECTS/LOGIN_AUTHENTICATION/myenv/lib/python3.8/site-packages/MySQLdb/cursors.py", line 179, in execute
    res = self._query(mogrified_query)
  File "/home/aakash/PROJECTS/LOGIN_AUTHENTICATION/myenv/lib/python3.8/site-packages/MySQLdb/cursors.py", line 330, in _query
    db.query(q)
  File "/home/aakash/PROJECTS/LOGIN_AUTHENTICATION/myenv/lib/python3.8/site-packages/MySQLdb/connections.py", line 255, in query
    _mysql.connection.query(self, query)
django.db.utils.ProgrammingError: (1064, "You have an error in your SQL syntax; check the manual that corresponds to your MySQL server version for the right syntax to use near 'on myapp_author.id and myapp_book.author_id WHERE myapp_author.id=1' at line 1")
2023-08-16 08:22:22 ERROR "GET /MANY_TO_MANY_ORM/ HTTP/1.1" 500 189386
2023-08-16 08:22:22 ERROR "GET /MANY_TO_MANY_ORM/ HTTP/1.1" 500 189386
2023-08-16 08:24:22 ERROR Internal Server Error: /MANY_TO_MANY_ORM/
Traceback (most recent call last):
  File "/home/aakash/PROJECTS/LOGIN_AUTHENTICATION/myenv/lib/python3.8/site-packages/django/db/backends/utils.py", line 89, in _execute
    return self.cursor.execute(sql, params)
  File "/home/aakash/PROJECTS/LOGIN_AUTHENTICATION/myenv/lib/python3.8/site-packages/django/db/backends/mysql/base.py", line 75, in execute
    return self.cursor.execute(query, args)
  File "/home/aakash/PROJECTS/LOGIN_AUTHENTICATION/myenv/lib/python3.8/site-packages/MySQLdb/cursors.py", line 179, in execute
    res = self._query(mogrified_query)
  File "/home/aakash/PROJECTS/LOGIN_AUTHENTICATION/myenv/lib/python3.8/site-packages/MySQLdb/cursors.py", line 330, in _query
    db.query(q)
  File "/home/aakash/PROJECTS/LOGIN_AUTHENTICATION/myenv/lib/python3.8/site-packages/MySQLdb/connections.py", line 255, in query
    _mysql.connection.query(self, query)
MySQLdb.OperationalError: (1054, "Unknown column 'myapp_book.author_id' in 'on clause'")

The above exception was the direct cause of the following exception:

Traceback (most recent call last):
  File "/home/aakash/PROJECTS/LOGIN_AUTHENTICATION/myenv/lib/python3.8/site-packages/django/core/handlers/exception.py", line 55, in inner
    response = get_response(request)
  File "/home/aakash/PROJECTS/LOGIN_AUTHENTICATION/myenv/lib/python3.8/site-packages/django/core/handlers/base.py", line 197, in _get_response
    response = wrapped_callback(request, *callback_args, **callback_kwargs)
  File "/home/aakash/PROJECTS/LOGIN_AUTHENTICATION/myenv/lib/python3.8/site-packages/django/views/decorators/csrf.py", line 56, in wrapper_view
    return view_func(*args, **kwargs)
  File "/home/aakash/PROJECTS/LOGIN_AUTHENTICATION/myenv/lib/python3.8/site-packages/django/views/generic/base.py", line 104, in view
    return self.dispatch(request, *args, **kwargs)
  File "/home/aakash/PROJECTS/LOGIN_AUTHENTICATION/myenv/lib/python3.8/site-packages/rest_framework/views.py", line 509, in dispatch
    response = self.handle_exception(exc)
  File "/home/aakash/PROJECTS/LOGIN_AUTHENTICATION/myenv/lib/python3.8/site-packages/rest_framework/views.py", line 469, in handle_exception
    self.raise_uncaught_exception(exc)
  File "/home/aakash/PROJECTS/LOGIN_AUTHENTICATION/myenv/lib/python3.8/site-packages/rest_framework/views.py", line 480, in raise_uncaught_exception
    raise exc
  File "/home/aakash/PROJECTS/LOGIN_AUTHENTICATION/myenv/lib/python3.8/site-packages/rest_framework/views.py", line 506, in dispatch
    response = handler(request, *args, **kwargs)
  File "/home/aakash/PROJECTS/LOGIN_AUTHENTICATION/Authentication_System/myapp/views.py", line 1349, in get
    print(list(raw_query))
  File "/home/aakash/PROJECTS/LOGIN_AUTHENTICATION/myenv/lib/python3.8/site-packages/django/db/models/query.py", line 2072, in __len__
    self._fetch_all()
  File "/home/aakash/PROJECTS/LOGIN_AUTHENTICATION/myenv/lib/python3.8/site-packages/django/db/models/query.py", line 2067, in _fetch_all
    self._result_cache = list(self.iterator())
  File "/home/aakash/PROJECTS/LOGIN_AUTHENTICATION/myenv/lib/python3.8/site-packages/django/db/models/query.py", line 2094, in iterator
    yield from RawModelIterable(self)
  File "/home/aakash/PROJECTS/LOGIN_AUTHENTICATION/myenv/lib/python3.8/site-packages/django/db/models/query.py", line 158, in __iter__
    query_iterator = iter(query)
  File "/home/aakash/PROJECTS/LOGIN_AUTHENTICATION/myenv/lib/python3.8/site-packages/django/db/models/sql/query.py", line 112, in __iter__
    self._execute_query()
  File "/home/aakash/PROJECTS/LOGIN_AUTHENTICATION/myenv/lib/python3.8/site-packages/django/db/models/sql/query.py", line 152, in _execute_query
    self.cursor.execute(self.sql, params)
  File "/home/aakash/PROJECTS/LOGIN_AUTHENTICATION/myenv/lib/python3.8/site-packages/django/db/backends/utils.py", line 102, in execute
    return super().execute(sql, params)
  File "/home/aakash/PROJECTS/LOGIN_AUTHENTICATION/myenv/lib/python3.8/site-packages/django/db/backends/utils.py", line 67, in execute
    return self._execute_with_wrappers(
  File "/home/aakash/PROJECTS/LOGIN_AUTHENTICATION/myenv/lib/python3.8/site-packages/django/db/backends/utils.py", line 80, in _execute_with_wrappers
    return executor(sql, params, many, context)
  File "/home/aakash/PROJECTS/LOGIN_AUTHENTICATION/myenv/lib/python3.8/site-packages/django/db/backends/utils.py", line 89, in _execute
    return self.cursor.execute(sql, params)
  File "/home/aakash/PROJECTS/LOGIN_AUTHENTICATION/myenv/lib/python3.8/site-packages/django/db/utils.py", line 91, in __exit__
    raise dj_exc_value.with_traceback(traceback) from exc_value
  File "/home/aakash/PROJECTS/LOGIN_AUTHENTICATION/myenv/lib/python3.8/site-packages/django/db/backends/utils.py", line 89, in _execute
    return self.cursor.execute(sql, params)
  File "/home/aakash/PROJECTS/LOGIN_AUTHENTICATION/myenv/lib/python3.8/site-packages/django/db/backends/mysql/base.py", line 75, in execute
    return self.cursor.execute(query, args)
  File "/home/aakash/PROJECTS/LOGIN_AUTHENTICATION/myenv/lib/python3.8/site-packages/MySQLdb/cursors.py", line 179, in execute
    res = self._query(mogrified_query)
  File "/home/aakash/PROJECTS/LOGIN_AUTHENTICATION/myenv/lib/python3.8/site-packages/MySQLdb/cursors.py", line 330, in _query
    db.query(q)
  File "/home/aakash/PROJECTS/LOGIN_AUTHENTICATION/myenv/lib/python3.8/site-packages/MySQLdb/connections.py", line 255, in query
    _mysql.connection.query(self, query)
django.db.utils.OperationalError: (1054, "Unknown column 'myapp_book.author_id' in 'on clause'")
2023-08-16 08:24:22 ERROR "GET /MANY_TO_MANY_ORM/ HTTP/1.1" 500 188092
2023-08-16 08:24:22 ERROR "GET /MANY_TO_MANY_ORM/ HTTP/1.1" 500 188092
2023-08-16 09:52:14 ERROR Internal Server Error: /MANY_TO_MANY_ORM/
Traceback (most recent call last):
  File "/home/aakash/PROJECTS/LOGIN_AUTHENTICATION/myenv/lib/python3.8/site-packages/django/core/handlers/exception.py", line 55, in inner
    response = get_response(request)
  File "/home/aakash/PROJECTS/LOGIN_AUTHENTICATION/myenv/lib/python3.8/site-packages/django/core/handlers/base.py", line 197, in _get_response
    response = wrapped_callback(request, *callback_args, **callback_kwargs)
  File "/home/aakash/PROJECTS/LOGIN_AUTHENTICATION/myenv/lib/python3.8/site-packages/django/views/decorators/csrf.py", line 56, in wrapper_view
    return view_func(*args, **kwargs)
  File "/home/aakash/PROJECTS/LOGIN_AUTHENTICATION/myenv/lib/python3.8/site-packages/django/views/generic/base.py", line 104, in view
    return self.dispatch(request, *args, **kwargs)
  File "/home/aakash/PROJECTS/LOGIN_AUTHENTICATION/myenv/lib/python3.8/site-packages/rest_framework/views.py", line 509, in dispatch
    response = self.handle_exception(exc)
  File "/home/aakash/PROJECTS/LOGIN_AUTHENTICATION/myenv/lib/python3.8/site-packages/rest_framework/views.py", line 469, in handle_exception
    self.raise_uncaught_exception(exc)
  File "/home/aakash/PROJECTS/LOGIN_AUTHENTICATION/myenv/lib/python3.8/site-packages/rest_framework/views.py", line 480, in raise_uncaught_exception
    raise exc
  File "/home/aakash/PROJECTS/LOGIN_AUTHENTICATION/myenv/lib/python3.8/site-packages/rest_framework/views.py", line 506, in dispatch
    response = handler(request, *args, **kwargs)
  File "/home/aakash/PROJECTS/LOGIN_AUTHENTICATION/Authentication_System/myapp/views.py", line 1349, in get
    print(list(raw_query))
  File "/home/aakash/PROJECTS/LOGIN_AUTHENTICATION/myenv/lib/python3.8/site-packages/django/db/models/query.py", line 2072, in __len__
    self._fetch_all()
  File "/home/aakash/PROJECTS/LOGIN_AUTHENTICATION/myenv/lib/python3.8/site-packages/django/db/models/query.py", line 2067, in _fetch_all
    self._result_cache = list(self.iterator())
  File "/home/aakash/PROJECTS/LOGIN_AUTHENTICATION/myenv/lib/python3.8/site-packages/django/db/models/query.py", line 2094, in iterator
    yield from RawModelIterable(self)
  File "/home/aakash/PROJECTS/LOGIN_AUTHENTICATION/myenv/lib/python3.8/site-packages/django/db/models/query.py", line 168, in __iter__
    raise exceptions.FieldDoesNotExist(
django.core.exceptions.FieldDoesNotExist: Raw query must include the primary key
2023-08-16 09:52:14 ERROR "GET /MANY_TO_MANY_ORM/ HTTP/1.1" 500 113171
2023-08-16 09:52:14 ERROR "GET /MANY_TO_MANY_ORM/ HTTP/1.1" 500 113171
2023-08-16 10:27:06 ERROR Internal Server Error: /MANY_TO_MANY_ORM/
Traceback (most recent call last):
  File "/home/aakash/PROJECTS/LOGIN_AUTHENTICATION/myenv/lib/python3.8/site-packages/django/core/handlers/exception.py", line 55, in inner
    response = get_response(request)
  File "/home/aakash/PROJECTS/LOGIN_AUTHENTICATION/myenv/lib/python3.8/site-packages/django/core/handlers/base.py", line 197, in _get_response
    response = wrapped_callback(request, *callback_args, **callback_kwargs)
  File "/home/aakash/PROJECTS/LOGIN_AUTHENTICATION/myenv/lib/python3.8/site-packages/django/views/decorators/csrf.py", line 56, in wrapper_view
    return view_func(*args, **kwargs)
  File "/home/aakash/PROJECTS/LOGIN_AUTHENTICATION/myenv/lib/python3.8/site-packages/django/views/generic/base.py", line 104, in view
    return self.dispatch(request, *args, **kwargs)
  File "/home/aakash/PROJECTS/LOGIN_AUTHENTICATION/myenv/lib/python3.8/site-packages/rest_framework/views.py", line 509, in dispatch
    response = self.handle_exception(exc)
  File "/home/aakash/PROJECTS/LOGIN_AUTHENTICATION/myenv/lib/python3.8/site-packages/rest_framework/views.py", line 469, in handle_exception
    self.raise_uncaught_exception(exc)
  File "/home/aakash/PROJECTS/LOGIN_AUTHENTICATION/myenv/lib/python3.8/site-packages/rest_framework/views.py", line 480, in raise_uncaught_exception
    raise exc
  File "/home/aakash/PROJECTS/LOGIN_AUTHENTICATION/myenv/lib/python3.8/site-packages/rest_framework/views.py", line 506, in dispatch
    response = handler(request, *args, **kwargs)
  File "/home/aakash/PROJECTS/LOGIN_AUTHENTICATION/Authentication_System/myapp/views.py", line 1352, in get
    print(list(raw_query))
TypeError: 'int' object is not iterable
2023-08-16 10:27:06 ERROR "GET /MANY_TO_MANY_ORM/ HTTP/1.1" 500 96067
2023-08-16 10:27:06 ERROR "GET /MANY_TO_MANY_ORM/ HTTP/1.1" 500 96067
2023-08-16 10:28:53 ERROR Internal Server Error: /MANY_TO_MANY_ORM/
Traceback (most recent call last):
  File "/home/aakash/PROJECTS/LOGIN_AUTHENTICATION/myenv/lib/python3.8/site-packages/django/db/backends/utils.py", line 87, in _execute
    return self.cursor.execute(sql)
  File "/home/aakash/PROJECTS/LOGIN_AUTHENTICATION/myenv/lib/python3.8/site-packages/django/db/backends/mysql/base.py", line 75, in execute
    return self.cursor.execute(query, args)
  File "/home/aakash/PROJECTS/LOGIN_AUTHENTICATION/myenv/lib/python3.8/site-packages/MySQLdb/cursors.py", line 179, in execute
    res = self._query(mogrified_query)
  File "/home/aakash/PROJECTS/LOGIN_AUTHENTICATION/myenv/lib/python3.8/site-packages/MySQLdb/cursors.py", line 330, in _query
    db.query(q)
  File "/home/aakash/PROJECTS/LOGIN_AUTHENTICATION/myenv/lib/python3.8/site-packages/MySQLdb/connections.py", line 255, in query
    _mysql.connection.query(self, query)
MySQLdb.OperationalError: (1054, "Unknown column 'myapp_author.name' in 'field list'")

The above exception was the direct cause of the following exception:

Traceback (most recent call last):
  File "/home/aakash/PROJECTS/LOGIN_AUTHENTICATION/myenv/lib/python3.8/site-packages/django/core/handlers/exception.py", line 55, in inner
    response = get_response(request)
  File "/home/aakash/PROJECTS/LOGIN_AUTHENTICATION/myenv/lib/python3.8/site-packages/django/core/handlers/base.py", line 197, in _get_response
    response = wrapped_callback(request, *callback_args, **callback_kwargs)
  File "/home/aakash/PROJECTS/LOGIN_AUTHENTICATION/myenv/lib/python3.8/site-packages/django/views/decorators/csrf.py", line 56, in wrapper_view
    return view_func(*args, **kwargs)
  File "/home/aakash/PROJECTS/LOGIN_AUTHENTICATION/myenv/lib/python3.8/site-packages/django/views/generic/base.py", line 104, in view
    return self.dispatch(request, *args, **kwargs)
  File "/home/aakash/PROJECTS/LOGIN_AUTHENTICATION/myenv/lib/python3.8/site-packages/rest_framework/views.py", line 509, in dispatch
    response = self.handle_exception(exc)
  File "/home/aakash/PROJECTS/LOGIN_AUTHENTICATION/myenv/lib/python3.8/site-packages/rest_framework/views.py", line 469, in handle_exception
    self.raise_uncaught_exception(exc)
  File "/home/aakash/PROJECTS/LOGIN_AUTHENTICATION/myenv/lib/python3.8/site-packages/rest_framework/views.py", line 480, in raise_uncaught_exception
    raise exc
  File "/home/aakash/PROJECTS/LOGIN_AUTHENTICATION/myenv/lib/python3.8/site-packages/rest_framework/views.py", line 506, in dispatch
    response = handler(request, *args, **kwargs)
  File "/home/aakash/PROJECTS/LOGIN_AUTHENTICATION/Authentication_System/myapp/views.py", line 1350, in get
    raw_query = cursor.execute(''' SELECT  myapp_author.name, myapp_book.title FROM myapp_author FULL JOIN myapp_book ON myapp_author.id = myapp_book.id WHERE myapp_author.id = 1; ''')
  File "/home/aakash/PROJECTS/LOGIN_AUTHENTICATION/myenv/lib/python3.8/site-packages/django/db/backends/utils.py", line 102, in execute
    return super().execute(sql, params)
  File "/home/aakash/PROJECTS/LOGIN_AUTHENTICATION/myenv/lib/python3.8/site-packages/django/db/backends/utils.py", line 67, in execute
    return self._execute_with_wrappers(
  File "/home/aakash/PROJECTS/LOGIN_AUTHENTICATION/myenv/lib/python3.8/site-packages/django/db/backends/utils.py", line 80, in _execute_with_wrappers
    return executor(sql, params, many, context)
  File "/home/aakash/PROJECTS/LOGIN_AUTHENTICATION/myenv/lib/python3.8/site-packages/django/db/backends/utils.py", line 89, in _execute
    return self.cursor.execute(sql, params)
  File "/home/aakash/PROJECTS/LOGIN_AUTHENTICATION/myenv/lib/python3.8/site-packages/django/db/utils.py", line 91, in __exit__
    raise dj_exc_value.with_traceback(traceback) from exc_value
  File "/home/aakash/PROJECTS/LOGIN_AUTHENTICATION/myenv/lib/python3.8/site-packages/django/db/backends/utils.py", line 87, in _execute
    return self.cursor.execute(sql)
  File "/home/aakash/PROJECTS/LOGIN_AUTHENTICATION/myenv/lib/python3.8/site-packages/django/db/backends/mysql/base.py", line 75, in execute
    return self.cursor.execute(query, args)
  File "/home/aakash/PROJECTS/LOGIN_AUTHENTICATION/myenv/lib/python3.8/site-packages/MySQLdb/cursors.py", line 179, in execute
    res = self._query(mogrified_query)
  File "/home/aakash/PROJECTS/LOGIN_AUTHENTICATION/myenv/lib/python3.8/site-packages/MySQLdb/cursors.py", line 330, in _query
    db.query(q)
  File "/home/aakash/PROJECTS/LOGIN_AUTHENTICATION/myenv/lib/python3.8/site-packages/MySQLdb/connections.py", line 255, in query
    _mysql.connection.query(self, query)
django.db.utils.OperationalError: (1054, "Unknown column 'myapp_author.name' in 'field list'")
2023-08-16 10:28:53 ERROR "GET /MANY_TO_MANY_ORM/ HTTP/1.1" 500 163517
2023-08-16 10:28:53 ERROR "GET /MANY_TO_MANY_ORM/ HTTP/1.1" 500 163517
2023-08-16 10:44:12 ERROR Internal Server Error: /MANY_TO_MANY_ORM/
Traceback (most recent call last):
  File "/home/aakash/PROJECTS/LOGIN_AUTHENTICATION/myenv/lib/python3.8/site-packages/django/db/backends/utils.py", line 87, in _execute
    return self.cursor.execute(sql)
  File "/home/aakash/PROJECTS/LOGIN_AUTHENTICATION/myenv/lib/python3.8/site-packages/django/db/backends/mysql/base.py", line 75, in execute
    return self.cursor.execute(query, args)
  File "/home/aakash/PROJECTS/LOGIN_AUTHENTICATION/myenv/lib/python3.8/site-packages/MySQLdb/cursors.py", line 179, in execute
    res = self._query(mogrified_query)
  File "/home/aakash/PROJECTS/LOGIN_AUTHENTICATION/myenv/lib/python3.8/site-packages/MySQLdb/cursors.py", line 330, in _query
    db.query(q)
  File "/home/aakash/PROJECTS/LOGIN_AUTHENTICATION/myenv/lib/python3.8/site-packages/MySQLdb/connections.py", line 255, in query
    _mysql.connection.query(self, query)
MySQLdb.OperationalError: (1054, "Unknown column 'myapp_author.name' in 'field list'")

The above exception was the direct cause of the following exception:

Traceback (most recent call last):
  File "/home/aakash/PROJECTS/LOGIN_AUTHENTICATION/myenv/lib/python3.8/site-packages/django/core/handlers/exception.py", line 55, in inner
    response = get_response(request)
  File "/home/aakash/PROJECTS/LOGIN_AUTHENTICATION/myenv/lib/python3.8/site-packages/django/core/handlers/base.py", line 197, in _get_response
    response = wrapped_callback(request, *callback_args, **callback_kwargs)
  File "/home/aakash/PROJECTS/LOGIN_AUTHENTICATION/myenv/lib/python3.8/site-packages/django/views/decorators/csrf.py", line 56, in wrapper_view
    return view_func(*args, **kwargs)
  File "/home/aakash/PROJECTS/LOGIN_AUTHENTICATION/myenv/lib/python3.8/site-packages/django/views/generic/base.py", line 104, in view
    return self.dispatch(request, *args, **kwargs)
  File "/home/aakash/PROJECTS/LOGIN_AUTHENTICATION/myenv/lib/python3.8/site-packages/rest_framework/views.py", line 509, in dispatch
    response = self.handle_exception(exc)
  File "/home/aakash/PROJECTS/LOGIN_AUTHENTICATION/myenv/lib/python3.8/site-packages/rest_framework/views.py", line 469, in handle_exception
    self.raise_uncaught_exception(exc)
  File "/home/aakash/PROJECTS/LOGIN_AUTHENTICATION/myenv/lib/python3.8/site-packages/rest_framework/views.py", line 480, in raise_uncaught_exception
    raise exc
  File "/home/aakash/PROJECTS/LOGIN_AUTHENTICATION/myenv/lib/python3.8/site-packages/rest_framework/views.py", line 506, in dispatch
    response = handler(request, *args, **kwargs)
  File "/home/aakash/PROJECTS/LOGIN_AUTHENTICATION/Authentication_System/myapp/views.py", line 1350, in get
    raw_query = cursor.execute(''' SELECT  myapp_author.name, myapp_book.title FROM myapp_author FULL JOIN myapp_book ON myapp_author.id = myapp_book.id WHERE myapp_author.id = 1; ''')
  File "/home/aakash/PROJECTS/LOGIN_AUTHENTICATION/myenv/lib/python3.8/site-packages/django/db/backends/utils.py", line 102, in execute
    return super().execute(sql, params)
  File "/home/aakash/PROJECTS/LOGIN_AUTHENTICATION/myenv/lib/python3.8/site-packages/django/db/backends/utils.py", line 67, in execute
    return self._execute_with_wrappers(
  File "/home/aakash/PROJECTS/LOGIN_AUTHENTICATION/myenv/lib/python3.8/site-packages/django/db/backends/utils.py", line 80, in _execute_with_wrappers
    return executor(sql, params, many, context)
  File "/home/aakash/PROJECTS/LOGIN_AUTHENTICATION/myenv/lib/python3.8/site-packages/django/db/backends/utils.py", line 89, in _execute
    return self.cursor.execute(sql, params)
  File "/home/aakash/PROJECTS/LOGIN_AUTHENTICATION/myenv/lib/python3.8/site-packages/django/db/utils.py", line 91, in __exit__
    raise dj_exc_value.with_traceback(traceback) from exc_value
  File "/home/aakash/PROJECTS/LOGIN_AUTHENTICATION/myenv/lib/python3.8/site-packages/django/db/backends/utils.py", line 87, in _execute
    return self.cursor.execute(sql)
  File "/home/aakash/PROJECTS/LOGIN_AUTHENTICATION/myenv/lib/python3.8/site-packages/django/db/backends/mysql/base.py", line 75, in execute
    return self.cursor.execute(query, args)
  File "/home/aakash/PROJECTS/LOGIN_AUTHENTICATION/myenv/lib/python3.8/site-packages/MySQLdb/cursors.py", line 179, in execute
    res = self._query(mogrified_query)
  File "/home/aakash/PROJECTS/LOGIN_AUTHENTICATION/myenv/lib/python3.8/site-packages/MySQLdb/cursors.py", line 330, in _query
    db.query(q)
  File "/home/aakash/PROJECTS/LOGIN_AUTHENTICATION/myenv/lib/python3.8/site-packages/MySQLdb/connections.py", line 255, in query
    _mysql.connection.query(self, query)
django.db.utils.OperationalError: (1054, "Unknown column 'myapp_author.name' in 'field list'")
2023-08-16 10:44:12 ERROR "GET /MANY_TO_MANY_ORM/ HTTP/1.1" 500 163336
2023-08-16 10:44:12 ERROR "GET /MANY_TO_MANY_ORM/ HTTP/1.1" 500 163336
2023-08-16 10:45:01 ERROR Internal Server Error: /MANY_TO_MANY_ORM/
Traceback (most recent call last):
  File "/home/aakash/PROJECTS/LOGIN_AUTHENTICATION/myenv/lib/python3.8/site-packages/django/core/handlers/exception.py", line 55, in inner
    response = get_response(request)
  File "/home/aakash/PROJECTS/LOGIN_AUTHENTICATION/myenv/lib/python3.8/site-packages/django/core/handlers/base.py", line 197, in _get_response
    response = wrapped_callback(request, *callback_args, **callback_kwargs)
  File "/home/aakash/PROJECTS/LOGIN_AUTHENTICATION/myenv/lib/python3.8/site-packages/django/views/decorators/csrf.py", line 56, in wrapper_view
    return view_func(*args, **kwargs)
  File "/home/aakash/PROJECTS/LOGIN_AUTHENTICATION/myenv/lib/python3.8/site-packages/django/views/generic/base.py", line 104, in view
    return self.dispatch(request, *args, **kwargs)
  File "/home/aakash/PROJECTS/LOGIN_AUTHENTICATION/myenv/lib/python3.8/site-packages/rest_framework/views.py", line 509, in dispatch
    response = self.handle_exception(exc)
  File "/home/aakash/PROJECTS/LOGIN_AUTHENTICATION/myenv/lib/python3.8/site-packages/rest_framework/views.py", line 469, in handle_exception
    self.raise_uncaught_exception(exc)
  File "/home/aakash/PROJECTS/LOGIN_AUTHENTICATION/myenv/lib/python3.8/site-packages/rest_framework/views.py", line 480, in raise_uncaught_exception
    raise exc
  File "/home/aakash/PROJECTS/LOGIN_AUTHENTICATION/myenv/lib/python3.8/site-packages/rest_framework/views.py", line 506, in dispatch
    response = handler(request, *args, **kwargs)
  File "/home/aakash/PROJECTS/LOGIN_AUTHENTICATION/Authentication_System/myapp/views.py", line 1351, in get
    results=raw_query.fetchall()
AttributeError: 'int' object has no attribute 'fetchall'
2023-08-16 10:45:01 ERROR "GET /MANY_TO_MANY_ORM/ HTTP/1.1" 500 96069
2023-08-16 10:45:01 ERROR "GET /MANY_TO_MANY_ORM/ HTTP/1.1" 500 96069
2023-08-16 10:53:13 ERROR Internal Server Error: /MANY_TO_MANY_ORM/
Traceback (most recent call last):
  File "/home/aakash/PROJECTS/LOGIN_AUTHENTICATION/myenv/lib/python3.8/site-packages/django/db/backends/utils.py", line 87, in _execute
    return self.cursor.execute(sql)
  File "/home/aakash/PROJECTS/LOGIN_AUTHENTICATION/myenv/lib/python3.8/site-packages/django/db/backends/mysql/base.py", line 75, in execute
    return self.cursor.execute(query, args)
  File "/home/aakash/PROJECTS/LOGIN_AUTHENTICATION/myenv/lib/python3.8/site-packages/MySQLdb/cursors.py", line 179, in execute
    res = self._query(mogrified_query)
  File "/home/aakash/PROJECTS/LOGIN_AUTHENTICATION/myenv/lib/python3.8/site-packages/MySQLdb/cursors.py", line 330, in _query
    db.query(q)
  File "/home/aakash/PROJECTS/LOGIN_AUTHENTICATION/myenv/lib/python3.8/site-packages/MySQLdb/connections.py", line 255, in query
    _mysql.connection.query(self, query)
MySQLdb.ProgrammingError: (1064, "You have an error in your SQL syntax; check the manual that corresponds to your MySQL server version for the right syntax to use near 'OUTER JOIN myapp_book ON myapp_author.id = myapp_book.id WHERE myapp_author.id =' at line 1")

The above exception was the direct cause of the following exception:

Traceback (most recent call last):
  File "/home/aakash/PROJECTS/LOGIN_AUTHENTICATION/myenv/lib/python3.8/site-packages/django/core/handlers/exception.py", line 55, in inner
    response = get_response(request)
  File "/home/aakash/PROJECTS/LOGIN_AUTHENTICATION/myenv/lib/python3.8/site-packages/django/core/handlers/base.py", line 197, in _get_response
    response = wrapped_callback(request, *callback_args, **callback_kwargs)
  File "/home/aakash/PROJECTS/LOGIN_AUTHENTICATION/myenv/lib/python3.8/site-packages/django/views/decorators/csrf.py", line 56, in wrapper_view
    return view_func(*args, **kwargs)
  File "/home/aakash/PROJECTS/LOGIN_AUTHENTICATION/myenv/lib/python3.8/site-packages/django/views/generic/base.py", line 104, in view
    return self.dispatch(request, *args, **kwargs)
  File "/home/aakash/PROJECTS/LOGIN_AUTHENTICATION/myenv/lib/python3.8/site-packages/rest_framework/views.py", line 509, in dispatch
    response = self.handle_exception(exc)
  File "/home/aakash/PROJECTS/LOGIN_AUTHENTICATION/myenv/lib/python3.8/site-packages/rest_framework/views.py", line 469, in handle_exception
    self.raise_uncaught_exception(exc)
  File "/home/aakash/PROJECTS/LOGIN_AUTHENTICATION/myenv/lib/python3.8/site-packages/rest_framework/views.py", line 480, in raise_uncaught_exception
    raise exc
  File "/home/aakash/PROJECTS/LOGIN_AUTHENTICATION/myenv/lib/python3.8/site-packages/rest_framework/views.py", line 506, in dispatch
    response = handler(request, *args, **kwargs)
  File "/home/aakash/PROJECTS/LOGIN_AUTHENTICATION/Authentication_System/myapp/views.py", line 1350, in get
    raw_query = cursor.execute(''' SELECT  myapp_author.name, myapp_book.title FROM myapp_author OUTER JOIN myapp_book ON myapp_author.id = myapp_book.id WHERE myapp_author.id = 1; ''')
  File "/home/aakash/PROJECTS/LOGIN_AUTHENTICATION/myenv/lib/python3.8/site-packages/django/db/backends/utils.py", line 102, in execute
    return super().execute(sql, params)
  File "/home/aakash/PROJECTS/LOGIN_AUTHENTICATION/myenv/lib/python3.8/site-packages/django/db/backends/utils.py", line 67, in execute
    return self._execute_with_wrappers(
  File "/home/aakash/PROJECTS/LOGIN_AUTHENTICATION/myenv/lib/python3.8/site-packages/django/db/backends/utils.py", line 80, in _execute_with_wrappers
    return executor(sql, params, many, context)
  File "/home/aakash/PROJECTS/LOGIN_AUTHENTICATION/myenv/lib/python3.8/site-packages/django/db/backends/utils.py", line 89, in _execute
    return self.cursor.execute(sql, params)
  File "/home/aakash/PROJECTS/LOGIN_AUTHENTICATION/myenv/lib/python3.8/site-packages/django/db/utils.py", line 91, in __exit__
    raise dj_exc_value.with_traceback(traceback) from exc_value
  File "/home/aakash/PROJECTS/LOGIN_AUTHENTICATION/myenv/lib/python3.8/site-packages/django/db/backends/utils.py", line 87, in _execute
    return self.cursor.execute(sql)
  File "/home/aakash/PROJECTS/LOGIN_AUTHENTICATION/myenv/lib/python3.8/site-packages/django/db/backends/mysql/base.py", line 75, in execute
    return self.cursor.execute(query, args)
  File "/home/aakash/PROJECTS/LOGIN_AUTHENTICATION/myenv/lib/python3.8/site-packages/MySQLdb/cursors.py", line 179, in execute
    res = self._query(mogrified_query)
  File "/home/aakash/PROJECTS/LOGIN_AUTHENTICATION/myenv/lib/python3.8/site-packages/MySQLdb/cursors.py", line 330, in _query
    db.query(q)
  File "/home/aakash/PROJECTS/LOGIN_AUTHENTICATION/myenv/lib/python3.8/site-packages/MySQLdb/connections.py", line 255, in query
    _mysql.connection.query(self, query)
django.db.utils.ProgrammingError: (1064, "You have an error in your SQL syntax; check the manual that corresponds to your MySQL server version for the right syntax to use near 'OUTER JOIN myapp_book ON myapp_author.id = myapp_book.id WHERE myapp_author.id =' at line 1")
2023-08-16 10:53:13 ERROR "GET /MANY_TO_MANY_ORM/ HTTP/1.1" 500 164988
2023-08-16 10:53:13 ERROR "GET /MANY_TO_MANY_ORM/ HTTP/1.1" 500 164988
2023-08-17 11:27:22 ERROR Internal Server Error: /MANY_TO_MANY_ORM/
Traceback (most recent call last):
  File "/home/aakash/PROJECTS/LOGIN_AUTHENTICATION/myenv/lib/python3.8/site-packages/django/core/handlers/exception.py", line 55, in inner
    response = get_response(request)
  File "/home/aakash/PROJECTS/LOGIN_AUTHENTICATION/myenv/lib/python3.8/site-packages/django/core/handlers/base.py", line 197, in _get_response
    response = wrapped_callback(request, *callback_args, **callback_kwargs)
  File "/home/aakash/PROJECTS/LOGIN_AUTHENTICATION/myenv/lib/python3.8/site-packages/django/views/decorators/csrf.py", line 56, in wrapper_view
    return view_func(*args, **kwargs)
  File "/home/aakash/PROJECTS/LOGIN_AUTHENTICATION/myenv/lib/python3.8/site-packages/django/views/generic/base.py", line 104, in view
    return self.dispatch(request, *args, **kwargs)
  File "/home/aakash/PROJECTS/LOGIN_AUTHENTICATION/myenv/lib/python3.8/site-packages/rest_framework/views.py", line 509, in dispatch
    response = self.handle_exception(exc)
  File "/home/aakash/PROJECTS/LOGIN_AUTHENTICATION/myenv/lib/python3.8/site-packages/rest_framework/views.py", line 469, in handle_exception
    self.raise_uncaught_exception(exc)
  File "/home/aakash/PROJECTS/LOGIN_AUTHENTICATION/myenv/lib/python3.8/site-packages/rest_framework/views.py", line 480, in raise_uncaught_exception
    raise exc
  File "/home/aakash/PROJECTS/LOGIN_AUTHENTICATION/myenv/lib/python3.8/site-packages/rest_framework/views.py", line 506, in dispatch
    response = handler(request, *args, **kwargs)
  File "/home/aakash/PROJECTS/LOGIN_AUTHENTICATION/Authentication_System/myapp/views.py", line 1360, in get
    result2= raw_query_2.fetchall()
AttributeError: 'int' object has no attribute 'fetchall'
2023-08-17 11:27:22 ERROR "GET /MANY_TO_MANY_ORM/ HTTP/1.1" 500 97121
2023-08-17 11:27:22 ERROR "GET /MANY_TO_MANY_ORM/ HTTP/1.1" 500 97121
2023-08-17 12:13:21 ERROR Internal Server Error: /MANY_TO_MANY_ORM/
Traceback (most recent call last):
  File "/home/aakash/PROJECTS/LOGIN_AUTHENTICATION/myenv/lib/python3.8/site-packages/django/core/handlers/exception.py", line 55, in inner
    response = get_response(request)
  File "/home/aakash/PROJECTS/LOGIN_AUTHENTICATION/myenv/lib/python3.8/site-packages/django/core/handlers/base.py", line 197, in _get_response
    response = wrapped_callback(request, *callback_args, **callback_kwargs)
  File "/home/aakash/PROJECTS/LOGIN_AUTHENTICATION/myenv/lib/python3.8/site-packages/django/views/decorators/csrf.py", line 56, in wrapper_view
    return view_func(*args, **kwargs)
  File "/home/aakash/PROJECTS/LOGIN_AUTHENTICATION/myenv/lib/python3.8/site-packages/django/views/generic/base.py", line 104, in view
    return self.dispatch(request, *args, **kwargs)
  File "/home/aakash/PROJECTS/LOGIN_AUTHENTICATION/myenv/lib/python3.8/site-packages/rest_framework/views.py", line 509, in dispatch
    response = self.handle_exception(exc)
  File "/home/aakash/PROJECTS/LOGIN_AUTHENTICATION/myenv/lib/python3.8/site-packages/rest_framework/views.py", line 469, in handle_exception
    self.raise_uncaught_exception(exc)
  File "/home/aakash/PROJECTS/LOGIN_AUTHENTICATION/myenv/lib/python3.8/site-packages/rest_framework/views.py", line 480, in raise_uncaught_exception
    raise exc
  File "/home/aakash/PROJECTS/LOGIN_AUTHENTICATION/myenv/lib/python3.8/site-packages/rest_framework/views.py", line 506, in dispatch
    response = handler(request, *args, **kwargs)
  File "/home/aakash/PROJECTS/LOGIN_AUTHENTICATION/Authentication_System/myapp/views.py", line 1371, in get
    cursor = cursor.connection()
TypeError: 'Connection' object is not callable
2023-08-17 12:13:21 ERROR "GET /MANY_TO_MANY_ORM/ HTTP/1.1" 500 98962
2023-08-17 12:13:21 ERROR "GET /MANY_TO_MANY_ORM/ HTTP/1.1" 500 98962
2023-08-18 12:00:24 ERROR Internal Server Error: /MANY_TO_MANY_ORM/
Traceback (most recent call last):
  File "/home/aakash/PROJECTS/LOGIN_AUTHENTICATION/myenv/lib/python3.8/site-packages/django/db/backends/utils.py", line 87, in _execute
    return self.cursor.execute(sql)
  File "/home/aakash/PROJECTS/LOGIN_AUTHENTICATION/myenv/lib/python3.8/site-packages/django/db/backends/mysql/base.py", line 75, in execute
    return self.cursor.execute(query, args)
  File "/home/aakash/PROJECTS/LOGIN_AUTHENTICATION/myenv/lib/python3.8/site-packages/MySQLdb/cursors.py", line 179, in execute
    res = self._query(mogrified_query)
  File "/home/aakash/PROJECTS/LOGIN_AUTHENTICATION/myenv/lib/python3.8/site-packages/MySQLdb/cursors.py", line 330, in _query
    db.query(q)
  File "/home/aakash/PROJECTS/LOGIN_AUTHENTICATION/myenv/lib/python3.8/site-packages/MySQLdb/connections.py", line 255, in query
    _mysql.connection.query(self, query)
MySQLdb.ProgrammingError: (1064, "You have an error in your SQL syntax; check the manual that corresponds to your MySQL server version for the right syntax to use near 'author_books.author_id  = myapp_author.id\n                            GROUP  BY ' at line 4")

The above exception was the direct cause of the following exception:

Traceback (most recent call last):
  File "/home/aakash/PROJECTS/LOGIN_AUTHENTICATION/myenv/lib/python3.8/site-packages/django/core/handlers/exception.py", line 55, in inner
    response = get_response(request)
  File "/home/aakash/PROJECTS/LOGIN_AUTHENTICATION/myenv/lib/python3.8/site-packages/django/core/handlers/base.py", line 197, in _get_response
    response = wrapped_callback(request, *callback_args, **callback_kwargs)
  File "/home/aakash/PROJECTS/LOGIN_AUTHENTICATION/myenv/lib/python3.8/site-packages/django/views/decorators/csrf.py", line 56, in wrapper_view
    return view_func(*args, **kwargs)
  File "/home/aakash/PROJECTS/LOGIN_AUTHENTICATION/myenv/lib/python3.8/site-packages/django/views/generic/base.py", line 104, in view
    return self.dispatch(request, *args, **kwargs)
  File "/home/aakash/PROJECTS/LOGIN_AUTHENTICATION/myenv/lib/python3.8/site-packages/rest_framework/views.py", line 509, in dispatch
    response = self.handle_exception(exc)
  File "/home/aakash/PROJECTS/LOGIN_AUTHENTICATION/myenv/lib/python3.8/site-packages/rest_framework/views.py", line 469, in handle_exception
    self.raise_uncaught_exception(exc)
  File "/home/aakash/PROJECTS/LOGIN_AUTHENTICATION/myenv/lib/python3.8/site-packages/rest_framework/views.py", line 480, in raise_uncaught_exception
    raise exc
  File "/home/aakash/PROJECTS/LOGIN_AUTHENTICATION/myenv/lib/python3.8/site-packages/rest_framework/views.py", line 506, in dispatch
    response = handler(request, *args, **kwargs)
  File "/home/aakash/PROJECTS/LOGIN_AUTHENTICATION/Authentication_System/myapp/views.py", line 1454, in get
    cursor.execute('''  SELECT  myapp_author.name ,COUNT(myapp_author_books.id) AS book_count
  File "/home/aakash/PROJECTS/LOGIN_AUTHENTICATION/myenv/lib/python3.8/site-packages/django/db/backends/utils.py", line 102, in execute
    return super().execute(sql, params)
  File "/home/aakash/PROJECTS/LOGIN_AUTHENTICATION/myenv/lib/python3.8/site-packages/django/db/backends/utils.py", line 67, in execute
    return self._execute_with_wrappers(
  File "/home/aakash/PROJECTS/LOGIN_AUTHENTICATION/myenv/lib/python3.8/site-packages/django/db/backends/utils.py", line 80, in _execute_with_wrappers
    return executor(sql, params, many, context)
  File "/home/aakash/PROJECTS/LOGIN_AUTHENTICATION/myenv/lib/python3.8/site-packages/django/db/backends/utils.py", line 89, in _execute
    return self.cursor.execute(sql, params)
  File "/home/aakash/PROJECTS/LOGIN_AUTHENTICATION/myenv/lib/python3.8/site-packages/django/db/utils.py", line 91, in __exit__
    raise dj_exc_value.with_traceback(traceback) from exc_value
  File "/home/aakash/PROJECTS/LOGIN_AUTHENTICATION/myenv/lib/python3.8/site-packages/django/db/backends/utils.py", line 87, in _execute
    return self.cursor.execute(sql)
  File "/home/aakash/PROJECTS/LOGIN_AUTHENTICATION/myenv/lib/python3.8/site-packages/django/db/backends/mysql/base.py", line 75, in execute
    return self.cursor.execute(query, args)
  File "/home/aakash/PROJECTS/LOGIN_AUTHENTICATION/myenv/lib/python3.8/site-packages/MySQLdb/cursors.py", line 179, in execute
    res = self._query(mogrified_query)
  File "/home/aakash/PROJECTS/LOGIN_AUTHENTICATION/myenv/lib/python3.8/site-packages/MySQLdb/cursors.py", line 330, in _query
    db.query(q)
  File "/home/aakash/PROJECTS/LOGIN_AUTHENTICATION/myenv/lib/python3.8/site-packages/MySQLdb/connections.py", line 255, in query
    _mysql.connection.query(self, query)
django.db.utils.ProgrammingError: (1064, "You have an error in your SQL syntax; check the manual that corresponds to your MySQL server version for the right syntax to use near 'author_books.author_id  = myapp_author.id\n                            GROUP  BY ' at line 4")
2023-08-18 12:00:24 ERROR "GET /MANY_TO_MANY_ORM/ HTTP/1.1" 500 176803
2023-08-18 12:00:24 ERROR "GET /MANY_TO_MANY_ORM/ HTTP/1.1" 500 176803
2023-08-18 12:00:57 ERROR Internal Server Error: /MANY_TO_MANY_ORM/
Traceback (most recent call last):
  File "/home/aakash/PROJECTS/LOGIN_AUTHENTICATION/myenv/lib/python3.8/site-packages/django/db/backends/utils.py", line 87, in _execute
    return self.cursor.execute(sql)
  File "/home/aakash/PROJECTS/LOGIN_AUTHENTICATION/myenv/lib/python3.8/site-packages/django/db/backends/mysql/base.py", line 75, in execute
    return self.cursor.execute(query, args)
  File "/home/aakash/PROJECTS/LOGIN_AUTHENTICATION/myenv/lib/python3.8/site-packages/MySQLdb/cursors.py", line 179, in execute
    res = self._query(mogrified_query)
  File "/home/aakash/PROJECTS/LOGIN_AUTHENTICATION/myenv/lib/python3.8/site-packages/MySQLdb/cursors.py", line 330, in _query
    db.query(q)
  File "/home/aakash/PROJECTS/LOGIN_AUTHENTICATION/myenv/lib/python3.8/site-packages/MySQLdb/connections.py", line 255, in query
    _mysql.connection.query(self, query)
MySQLdb.ProgrammingError: (1064, "You have an error in your SQL syntax; check the manual that corresponds to your MySQL server version for the right syntax to use near 'author_books.author_id  = myapp_author.id\n                            GROUP  BY ' at line 4")

The above exception was the direct cause of the following exception:

Traceback (most recent call last):
  File "/home/aakash/PROJECTS/LOGIN_AUTHENTICATION/myenv/lib/python3.8/site-packages/django/core/handlers/exception.py", line 55, in inner
    response = get_response(request)
  File "/home/aakash/PROJECTS/LOGIN_AUTHENTICATION/myenv/lib/python3.8/site-packages/django/core/handlers/base.py", line 197, in _get_response
    response = wrapped_callback(request, *callback_args, **callback_kwargs)
  File "/home/aakash/PROJECTS/LOGIN_AUTHENTICATION/myenv/lib/python3.8/site-packages/django/views/decorators/csrf.py", line 56, in wrapper_view
    return view_func(*args, **kwargs)
  File "/home/aakash/PROJECTS/LOGIN_AUTHENTICATION/myenv/lib/python3.8/site-packages/django/views/generic/base.py", line 104, in view
    return self.dispatch(request, *args, **kwargs)
  File "/home/aakash/PROJECTS/LOGIN_AUTHENTICATION/myenv/lib/python3.8/site-packages/rest_framework/views.py", line 509, in dispatch
    response = self.handle_exception(exc)
  File "/home/aakash/PROJECTS/LOGIN_AUTHENTICATION/myenv/lib/python3.8/site-packages/rest_framework/views.py", line 469, in handle_exception
    self.raise_uncaught_exception(exc)
  File "/home/aakash/PROJECTS/LOGIN_AUTHENTICATION/myenv/lib/python3.8/site-packages/rest_framework/views.py", line 480, in raise_uncaught_exception
    raise exc
  File "/home/aakash/PROJECTS/LOGIN_AUTHENTICATION/myenv/lib/python3.8/site-packages/rest_framework/views.py", line 506, in dispatch
    response = handler(request, *args, **kwargs)
  File "/home/aakash/PROJECTS/LOGIN_AUTHENTICATION/Authentication_System/myapp/views.py", line 1454, in get
    cursor.execute('''  SELECT  myapp_author.name ,COUNT(myapp_author_books.id) AS book_count
  File "/home/aakash/PROJECTS/LOGIN_AUTHENTICATION/myenv/lib/python3.8/site-packages/django/db/backends/utils.py", line 102, in execute
    return super().execute(sql, params)
  File "/home/aakash/PROJECTS/LOGIN_AUTHENTICATION/myenv/lib/python3.8/site-packages/django/db/backends/utils.py", line 67, in execute
    return self._execute_with_wrappers(
  File "/home/aakash/PROJECTS/LOGIN_AUTHENTICATION/myenv/lib/python3.8/site-packages/django/db/backends/utils.py", line 80, in _execute_with_wrappers
    return executor(sql, params, many, context)
  File "/home/aakash/PROJECTS/LOGIN_AUTHENTICATION/myenv/lib/python3.8/site-packages/django/db/backends/utils.py", line 89, in _execute
    return self.cursor.execute(sql, params)
  File "/home/aakash/PROJECTS/LOGIN_AUTHENTICATION/myenv/lib/python3.8/site-packages/django/db/utils.py", line 91, in __exit__
    raise dj_exc_value.with_traceback(traceback) from exc_value
  File "/home/aakash/PROJECTS/LOGIN_AUTHENTICATION/myenv/lib/python3.8/site-packages/django/db/backends/utils.py", line 87, in _execute
    return self.cursor.execute(sql)
  File "/home/aakash/PROJECTS/LOGIN_AUTHENTICATION/myenv/lib/python3.8/site-packages/django/db/backends/mysql/base.py", line 75, in execute
    return self.cursor.execute(query, args)
  File "/home/aakash/PROJECTS/LOGIN_AUTHENTICATION/myenv/lib/python3.8/site-packages/MySQLdb/cursors.py", line 179, in execute
    res = self._query(mogrified_query)
  File "/home/aakash/PROJECTS/LOGIN_AUTHENTICATION/myenv/lib/python3.8/site-packages/MySQLdb/cursors.py", line 330, in _query
    db.query(q)
  File "/home/aakash/PROJECTS/LOGIN_AUTHENTICATION/myenv/lib/python3.8/site-packages/MySQLdb/connections.py", line 255, in query
    _mysql.connection.query(self, query)
django.db.utils.ProgrammingError: (1064, "You have an error in your SQL syntax; check the manual that corresponds to your MySQL server version for the right syntax to use near 'author_books.author_id  = myapp_author.id\n                            GROUP  BY ' at line 4")
2023-08-18 12:00:57 ERROR "GET /MANY_TO_MANY_ORM/ HTTP/1.1" 500 176820
2023-08-18 12:00:57 ERROR "GET /MANY_TO_MANY_ORM/ HTTP/1.1" 500 176820
2023-08-21 10:50:45 ERROR Internal Server Error: /get_orm_foreignKey_relation/
Traceback (most recent call last):
  File "/home/aakash/PROJECTS/LOGIN_AUTHENTICATION/myenv/lib/python3.8/site-packages/django/core/handlers/exception.py", line 55, in inner
    response = get_response(request)
  File "/home/aakash/PROJECTS/LOGIN_AUTHENTICATION/myenv/lib/python3.8/site-packages/django/core/handlers/base.py", line 197, in _get_response
    response = wrapped_callback(request, *callback_args, **callback_kwargs)
  File "/home/aakash/PROJECTS/LOGIN_AUTHENTICATION/myenv/lib/python3.8/site-packages/django/views/decorators/csrf.py", line 56, in wrapper_view
    return view_func(*args, **kwargs)
  File "/home/aakash/PROJECTS/LOGIN_AUTHENTICATION/myenv/lib/python3.8/site-packages/django/views/generic/base.py", line 104, in view
    return self.dispatch(request, *args, **kwargs)
  File "/home/aakash/PROJECTS/LOGIN_AUTHENTICATION/myenv/lib/python3.8/site-packages/rest_framework/views.py", line 509, in dispatch
    response = self.handle_exception(exc)
  File "/home/aakash/PROJECTS/LOGIN_AUTHENTICATION/myenv/lib/python3.8/site-packages/rest_framework/views.py", line 469, in handle_exception
    self.raise_uncaught_exception(exc)
  File "/home/aakash/PROJECTS/LOGIN_AUTHENTICATION/myenv/lib/python3.8/site-packages/rest_framework/views.py", line 480, in raise_uncaught_exception
    raise exc
  File "/home/aakash/PROJECTS/LOGIN_AUTHENTICATION/myenv/lib/python3.8/site-packages/rest_framework/views.py", line 506, in dispatch
    response = handler(request, *args, **kwargs)
  File "/home/aakash/PROJECTS/LOGIN_AUTHENTICATION/Authentication_System/myapp/views.py", line 1118, in get
    print(students)
UnboundLocalError: local variable 'students' referenced before assignment
2023-08-21 10:50:45 ERROR "GET /get_orm_foreignKey_relation/ HTTP/1.1" 500 99994
2023-08-21 10:50:45 ERROR "GET /get_orm_foreignKey_relation/ HTTP/1.1" 500 99994
2023-08-23 07:44:14 ERROR Internal Server Error: /get_orm_foreignKey_relation/
Traceback (most recent call last):
  File "/home/aakash/PROJECTS/LOGIN_AUTHENTICATION/myenv/lib/python3.8/site-packages/django/db/backends/utils.py", line 87, in _execute
    return self.cursor.execute(sql)
  File "/home/aakash/PROJECTS/LOGIN_AUTHENTICATION/myenv/lib/python3.8/site-packages/django/db/backends/mysql/base.py", line 75, in execute
    return self.cursor.execute(query, args)
  File "/home/aakash/PROJECTS/LOGIN_AUTHENTICATION/myenv/lib/python3.8/site-packages/MySQLdb/cursors.py", line 179, in execute
    res = self._query(mogrified_query)
  File "/home/aakash/PROJECTS/LOGIN_AUTHENTICATION/myenv/lib/python3.8/site-packages/MySQLdb/cursors.py", line 330, in _query
    db.query(q)
  File "/home/aakash/PROJECTS/LOGIN_AUTHENTICATION/myenv/lib/python3.8/site-packages/MySQLdb/connections.py", line 255, in query
    _mysql.connection.query(self, query)
MySQLdb.OperationalError: (1054, "Unknown column 'myapp_departments.university_id' in 'on clause'")

The above exception was the direct cause of the following exception:

Traceback (most recent call last):
  File "/home/aakash/PROJECTS/LOGIN_AUTHENTICATION/myenv/lib/python3.8/site-packages/django/core/handlers/exception.py", line 55, in inner
    response = get_response(request)
  File "/home/aakash/PROJECTS/LOGIN_AUTHENTICATION/myenv/lib/python3.8/site-packages/django/core/handlers/base.py", line 197, in _get_response
    response = wrapped_callback(request, *callback_args, **callback_kwargs)
  File "/home/aakash/PROJECTS/LOGIN_AUTHENTICATION/myenv/lib/python3.8/site-packages/django/views/decorators/csrf.py", line 56, in wrapper_view
    return view_func(*args, **kwargs)
  File "/home/aakash/PROJECTS/LOGIN_AUTHENTICATION/myenv/lib/python3.8/site-packages/django/views/generic/base.py", line 104, in view
    return self.dispatch(request, *args, **kwargs)
  File "/home/aakash/PROJECTS/LOGIN_AUTHENTICATION/myenv/lib/python3.8/site-packages/rest_framework/views.py", line 509, in dispatch
    response = self.handle_exception(exc)
  File "/home/aakash/PROJECTS/LOGIN_AUTHENTICATION/myenv/lib/python3.8/site-packages/rest_framework/views.py", line 469, in handle_exception
    self.raise_uncaught_exception(exc)
  File "/home/aakash/PROJECTS/LOGIN_AUTHENTICATION/myenv/lib/python3.8/site-packages/rest_framework/views.py", line 480, in raise_uncaught_exception
    raise exc
  File "/home/aakash/PROJECTS/LOGIN_AUTHENTICATION/myenv/lib/python3.8/site-packages/rest_framework/views.py", line 506, in dispatch
    response = handler(request, *args, **kwargs)
  File "/home/aakash/PROJECTS/LOGIN_AUTHENTICATION/Authentication_System/myapp/views.py", line 1273, in get
    cursor.execute('''  SELECT myapp_department.id , myapp_department.department_name , myapp_university.university_name
  File "/home/aakash/PROJECTS/LOGIN_AUTHENTICATION/myenv/lib/python3.8/site-packages/django/db/backends/utils.py", line 102, in execute
    return super().execute(sql, params)
  File "/home/aakash/PROJECTS/LOGIN_AUTHENTICATION/myenv/lib/python3.8/site-packages/django/db/backends/utils.py", line 67, in execute
    return self._execute_with_wrappers(
  File "/home/aakash/PROJECTS/LOGIN_AUTHENTICATION/myenv/lib/python3.8/site-packages/django/db/backends/utils.py", line 80, in _execute_with_wrappers
    return executor(sql, params, many, context)
  File "/home/aakash/PROJECTS/LOGIN_AUTHENTICATION/myenv/lib/python3.8/site-packages/django/db/backends/utils.py", line 89, in _execute
    return self.cursor.execute(sql, params)
  File "/home/aakash/PROJECTS/LOGIN_AUTHENTICATION/myenv/lib/python3.8/site-packages/django/db/utils.py", line 91, in __exit__
    raise dj_exc_value.with_traceback(traceback) from exc_value
  File "/home/aakash/PROJECTS/LOGIN_AUTHENTICATION/myenv/lib/python3.8/site-packages/django/db/backends/utils.py", line 87, in _execute
    return self.cursor.execute(sql)
  File "/home/aakash/PROJECTS/LOGIN_AUTHENTICATION/myenv/lib/python3.8/site-packages/django/db/backends/mysql/base.py", line 75, in execute
    return self.cursor.execute(query, args)
  File "/home/aakash/PROJECTS/LOGIN_AUTHENTICATION/myenv/lib/python3.8/site-packages/MySQLdb/cursors.py", line 179, in execute
    res = self._query(mogrified_query)
  File "/home/aakash/PROJECTS/LOGIN_AUTHENTICATION/myenv/lib/python3.8/site-packages/MySQLdb/cursors.py", line 330, in _query
    db.query(q)
  File "/home/aakash/PROJECTS/LOGIN_AUTHENTICATION/myenv/lib/python3.8/site-packages/MySQLdb/connections.py", line 255, in query
    _mysql.connection.query(self, query)
django.db.utils.OperationalError: (1054, "Unknown column 'myapp_departments.university_id' in 'on clause'")
2023-08-23 07:44:14 ERROR "GET /get_orm_foreignKey_relation/ HTTP/1.1" 500 185249
2023-08-23 07:44:14 ERROR "GET /get_orm_foreignKey_relation/ HTTP/1.1" 500 185249
2023-08-23 10:07:17 ERROR Internal Server Error: /get_orm_foreignKey_relation/
Traceback (most recent call last):
  File "/home/aakash/PROJECTS/LOGIN_AUTHENTICATION/myenv/lib/python3.8/site-packages/django/db/backends/utils.py", line 87, in _execute
    return self.cursor.execute(sql)
  File "/home/aakash/PROJECTS/LOGIN_AUTHENTICATION/myenv/lib/python3.8/site-packages/django/db/backends/mysql/base.py", line 75, in execute
    return self.cursor.execute(query, args)
  File "/home/aakash/PROJECTS/LOGIN_AUTHENTICATION/myenv/lib/python3.8/site-packages/MySQLdb/cursors.py", line 179, in execute
    res = self._query(mogrified_query)
  File "/home/aakash/PROJECTS/LOGIN_AUTHENTICATION/myenv/lib/python3.8/site-packages/MySQLdb/cursors.py", line 330, in _query
    db.query(q)
  File "/home/aakash/PROJECTS/LOGIN_AUTHENTICATION/myenv/lib/python3.8/site-packages/MySQLdb/connections.py", line 255, in query
    _mysql.connection.query(self, query)
MySQLdb.OperationalError: (1054, "Unknown column 'myapp_departments.university_id' in 'on clause'")

The above exception was the direct cause of the following exception:

Traceback (most recent call last):
  File "/home/aakash/PROJECTS/LOGIN_AUTHENTICATION/myenv/lib/python3.8/site-packages/django/core/handlers/exception.py", line 55, in inner
    response = get_response(request)
  File "/home/aakash/PROJECTS/LOGIN_AUTHENTICATION/myenv/lib/python3.8/site-packages/django/core/handlers/base.py", line 197, in _get_response
    response = wrapped_callback(request, *callback_args, **callback_kwargs)
  File "/home/aakash/PROJECTS/LOGIN_AUTHENTICATION/myenv/lib/python3.8/site-packages/django/views/decorators/csrf.py", line 56, in wrapper_view
    return view_func(*args, **kwargs)
  File "/home/aakash/PROJECTS/LOGIN_AUTHENTICATION/myenv/lib/python3.8/site-packages/django/views/generic/base.py", line 104, in view
    return self.dispatch(request, *args, **kwargs)
  File "/home/aakash/PROJECTS/LOGIN_AUTHENTICATION/myenv/lib/python3.8/site-packages/rest_framework/views.py", line 509, in dispatch
    response = self.handle_exception(exc)
  File "/home/aakash/PROJECTS/LOGIN_AUTHENTICATION/myenv/lib/python3.8/site-packages/rest_framework/views.py", line 469, in handle_exception
    self.raise_uncaught_exception(exc)
  File "/home/aakash/PROJECTS/LOGIN_AUTHENTICATION/myenv/lib/python3.8/site-packages/rest_framework/views.py", line 480, in raise_uncaught_exception
    raise exc
  File "/home/aakash/PROJECTS/LOGIN_AUTHENTICATION/myenv/lib/python3.8/site-packages/rest_framework/views.py", line 506, in dispatch
    response = handler(request, *args, **kwargs)
  File "/home/aakash/PROJECTS/LOGIN_AUTHENTICATION/Authentication_System/myapp/views.py", line 1273, in get
    cursor.execute('''  SELECT myapp_department.id , myapp_department.department_name , myapp_university.university_name
  File "/home/aakash/PROJECTS/LOGIN_AUTHENTICATION/myenv/lib/python3.8/site-packages/django/db/backends/utils.py", line 102, in execute
    return super().execute(sql, params)
  File "/home/aakash/PROJECTS/LOGIN_AUTHENTICATION/myenv/lib/python3.8/site-packages/django/db/backends/utils.py", line 67, in execute
    return self._execute_with_wrappers(
  File "/home/aakash/PROJECTS/LOGIN_AUTHENTICATION/myenv/lib/python3.8/site-packages/django/db/backends/utils.py", line 80, in _execute_with_wrappers
    return executor(sql, params, many, context)
  File "/home/aakash/PROJECTS/LOGIN_AUTHENTICATION/myenv/lib/python3.8/site-packages/django/db/backends/utils.py", line 89, in _execute
    return self.cursor.execute(sql, params)
  File "/home/aakash/PROJECTS/LOGIN_AUTHENTICATION/myenv/lib/python3.8/site-packages/django/db/utils.py", line 91, in __exit__
    raise dj_exc_value.with_traceback(traceback) from exc_value
  File "/home/aakash/PROJECTS/LOGIN_AUTHENTICATION/myenv/lib/python3.8/site-packages/django/db/backends/utils.py", line 87, in _execute
    return self.cursor.execute(sql)
  File "/home/aakash/PROJECTS/LOGIN_AUTHENTICATION/myenv/lib/python3.8/site-packages/django/db/backends/mysql/base.py", line 75, in execute
    return self.cursor.execute(query, args)
  File "/home/aakash/PROJECTS/LOGIN_AUTHENTICATION/myenv/lib/python3.8/site-packages/MySQLdb/cursors.py", line 179, in execute
    res = self._query(mogrified_query)
  File "/home/aakash/PROJECTS/LOGIN_AUTHENTICATION/myenv/lib/python3.8/site-packages/MySQLdb/cursors.py", line 330, in _query
    db.query(q)
  File "/home/aakash/PROJECTS/LOGIN_AUTHENTICATION/myenv/lib/python3.8/site-packages/MySQLdb/connections.py", line 255, in query
    _mysql.connection.query(self, query)
django.db.utils.OperationalError: (1054, "Unknown column 'myapp_departments.university_id' in 'on clause'")
2023-08-23 10:07:17 ERROR "GET /get_orm_foreignKey_relation/ HTTP/1.1" 500 185249
2023-08-23 10:07:17 ERROR "GET /get_orm_foreignKey_relation/ HTTP/1.1" 500 185249
2023-08-24 07:45:17 ERROR Internal Server Error: /get_orm_foreignKey_relation/
Traceback (most recent call last):
  File "/home/aakash/PROJECTS/LOGIN_AUTHENTICATION/myenv/lib/python3.8/site-packages/django/db/backends/utils.py", line 87, in _execute
    return self.cursor.execute(sql)
  File "/home/aakash/PROJECTS/LOGIN_AUTHENTICATION/myenv/lib/python3.8/site-packages/django/db/backends/mysql/base.py", line 75, in execute
    return self.cursor.execute(query, args)
  File "/home/aakash/PROJECTS/LOGIN_AUTHENTICATION/myenv/lib/python3.8/site-packages/MySQLdb/cursors.py", line 179, in execute
    res = self._query(mogrified_query)
  File "/home/aakash/PROJECTS/LOGIN_AUTHENTICATION/myenv/lib/python3.8/site-packages/MySQLdb/cursors.py", line 330, in _query
    db.query(q)
  File "/home/aakash/PROJECTS/LOGIN_AUTHENTICATION/myenv/lib/python3.8/site-packages/MySQLdb/connections.py", line 255, in query
    _mysql.connection.query(self, query)
MySQLdb.OperationalError: (1054, "Unknown column 'myapp_universitys.id' in 'group statement'")

The above exception was the direct cause of the following exception:

Traceback (most recent call last):
  File "/home/aakash/PROJECTS/LOGIN_AUTHENTICATION/myenv/lib/python3.8/site-packages/django/core/handlers/exception.py", line 55, in inner
    response = get_response(request)
  File "/home/aakash/PROJECTS/LOGIN_AUTHENTICATION/myenv/lib/python3.8/site-packages/django/core/handlers/base.py", line 197, in _get_response
    response = wrapped_callback(request, *callback_args, **callback_kwargs)
  File "/home/aakash/PROJECTS/LOGIN_AUTHENTICATION/myenv/lib/python3.8/site-packages/django/views/decorators/csrf.py", line 56, in wrapper_view
    return view_func(*args, **kwargs)
  File "/home/aakash/PROJECTS/LOGIN_AUTHENTICATION/myenv/lib/python3.8/site-packages/django/views/generic/base.py", line 104, in view
    return self.dispatch(request, *args, **kwargs)
  File "/home/aakash/PROJECTS/LOGIN_AUTHENTICATION/myenv/lib/python3.8/site-packages/rest_framework/views.py", line 509, in dispatch
    response = self.handle_exception(exc)
  File "/home/aakash/PROJECTS/LOGIN_AUTHENTICATION/myenv/lib/python3.8/site-packages/rest_framework/views.py", line 469, in handle_exception
    self.raise_uncaught_exception(exc)
  File "/home/aakash/PROJECTS/LOGIN_AUTHENTICATION/myenv/lib/python3.8/site-packages/rest_framework/views.py", line 480, in raise_uncaught_exception
    raise exc
  File "/home/aakash/PROJECTS/LOGIN_AUTHENTICATION/myenv/lib/python3.8/site-packages/rest_framework/views.py", line 506, in dispatch
    response = handler(request, *args, **kwargs)
  File "/home/aakash/PROJECTS/LOGIN_AUTHENTICATION/Authentication_System/myapp/views.py", line 1319, in get
    cursor.execute('''  SELECT myapp_university.id , myapp_university.university_name , COUNT(myapp_department.id) AS dept_count
  File "/home/aakash/PROJECTS/LOGIN_AUTHENTICATION/myenv/lib/python3.8/site-packages/django/db/backends/utils.py", line 102, in execute
    return super().execute(sql, params)
  File "/home/aakash/PROJECTS/LOGIN_AUTHENTICATION/myenv/lib/python3.8/site-packages/django/db/backends/utils.py", line 67, in execute
    return self._execute_with_wrappers(
  File "/home/aakash/PROJECTS/LOGIN_AUTHENTICATION/myenv/lib/python3.8/site-packages/django/db/backends/utils.py", line 80, in _execute_with_wrappers
    return executor(sql, params, many, context)
  File "/home/aakash/PROJECTS/LOGIN_AUTHENTICATION/myenv/lib/python3.8/site-packages/django/db/backends/utils.py", line 89, in _execute
    return self.cursor.execute(sql, params)
  File "/home/aakash/PROJECTS/LOGIN_AUTHENTICATION/myenv/lib/python3.8/site-packages/django/db/utils.py", line 91, in __exit__
    raise dj_exc_value.with_traceback(traceback) from exc_value
  File "/home/aakash/PROJECTS/LOGIN_AUTHENTICATION/myenv/lib/python3.8/site-packages/django/db/backends/utils.py", line 87, in _execute
    return self.cursor.execute(sql)
  File "/home/aakash/PROJECTS/LOGIN_AUTHENTICATION/myenv/lib/python3.8/site-packages/django/db/backends/mysql/base.py", line 75, in execute
    return self.cursor.execute(query, args)
  File "/home/aakash/PROJECTS/LOGIN_AUTHENTICATION/myenv/lib/python3.8/site-packages/MySQLdb/cursors.py", line 179, in execute
    res = self._query(mogrified_query)
  File "/home/aakash/PROJECTS/LOGIN_AUTHENTICATION/myenv/lib/python3.8/site-packages/MySQLdb/cursors.py", line 330, in _query
    db.query(q)
  File "/home/aakash/PROJECTS/LOGIN_AUTHENTICATION/myenv/lib/python3.8/site-packages/MySQLdb/connections.py", line 255, in query
    _mysql.connection.query(self, query)
django.db.utils.OperationalError: (1054, "Unknown column 'myapp_universitys.id' in 'group statement'")
2023-08-24 07:45:17 ERROR "GET /get_orm_foreignKey_relation/ HTTP/1.1" 500 187768
2023-08-24 07:45:17 ERROR "GET /get_orm_foreignKey_relation/ HTTP/1.1" 500 187768
2023-08-25 05:20:48 ERROR Internal Server Error: /get_orm_foreignKey_relation/
Traceback (most recent call last):
  File "/home/aakash/PROJECTS/LOGIN_AUTHENTICATION/myenv/lib/python3.8/site-packages/django/db/backends/utils.py", line 87, in _execute
    return self.cursor.execute(sql)
  File "/home/aakash/PROJECTS/LOGIN_AUTHENTICATION/myenv/lib/python3.8/site-packages/django/db/backends/mysql/base.py", line 75, in execute
    return self.cursor.execute(query, args)
  File "/home/aakash/PROJECTS/LOGIN_AUTHENTICATION/myenv/lib/python3.8/site-packages/MySQLdb/cursors.py", line 179, in execute
    res = self._query(mogrified_query)
  File "/home/aakash/PROJECTS/LOGIN_AUTHENTICATION/myenv/lib/python3.8/site-packages/MySQLdb/cursors.py", line 330, in _query
    db.query(q)
  File "/home/aakash/PROJECTS/LOGIN_AUTHENTICATION/myenv/lib/python3.8/site-packages/MySQLdb/connections.py", line 255, in query
    _mysql.connection.query(self, query)
MySQLdb.OperationalError: (1054, "Unknown column 'myapp_universitys.id' in 'group statement'")

The above exception was the direct cause of the following exception:

Traceback (most recent call last):
  File "/home/aakash/PROJECTS/LOGIN_AUTHENTICATION/myenv/lib/python3.8/site-packages/django/core/handlers/exception.py", line 55, in inner
    response = get_response(request)
  File "/home/aakash/PROJECTS/LOGIN_AUTHENTICATION/myenv/lib/python3.8/site-packages/django/core/handlers/base.py", line 197, in _get_response
    response = wrapped_callback(request, *callback_args, **callback_kwargs)
  File "/home/aakash/PROJECTS/LOGIN_AUTHENTICATION/myenv/lib/python3.8/site-packages/django/views/decorators/csrf.py", line 56, in wrapper_view
    return view_func(*args, **kwargs)
  File "/home/aakash/PROJECTS/LOGIN_AUTHENTICATION/myenv/lib/python3.8/site-packages/django/views/generic/base.py", line 104, in view
    return self.dispatch(request, *args, **kwargs)
  File "/home/aakash/PROJECTS/LOGIN_AUTHENTICATION/myenv/lib/python3.8/site-packages/rest_framework/views.py", line 509, in dispatch
    response = self.handle_exception(exc)
  File "/home/aakash/PROJECTS/LOGIN_AUTHENTICATION/myenv/lib/python3.8/site-packages/rest_framework/views.py", line 469, in handle_exception
    self.raise_uncaught_exception(exc)
  File "/home/aakash/PROJECTS/LOGIN_AUTHENTICATION/myenv/lib/python3.8/site-packages/rest_framework/views.py", line 480, in raise_uncaught_exception
    raise exc
  File "/home/aakash/PROJECTS/LOGIN_AUTHENTICATION/myenv/lib/python3.8/site-packages/rest_framework/views.py", line 506, in dispatch
    response = handler(request, *args, **kwargs)
  File "/home/aakash/PROJECTS/LOGIN_AUTHENTICATION/Authentication_System/myapp/views.py", line 1319, in get
    cursor.execute('''  SELECT myapp_university.id , myapp_university.university_name , COUNT(myapp_department.id) AS dept_count
  File "/home/aakash/PROJECTS/LOGIN_AUTHENTICATION/myenv/lib/python3.8/site-packages/django/db/backends/utils.py", line 102, in execute
    return super().execute(sql, params)
  File "/home/aakash/PROJECTS/LOGIN_AUTHENTICATION/myenv/lib/python3.8/site-packages/django/db/backends/utils.py", line 67, in execute
    return self._execute_with_wrappers(
  File "/home/aakash/PROJECTS/LOGIN_AUTHENTICATION/myenv/lib/python3.8/site-packages/django/db/backends/utils.py", line 80, in _execute_with_wrappers
    return executor(sql, params, many, context)
  File "/home/aakash/PROJECTS/LOGIN_AUTHENTICATION/myenv/lib/python3.8/site-packages/django/db/backends/utils.py", line 89, in _execute
    return self.cursor.execute(sql, params)
  File "/home/aakash/PROJECTS/LOGIN_AUTHENTICATION/myenv/lib/python3.8/site-packages/django/db/utils.py", line 91, in __exit__
    raise dj_exc_value.with_traceback(traceback) from exc_value
  File "/home/aakash/PROJECTS/LOGIN_AUTHENTICATION/myenv/lib/python3.8/site-packages/django/db/backends/utils.py", line 87, in _execute
    return self.cursor.execute(sql)
  File "/home/aakash/PROJECTS/LOGIN_AUTHENTICATION/myenv/lib/python3.8/site-packages/django/db/backends/mysql/base.py", line 75, in execute
    return self.cursor.execute(query, args)
  File "/home/aakash/PROJECTS/LOGIN_AUTHENTICATION/myenv/lib/python3.8/site-packages/MySQLdb/cursors.py", line 179, in execute
    res = self._query(mogrified_query)
  File "/home/aakash/PROJECTS/LOGIN_AUTHENTICATION/myenv/lib/python3.8/site-packages/MySQLdb/cursors.py", line 330, in _query
    db.query(q)
  File "/home/aakash/PROJECTS/LOGIN_AUTHENTICATION/myenv/lib/python3.8/site-packages/MySQLdb/connections.py", line 255, in query
    _mysql.connection.query(self, query)
django.db.utils.OperationalError: (1054, "Unknown column 'myapp_universitys.id' in 'group statement'")
2023-08-25 05:20:48 ERROR "GET /get_orm_foreignKey_relation/ HTTP/1.1" 500 187768
2023-08-25 05:20:48 ERROR "GET /get_orm_foreignKey_relation/ HTTP/1.1" 500 187768
2023-08-25 09:24:37 ERROR Internal Server Error: /get_orm_foreignKey_relation/
Traceback (most recent call last):
  File "/home/aakash/PROJECTS/LOGIN_AUTHENTICATION/myenv/lib/python3.8/site-packages/django/core/handlers/exception.py", line 55, in inner
    response = get_response(request)
  File "/home/aakash/PROJECTS/LOGIN_AUTHENTICATION/myenv/lib/python3.8/site-packages/django/core/handlers/base.py", line 197, in _get_response
    response = wrapped_callback(request, *callback_args, **callback_kwargs)
  File "/home/aakash/PROJECTS/LOGIN_AUTHENTICATION/myenv/lib/python3.8/site-packages/django/views/decorators/csrf.py", line 56, in wrapper_view
    return view_func(*args, **kwargs)
  File "/home/aakash/PROJECTS/LOGIN_AUTHENTICATION/myenv/lib/python3.8/site-packages/django/views/generic/base.py", line 104, in view
    return self.dispatch(request, *args, **kwargs)
  File "/home/aakash/PROJECTS/LOGIN_AUTHENTICATION/myenv/lib/python3.8/site-packages/rest_framework/views.py", line 509, in dispatch
    response = self.handle_exception(exc)
  File "/home/aakash/PROJECTS/LOGIN_AUTHENTICATION/myenv/lib/python3.8/site-packages/rest_framework/views.py", line 469, in handle_exception
    self.raise_uncaught_exception(exc)
  File "/home/aakash/PROJECTS/LOGIN_AUTHENTICATION/myenv/lib/python3.8/site-packages/rest_framework/views.py", line 480, in raise_uncaught_exception
    raise exc
  File "/home/aakash/PROJECTS/LOGIN_AUTHENTICATION/myenv/lib/python3.8/site-packages/rest_framework/views.py", line 506, in dispatch
    response = handler(request, *args, **kwargs)
  File "/home/aakash/PROJECTS/LOGIN_AUTHENTICATION/Authentication_System/myapp/views.py", line 1391, in get
    st = Student.objects.all().values('id', 'student_name', 'student__department__department_name', 'student__department__university__university_name')
  File "/home/aakash/PROJECTS/LOGIN_AUTHENTICATION/myenv/lib/python3.8/site-packages/django/db/models/query.py", line 1313, in values
    clone = self._values(*fields, **expressions)
  File "/home/aakash/PROJECTS/LOGIN_AUTHENTICATION/myenv/lib/python3.8/site-packages/django/db/models/query.py", line 1308, in _values
    clone.query.set_values(fields)
  File "/home/aakash/PROJECTS/LOGIN_AUTHENTICATION/myenv/lib/python3.8/site-packages/django/db/models/sql/query.py", line 2449, in set_values
    self.add_fields(field_names, True)
  File "/home/aakash/PROJECTS/LOGIN_AUTHENTICATION/myenv/lib/python3.8/site-packages/django/db/models/sql/query.py", line 2150, in add_fields
    join_info = self.setup_joins(
  File "/home/aakash/PROJECTS/LOGIN_AUTHENTICATION/myenv/lib/python3.8/site-packages/django/db/models/sql/query.py", line 1812, in setup_joins
    path, final_field, targets, rest = self.names_to_path(
  File "/home/aakash/PROJECTS/LOGIN_AUTHENTICATION/myenv/lib/python3.8/site-packages/django/db/models/sql/query.py", line 1713, in names_to_path
    raise FieldError(
django.core.exceptions.FieldError: Cannot resolve keyword 'student' into field. Choices are: department, department_id, id, student_name
2023-08-25 09:24:37 ERROR "GET /get_orm_foreignKey_relation/ HTTP/1.1" 500 155532
2023-08-25 09:24:37 ERROR "GET /get_orm_foreignKey_relation/ HTTP/1.1" 500 155532
2023-08-25 09:26:28 ERROR Internal Server Error: /get_orm_foreignKey_relation/
Traceback (most recent call last):
  File "/home/aakash/PROJECTS/LOGIN_AUTHENTICATION/myenv/lib/python3.8/site-packages/django/core/handlers/exception.py", line 55, in inner
    response = get_response(request)
  File "/home/aakash/PROJECTS/LOGIN_AUTHENTICATION/myenv/lib/python3.8/site-packages/django/core/handlers/base.py", line 197, in _get_response
    response = wrapped_callback(request, *callback_args, **callback_kwargs)
  File "/home/aakash/PROJECTS/LOGIN_AUTHENTICATION/myenv/lib/python3.8/site-packages/django/views/decorators/csrf.py", line 56, in wrapper_view
    return view_func(*args, **kwargs)
  File "/home/aakash/PROJECTS/LOGIN_AUTHENTICATION/myenv/lib/python3.8/site-packages/django/views/generic/base.py", line 104, in view
    return self.dispatch(request, *args, **kwargs)
  File "/home/aakash/PROJECTS/LOGIN_AUTHENTICATION/myenv/lib/python3.8/site-packages/rest_framework/views.py", line 509, in dispatch
    response = self.handle_exception(exc)
  File "/home/aakash/PROJECTS/LOGIN_AUTHENTICATION/myenv/lib/python3.8/site-packages/rest_framework/views.py", line 469, in handle_exception
    self.raise_uncaught_exception(exc)
  File "/home/aakash/PROJECTS/LOGIN_AUTHENTICATION/myenv/lib/python3.8/site-packages/rest_framework/views.py", line 480, in raise_uncaught_exception
    raise exc
  File "/home/aakash/PROJECTS/LOGIN_AUTHENTICATION/myenv/lib/python3.8/site-packages/rest_framework/views.py", line 506, in dispatch
    response = handler(request, *args, **kwargs)
  File "/home/aakash/PROJECTS/LOGIN_AUTHENTICATION/Authentication_System/myapp/views.py", line 1391, in get
    st = Student.objects.all().values('id', 'student_name', 'student__department__department_name')
  File "/home/aakash/PROJECTS/LOGIN_AUTHENTICATION/myenv/lib/python3.8/site-packages/django/db/models/query.py", line 1313, in values
    clone = self._values(*fields, **expressions)
  File "/home/aakash/PROJECTS/LOGIN_AUTHENTICATION/myenv/lib/python3.8/site-packages/django/db/models/query.py", line 1308, in _values
    clone.query.set_values(fields)
  File "/home/aakash/PROJECTS/LOGIN_AUTHENTICATION/myenv/lib/python3.8/site-packages/django/db/models/sql/query.py", line 2449, in set_values
    self.add_fields(field_names, True)
  File "/home/aakash/PROJECTS/LOGIN_AUTHENTICATION/myenv/lib/python3.8/site-packages/django/db/models/sql/query.py", line 2150, in add_fields
    join_info = self.setup_joins(
  File "/home/aakash/PROJECTS/LOGIN_AUTHENTICATION/myenv/lib/python3.8/site-packages/django/db/models/sql/query.py", line 1812, in setup_joins
    path, final_field, targets, rest = self.names_to_path(
  File "/home/aakash/PROJECTS/LOGIN_AUTHENTICATION/myenv/lib/python3.8/site-packages/django/db/models/sql/query.py", line 1713, in names_to_path
    raise FieldError(
django.core.exceptions.FieldError: Cannot resolve keyword 'student' into field. Choices are: department, department_id, id, student_name
2023-08-25 09:26:28 ERROR "GET /get_orm_foreignKey_relation/ HTTP/1.1" 500 154988
2023-08-25 09:26:28 ERROR "GET /get_orm_foreignKey_relation/ HTTP/1.1" 500 154988
2023-08-25 09:55:19 ERROR Internal Server Error: /get_orm_foreignKey_relation/
Traceback (most recent call last):
  File "/home/aakash/PROJECTS/LOGIN_AUTHENTICATION/myenv/lib/python3.8/site-packages/django/core/handlers/exception.py", line 55, in inner
    response = get_response(request)
  File "/home/aakash/PROJECTS/LOGIN_AUTHENTICATION/myenv/lib/python3.8/site-packages/django/core/handlers/base.py", line 197, in _get_response
    response = wrapped_callback(request, *callback_args, **callback_kwargs)
  File "/home/aakash/PROJECTS/LOGIN_AUTHENTICATION/myenv/lib/python3.8/site-packages/django/views/decorators/csrf.py", line 56, in wrapper_view
    return view_func(*args, **kwargs)
  File "/home/aakash/PROJECTS/LOGIN_AUTHENTICATION/myenv/lib/python3.8/site-packages/django/views/generic/base.py", line 104, in view
    return self.dispatch(request, *args, **kwargs)
  File "/home/aakash/PROJECTS/LOGIN_AUTHENTICATION/myenv/lib/python3.8/site-packages/rest_framework/views.py", line 509, in dispatch
    response = self.handle_exception(exc)
  File "/home/aakash/PROJECTS/LOGIN_AUTHENTICATION/myenv/lib/python3.8/site-packages/rest_framework/views.py", line 469, in handle_exception
    self.raise_uncaught_exception(exc)
  File "/home/aakash/PROJECTS/LOGIN_AUTHENTICATION/myenv/lib/python3.8/site-packages/rest_framework/views.py", line 480, in raise_uncaught_exception
    raise exc
  File "/home/aakash/PROJECTS/LOGIN_AUTHENTICATION/myenv/lib/python3.8/site-packages/rest_framework/views.py", line 506, in dispatch
    response = handler(request, *args, **kwargs)
  File "/home/aakash/PROJECTS/LOGIN_AUTHENTICATION/Authentication_System/myapp/views.py", line 1406, in get
    ORM_21 = Department.objects.all(),values('students__id', 'students__student_name', 'department_name')
NameError: name 'values' is not defined
2023-08-25 09:55:19 ERROR "GET /get_orm_foreignKey_relation/ HTTP/1.1" 500 125322
2023-08-25 09:55:19 ERROR "GET /get_orm_foreignKey_relation/ HTTP/1.1" 500 125322
2023-09-11 11:31:35 ERROR Internal Server Error: /schedulemail/
Traceback (most recent call last):
  File "/home/aakash/PROJECTS/LOGIN_AUTHENTICATION/myenv/lib/python3.8/site-packages/django/core/handlers/exception.py", line 55, in inner
    response = get_response(request)
  File "/home/aakash/PROJECTS/LOGIN_AUTHENTICATION/myenv/lib/python3.8/site-packages/django/core/handlers/base.py", line 197, in _get_response
    response = wrapped_callback(request, *callback_args, **callback_kwargs)
  File "/home/aakash/PROJECTS/LOGIN_AUTHENTICATION/Authentication_System/myapp/views.py", line 1895, in schedule_mail
    task = PeriodicTask.objects.create(crontab=schedule, name='schedule_mail_task_'+'1',tasks='send_mail_app.tasks.send_mail_func', args=json.dumps((2,3,)) )
  File "/home/aakash/PROJECTS/LOGIN_AUTHENTICATION/myenv/lib/python3.8/site-packages/django/db/models/manager.py", line 87, in manager_method
    return getattr(self.get_queryset(), name)(*args, **kwargs)
  File "/home/aakash/PROJECTS/LOGIN_AUTHENTICATION/myenv/lib/python3.8/site-packages/django/db/models/query.py", line 656, in create
    obj = self.model(**kwargs)
  File "/home/aakash/PROJECTS/LOGIN_AUTHENTICATION/myenv/lib/python3.8/site-packages/django/db/models/base.py", line 567, in __init__
    raise TypeError(
TypeError: PeriodicTask() got unexpected keyword arguments: 'tasks'
2023-09-11 11:31:35 ERROR "GET /schedulemail/ HTTP/1.1" 500 87983
2023-09-11 11:31:35 ERROR "GET /schedulemail/ HTTP/1.1" 500 87983
2023-09-11 11:37:43 ERROR Internal Server Error: /schedulemail/
Traceback (most recent call last):
  File "/home/aakash/PROJECTS/LOGIN_AUTHENTICATION/myenv/lib/python3.8/site-packages/django/core/handlers/exception.py", line 55, in inner
    response = get_response(request)
  File "/home/aakash/PROJECTS/LOGIN_AUTHENTICATION/myenv/lib/python3.8/site-packages/django/core/handlers/base.py", line 197, in _get_response
    response = wrapped_callback(request, *callback_args, **callback_kwargs)
  File "/home/aakash/PROJECTS/LOGIN_AUTHENTICATION/Authentication_System/myapp/views.py", line 1895, in schedule_mail
    task = PeriodicTask.objects.create(crontab=schedule, name='schedule_mail_task_'+'1', task='send_mail_app.tasks.send_mail_func', args=json.dumps((2,3,)) )
  File "/home/aakash/PROJECTS/LOGIN_AUTHENTICATION/myenv/lib/python3.8/site-packages/django/db/models/manager.py", line 87, in manager_method
    return getattr(self.get_queryset(), name)(*args, **kwargs)
  File "/home/aakash/PROJECTS/LOGIN_AUTHENTICATION/myenv/lib/python3.8/site-packages/django/db/models/query.py", line 658, in create
    obj.save(force_insert=True, using=self.db)
  File "/home/aakash/PROJECTS/LOGIN_AUTHENTICATION/myenv/lib/python3.8/site-packages/django_celery_beat/models.py", line 594, in save
    self.validate_unique()
  File "/home/aakash/PROJECTS/LOGIN_AUTHENTICATION/myenv/lib/python3.8/site-packages/django_celery_beat/models.py", line 561, in validate_unique
    super().validate_unique(*args, **kwargs)
  File "/home/aakash/PROJECTS/LOGIN_AUTHENTICATION/myenv/lib/python3.8/site-packages/django/db/models/base.py", line 1236, in validate_unique
    raise ValidationError(errors)
django.core.exceptions.ValidationError: {'name': ['Periodic task with this Name already exists.']}
2023-09-11 11:37:43 ERROR "GET /schedulemail/ HTTP/1.1" 500 94971
2023-09-11 11:37:43 ERROR "GET /schedulemail/ HTTP/1.1" 500 94971
2023-09-11 11:40:24 ERROR Internal Server Error: /schedulemail/
Traceback (most recent call last):
  File "/home/aakash/PROJECTS/LOGIN_AUTHENTICATION/myenv/lib/python3.8/site-packages/django/core/handlers/exception.py", line 55, in inner
    response = get_response(request)
  File "/home/aakash/PROJECTS/LOGIN_AUTHENTICATION/myenv/lib/python3.8/site-packages/django/core/handlers/base.py", line 197, in _get_response
    response = wrapped_callback(request, *callback_args, **callback_kwargs)
  File "/home/aakash/PROJECTS/LOGIN_AUTHENTICATION/Authentication_System/myapp/views.py", line 1895, in schedule_mail
    task = PeriodicTask.objects.create(crontab=schedule, name='schedule_mail_task_'+'2', task='send_mail_app.tasks.send_mail_func') #, args=json.dumps([[2,3]]) )
  File "/home/aakash/PROJECTS/LOGIN_AUTHENTICATION/myenv/lib/python3.8/site-packages/django/db/models/manager.py", line 87, in manager_method
    return getattr(self.get_queryset(), name)(*args, **kwargs)
  File "/home/aakash/PROJECTS/LOGIN_AUTHENTICATION/myenv/lib/python3.8/site-packages/django/db/models/query.py", line 658, in create
    obj.save(force_insert=True, using=self.db)
  File "/home/aakash/PROJECTS/LOGIN_AUTHENTICATION/myenv/lib/python3.8/site-packages/django_celery_beat/models.py", line 594, in save
    self.validate_unique()
  File "/home/aakash/PROJECTS/LOGIN_AUTHENTICATION/myenv/lib/python3.8/site-packages/django_celery_beat/models.py", line 561, in validate_unique
    super().validate_unique(*args, **kwargs)
  File "/home/aakash/PROJECTS/LOGIN_AUTHENTICATION/myenv/lib/python3.8/site-packages/django/db/models/base.py", line 1236, in validate_unique
    raise ValidationError(errors)
django.core.exceptions.ValidationError: {'name': ['Periodic task with this Name already exists.']}
2023-09-11 11:40:24 ERROR "GET /schedulemail/ HTTP/1.1" 500 94985
2023-09-11 11:40:24 ERROR "GET /schedulemail/ HTTP/1.1" 500 94985
2023-09-12 05:49:52 ERROR Internal Server Error: /schedulemail/
Traceback (most recent call last):
  File "/home/aakash/PROJECTS/LOGIN_AUTHENTICATION/myenv/lib/python3.8/site-packages/django/core/handlers/exception.py", line 55, in inner
    response = get_response(request)
  File "/home/aakash/PROJECTS/LOGIN_AUTHENTICATION/myenv/lib/python3.8/site-packages/django/core/handlers/base.py", line 197, in _get_response
    response = wrapped_callback(request, *callback_args, **callback_kwargs)
  File "/home/aakash/PROJECTS/LOGIN_AUTHENTICATION/Authentication_System/myapp/views.py", line 1895, in schedule_mail
    task = PeriodicTask.objects.create(crontab=schedule, name='schedule_mail_task_'+'3', task='send_mail_app.tasks.send_mail_func') #, args=json.dumps([[2,3]]) )
  File "/home/aakash/PROJECTS/LOGIN_AUTHENTICATION/myenv/lib/python3.8/site-packages/django/db/models/manager.py", line 87, in manager_method
    return getattr(self.get_queryset(), name)(*args, **kwargs)
  File "/home/aakash/PROJECTS/LOGIN_AUTHENTICATION/myenv/lib/python3.8/site-packages/django/db/models/query.py", line 658, in create
    obj.save(force_insert=True, using=self.db)
  File "/home/aakash/PROJECTS/LOGIN_AUTHENTICATION/myenv/lib/python3.8/site-packages/django_celery_beat/models.py", line 594, in save
    self.validate_unique()
  File "/home/aakash/PROJECTS/LOGIN_AUTHENTICATION/myenv/lib/python3.8/site-packages/django_celery_beat/models.py", line 561, in validate_unique
    super().validate_unique(*args, **kwargs)
  File "/home/aakash/PROJECTS/LOGIN_AUTHENTICATION/myenv/lib/python3.8/site-packages/django/db/models/base.py", line 1236, in validate_unique
    raise ValidationError(errors)
django.core.exceptions.ValidationError: {'name': ['Periodic task with this Name already exists.']}
2023-09-12 05:49:52 ERROR "GET /schedulemail/ HTTP/1.1" 500 94935
2023-09-12 05:49:52 ERROR "GET /schedulemail/ HTTP/1.1" 500 94935
2023-09-12 09:41:39 ERROR Internal Server Error: /schedulemail/
Traceback (most recent call last):
  File "/home/aakash/PROJECTS/LOGIN_AUTHENTICATION/myenv/lib/python3.8/site-packages/django/core/handlers/exception.py", line 55, in inner
    response = get_response(request)
  File "/home/aakash/PROJECTS/LOGIN_AUTHENTICATION/myenv/lib/python3.8/site-packages/django/core/handlers/base.py", line 197, in _get_response
    response = wrapped_callback(request, *callback_args, **callback_kwargs)
  File "/home/aakash/PROJECTS/LOGIN_AUTHENTICATION/Authentication_System/myapp/views.py", line 1895, in schedule_mail
    task = PeriodicTask.objects.create(crontab=schedule, name='schedule_mail_task_'+'3', task='send_mail_app.tasks.send_mail_func') #, args=json.dumps([[2,3]]) )
  File "/home/aakash/PROJECTS/LOGIN_AUTHENTICATION/myenv/lib/python3.8/site-packages/django/db/models/manager.py", line 87, in manager_method
    return getattr(self.get_queryset(), name)(*args, **kwargs)
  File "/home/aakash/PROJECTS/LOGIN_AUTHENTICATION/myenv/lib/python3.8/site-packages/django/db/models/query.py", line 658, in create
    obj.save(force_insert=True, using=self.db)
  File "/home/aakash/PROJECTS/LOGIN_AUTHENTICATION/myenv/lib/python3.8/site-packages/django_celery_beat/models.py", line 594, in save
    self.validate_unique()
  File "/home/aakash/PROJECTS/LOGIN_AUTHENTICATION/myenv/lib/python3.8/site-packages/django_celery_beat/models.py", line 561, in validate_unique
    super().validate_unique(*args, **kwargs)
  File "/home/aakash/PROJECTS/LOGIN_AUTHENTICATION/myenv/lib/python3.8/site-packages/django/db/models/base.py", line 1236, in validate_unique
    raise ValidationError(errors)
django.core.exceptions.ValidationError: {'name': ['Periodic task with this Name already exists.']}
2023-09-12 09:41:39 ERROR "GET /schedulemail/ HTTP/1.1" 500 95073
2023-09-12 09:41:39 ERROR "GET /schedulemail/ HTTP/1.1" 500 95073
2023-09-12 09:41:59 ERROR Internal Server Error: /schedulemail/
Traceback (most recent call last):
  File "/home/aakash/PROJECTS/LOGIN_AUTHENTICATION/myenv/lib/python3.8/site-packages/django/core/handlers/exception.py", line 55, in inner
    response = get_response(request)
  File "/home/aakash/PROJECTS/LOGIN_AUTHENTICATION/myenv/lib/python3.8/site-packages/django/core/handlers/base.py", line 197, in _get_response
    response = wrapped_callback(request, *callback_args, **callback_kwargs)
  File "/home/aakash/PROJECTS/LOGIN_AUTHENTICATION/Authentication_System/myapp/views.py", line 1895, in schedule_mail
    task = PeriodicTask.objects.create(crontab=schedule, name='schedule_mail_task_'+'3', task='send_mail_app.tasks.send_mail_func') #, args=json.dumps([[2,3]]) )
  File "/home/aakash/PROJECTS/LOGIN_AUTHENTICATION/myenv/lib/python3.8/site-packages/django/db/models/manager.py", line 87, in manager_method
    return getattr(self.get_queryset(), name)(*args, **kwargs)
  File "/home/aakash/PROJECTS/LOGIN_AUTHENTICATION/myenv/lib/python3.8/site-packages/django/db/models/query.py", line 658, in create
    obj.save(force_insert=True, using=self.db)
  File "/home/aakash/PROJECTS/LOGIN_AUTHENTICATION/myenv/lib/python3.8/site-packages/django_celery_beat/models.py", line 594, in save
    self.validate_unique()
  File "/home/aakash/PROJECTS/LOGIN_AUTHENTICATION/myenv/lib/python3.8/site-packages/django_celery_beat/models.py", line 561, in validate_unique
    super().validate_unique(*args, **kwargs)
  File "/home/aakash/PROJECTS/LOGIN_AUTHENTICATION/myenv/lib/python3.8/site-packages/django/db/models/base.py", line 1236, in validate_unique
    raise ValidationError(errors)
django.core.exceptions.ValidationError: {'name': ['Periodic task with this Name already exists.']}
2023-09-12 09:41:59 ERROR "GET /schedulemail/ HTTP/1.1" 500 95073
2023-09-12 09:41:59 ERROR "GET /schedulemail/ HTTP/1.1" 500 95073
2023-09-12 11:07:52 ERROR Internal Server Error: /schedulemail/
Traceback (most recent call last):
  File "/home/aakash/PROJECTS/LOGIN_AUTHENTICATION/myenv/lib/python3.8/site-packages/django/core/handlers/exception.py", line 55, in inner
    response = get_response(request)
  File "/home/aakash/PROJECTS/LOGIN_AUTHENTICATION/myenv/lib/python3.8/site-packages/django/core/handlers/base.py", line 197, in _get_response
    response = wrapped_callback(request, *callback_args, **callback_kwargs)
  File "/home/aakash/PROJECTS/LOGIN_AUTHENTICATION/Authentication_System/myapp/views.py", line 1895, in schedule_mail
    task = PeriodicTask.objects.create(crontab=schedule, name='schedule_mail_task_'+'3', task='send_mail_app.tasks.send_mail_func') #, args=json.dumps([[2,3]]) )
  File "/home/aakash/PROJECTS/LOGIN_AUTHENTICATION/myenv/lib/python3.8/site-packages/django/db/models/manager.py", line 87, in manager_method
    return getattr(self.get_queryset(), name)(*args, **kwargs)
  File "/home/aakash/PROJECTS/LOGIN_AUTHENTICATION/myenv/lib/python3.8/site-packages/django/db/models/query.py", line 658, in create
    obj.save(force_insert=True, using=self.db)
  File "/home/aakash/PROJECTS/LOGIN_AUTHENTICATION/myenv/lib/python3.8/site-packages/django_celery_beat/models.py", line 594, in save
    self.validate_unique()
  File "/home/aakash/PROJECTS/LOGIN_AUTHENTICATION/myenv/lib/python3.8/site-packages/django_celery_beat/models.py", line 561, in validate_unique
    super().validate_unique(*args, **kwargs)
  File "/home/aakash/PROJECTS/LOGIN_AUTHENTICATION/myenv/lib/python3.8/site-packages/django/db/models/base.py", line 1236, in validate_unique
    raise ValidationError(errors)
django.core.exceptions.ValidationError: {'name': ['Periodic task with this Name already exists.']}
2023-09-12 11:07:52 ERROR "GET /schedulemail/ HTTP/1.1" 500 95073
2023-09-12 11:07:52 ERROR "GET /schedulemail/ HTTP/1.1" 500 95073
2023-09-12 11:07:53 ERROR Internal Server Error: /schedulemail/
Traceback (most recent call last):
  File "/home/aakash/PROJECTS/LOGIN_AUTHENTICATION/myenv/lib/python3.8/site-packages/django/core/handlers/exception.py", line 55, in inner
    response = get_response(request)
  File "/home/aakash/PROJECTS/LOGIN_AUTHENTICATION/myenv/lib/python3.8/site-packages/django/core/handlers/base.py", line 197, in _get_response
    response = wrapped_callback(request, *callback_args, **callback_kwargs)
  File "/home/aakash/PROJECTS/LOGIN_AUTHENTICATION/Authentication_System/myapp/views.py", line 1895, in schedule_mail
    task = PeriodicTask.objects.create(crontab=schedule, name='schedule_mail_task_'+'3', task='send_mail_app.tasks.send_mail_func') #, args=json.dumps([[2,3]]) )
  File "/home/aakash/PROJECTS/LOGIN_AUTHENTICATION/myenv/lib/python3.8/site-packages/django/db/models/manager.py", line 87, in manager_method
    return getattr(self.get_queryset(), name)(*args, **kwargs)
  File "/home/aakash/PROJECTS/LOGIN_AUTHENTICATION/myenv/lib/python3.8/site-packages/django/db/models/query.py", line 658, in create
    obj.save(force_insert=True, using=self.db)
  File "/home/aakash/PROJECTS/LOGIN_AUTHENTICATION/myenv/lib/python3.8/site-packages/django_celery_beat/models.py", line 594, in save
    self.validate_unique()
  File "/home/aakash/PROJECTS/LOGIN_AUTHENTICATION/myenv/lib/python3.8/site-packages/django_celery_beat/models.py", line 561, in validate_unique
    super().validate_unique(*args, **kwargs)
  File "/home/aakash/PROJECTS/LOGIN_AUTHENTICATION/myenv/lib/python3.8/site-packages/django/db/models/base.py", line 1236, in validate_unique
    raise ValidationError(errors)
django.core.exceptions.ValidationError: {'name': ['Periodic task with this Name already exists.']}
2023-09-12 11:07:53 ERROR "GET /schedulemail/ HTTP/1.1" 500 95073
2023-09-12 11:07:53 ERROR "GET /schedulemail/ HTTP/1.1" 500 95073
2023-09-12 11:07:54 ERROR Internal Server Error: /schedulemail/
Traceback (most recent call last):
  File "/home/aakash/PROJECTS/LOGIN_AUTHENTICATION/myenv/lib/python3.8/site-packages/django/core/handlers/exception.py", line 55, in inner
    response = get_response(request)
  File "/home/aakash/PROJECTS/LOGIN_AUTHENTICATION/myenv/lib/python3.8/site-packages/django/core/handlers/base.py", line 197, in _get_response
    response = wrapped_callback(request, *callback_args, **callback_kwargs)
  File "/home/aakash/PROJECTS/LOGIN_AUTHENTICATION/Authentication_System/myapp/views.py", line 1895, in schedule_mail
    task = PeriodicTask.objects.create(crontab=schedule, name='schedule_mail_task_'+'3', task='send_mail_app.tasks.send_mail_func') #, args=json.dumps([[2,3]]) )
  File "/home/aakash/PROJECTS/LOGIN_AUTHENTICATION/myenv/lib/python3.8/site-packages/django/db/models/manager.py", line 87, in manager_method
    return getattr(self.get_queryset(), name)(*args, **kwargs)
  File "/home/aakash/PROJECTS/LOGIN_AUTHENTICATION/myenv/lib/python3.8/site-packages/django/db/models/query.py", line 658, in create
    obj.save(force_insert=True, using=self.db)
  File "/home/aakash/PROJECTS/LOGIN_AUTHENTICATION/myenv/lib/python3.8/site-packages/django_celery_beat/models.py", line 594, in save
    self.validate_unique()
  File "/home/aakash/PROJECTS/LOGIN_AUTHENTICATION/myenv/lib/python3.8/site-packages/django_celery_beat/models.py", line 561, in validate_unique
    super().validate_unique(*args, **kwargs)
  File "/home/aakash/PROJECTS/LOGIN_AUTHENTICATION/myenv/lib/python3.8/site-packages/django/db/models/base.py", line 1236, in validate_unique
    raise ValidationError(errors)
django.core.exceptions.ValidationError: {'name': ['Periodic task with this Name already exists.']}
2023-09-12 11:07:54 ERROR "GET /schedulemail/ HTTP/1.1" 500 95073
2023-09-12 11:07:54 ERROR "GET /schedulemail/ HTTP/1.1" 500 95073
2023-09-12 11:07:55 ERROR Internal Server Error: /schedulemail/
Traceback (most recent call last):
  File "/home/aakash/PROJECTS/LOGIN_AUTHENTICATION/myenv/lib/python3.8/site-packages/django/core/handlers/exception.py", line 55, in inner
    response = get_response(request)
  File "/home/aakash/PROJECTS/LOGIN_AUTHENTICATION/myenv/lib/python3.8/site-packages/django/core/handlers/base.py", line 197, in _get_response
    response = wrapped_callback(request, *callback_args, **callback_kwargs)
  File "/home/aakash/PROJECTS/LOGIN_AUTHENTICATION/Authentication_System/myapp/views.py", line 1895, in schedule_mail
    task = PeriodicTask.objects.create(crontab=schedule, name='schedule_mail_task_'+'3', task='send_mail_app.tasks.send_mail_func') #, args=json.dumps([[2,3]]) )
  File "/home/aakash/PROJECTS/LOGIN_AUTHENTICATION/myenv/lib/python3.8/site-packages/django/db/models/manager.py", line 87, in manager_method
    return getattr(self.get_queryset(), name)(*args, **kwargs)
  File "/home/aakash/PROJECTS/LOGIN_AUTHENTICATION/myenv/lib/python3.8/site-packages/django/db/models/query.py", line 658, in create
    obj.save(force_insert=True, using=self.db)
  File "/home/aakash/PROJECTS/LOGIN_AUTHENTICATION/myenv/lib/python3.8/site-packages/django_celery_beat/models.py", line 594, in save
    self.validate_unique()
  File "/home/aakash/PROJECTS/LOGIN_AUTHENTICATION/myenv/lib/python3.8/site-packages/django_celery_beat/models.py", line 561, in validate_unique
    super().validate_unique(*args, **kwargs)
  File "/home/aakash/PROJECTS/LOGIN_AUTHENTICATION/myenv/lib/python3.8/site-packages/django/db/models/base.py", line 1236, in validate_unique
    raise ValidationError(errors)
django.core.exceptions.ValidationError: {'name': ['Periodic task with this Name already exists.']}
2023-09-12 11:07:55 ERROR "GET /schedulemail/ HTTP/1.1" 500 95073
2023-09-12 11:07:55 ERROR "GET /schedulemail/ HTTP/1.1" 500 95073
2023-09-12 11:07:55 ERROR Internal Server Error: /schedulemail/
Traceback (most recent call last):
  File "/home/aakash/PROJECTS/LOGIN_AUTHENTICATION/myenv/lib/python3.8/site-packages/django/core/handlers/exception.py", line 55, in inner
    response = get_response(request)
  File "/home/aakash/PROJECTS/LOGIN_AUTHENTICATION/myenv/lib/python3.8/site-packages/django/core/handlers/base.py", line 197, in _get_response
    response = wrapped_callback(request, *callback_args, **callback_kwargs)
  File "/home/aakash/PROJECTS/LOGIN_AUTHENTICATION/Authentication_System/myapp/views.py", line 1895, in schedule_mail
    task = PeriodicTask.objects.create(crontab=schedule, name='schedule_mail_task_'+'3', task='send_mail_app.tasks.send_mail_func') #, args=json.dumps([[2,3]]) )
  File "/home/aakash/PROJECTS/LOGIN_AUTHENTICATION/myenv/lib/python3.8/site-packages/django/db/models/manager.py", line 87, in manager_method
    return getattr(self.get_queryset(), name)(*args, **kwargs)
  File "/home/aakash/PROJECTS/LOGIN_AUTHENTICATION/myenv/lib/python3.8/site-packages/django/db/models/query.py", line 658, in create
    obj.save(force_insert=True, using=self.db)
  File "/home/aakash/PROJECTS/LOGIN_AUTHENTICATION/myenv/lib/python3.8/site-packages/django_celery_beat/models.py", line 594, in save
    self.validate_unique()
  File "/home/aakash/PROJECTS/LOGIN_AUTHENTICATION/myenv/lib/python3.8/site-packages/django_celery_beat/models.py", line 561, in validate_unique
    super().validate_unique(*args, **kwargs)
  File "/home/aakash/PROJECTS/LOGIN_AUTHENTICATION/myenv/lib/python3.8/site-packages/django/db/models/base.py", line 1236, in validate_unique
    raise ValidationError(errors)
django.core.exceptions.ValidationError: {'name': ['Periodic task with this Name already exists.']}
2023-09-12 11:07:55 ERROR "GET /schedulemail/ HTTP/1.1" 500 95073
2023-09-12 11:07:55 ERROR "GET /schedulemail/ HTTP/1.1" 500 95073
2023-09-12 11:48:22 ERROR Internal Server Error: /schedulemail/
Traceback (most recent call last):
  File "/home/aakash/PROJECTS/LOGIN_AUTHENTICATION/myenv/lib/python3.8/site-packages/django/core/handlers/exception.py", line 55, in inner
    response = get_response(request)
  File "/home/aakash/PROJECTS/LOGIN_AUTHENTICATION/myenv/lib/python3.8/site-packages/django/core/handlers/base.py", line 197, in _get_response
    response = wrapped_callback(request, *callback_args, **callback_kwargs)
  File "/home/aakash/PROJECTS/LOGIN_AUTHENTICATION/Authentication_System/myapp/views.py", line 1895, in schedule_mail
    task = PeriodicTask.objects.create(crontab=schedule, name='schedule_mail_task_'+'3', task='send_mail_app.tasks.send_mail_func') #, args=json.dumps([[2,3]]) )
  File "/home/aakash/PROJECTS/LOGIN_AUTHENTICATION/myenv/lib/python3.8/site-packages/django/db/models/manager.py", line 87, in manager_method
    return getattr(self.get_queryset(), name)(*args, **kwargs)
  File "/home/aakash/PROJECTS/LOGIN_AUTHENTICATION/myenv/lib/python3.8/site-packages/django/db/models/query.py", line 658, in create
    obj.save(force_insert=True, using=self.db)
  File "/home/aakash/PROJECTS/LOGIN_AUTHENTICATION/myenv/lib/python3.8/site-packages/django_celery_beat/models.py", line 594, in save
    self.validate_unique()
  File "/home/aakash/PROJECTS/LOGIN_AUTHENTICATION/myenv/lib/python3.8/site-packages/django_celery_beat/models.py", line 561, in validate_unique
    super().validate_unique(*args, **kwargs)
  File "/home/aakash/PROJECTS/LOGIN_AUTHENTICATION/myenv/lib/python3.8/site-packages/django/db/models/base.py", line 1236, in validate_unique
    raise ValidationError(errors)
django.core.exceptions.ValidationError: {'name': ['Periodic task with this Name already exists.']}
2023-09-12 11:48:22 ERROR "GET /schedulemail/ HTTP/1.1" 500 95073
2023-09-12 11:48:22 ERROR "GET /schedulemail/ HTTP/1.1" 500 95073
2023-09-13 06:35:33 ERROR Internal Server Error: /schedulemail/
Traceback (most recent call last):
  File "/home/aakash/PROJECTS/LOGIN_AUTHENTICATION/myenv/lib/python3.8/site-packages/django/core/handlers/exception.py", line 55, in inner
    response = get_response(request)
  File "/home/aakash/PROJECTS/LOGIN_AUTHENTICATION/myenv/lib/python3.8/site-packages/django/core/handlers/base.py", line 197, in _get_response
    response = wrapped_callback(request, *callback_args, **callback_kwargs)
  File "/home/aakash/PROJECTS/LOGIN_AUTHENTICATION/Authentication_System/myapp/views.py", line 1895, in schedule_mail
    task = PeriodicTask.objects.create(crontab=schedule, name='schedule_mail_task_'+'3', task='send_mail_app.tasks.send_mail_func') #, args=json.dumps([[2,3]]) )
  File "/home/aakash/PROJECTS/LOGIN_AUTHENTICATION/myenv/lib/python3.8/site-packages/django/db/models/manager.py", line 87, in manager_method
    return getattr(self.get_queryset(), name)(*args, **kwargs)
  File "/home/aakash/PROJECTS/LOGIN_AUTHENTICATION/myenv/lib/python3.8/site-packages/django/db/models/query.py", line 658, in create
    obj.save(force_insert=True, using=self.db)
  File "/home/aakash/PROJECTS/LOGIN_AUTHENTICATION/myenv/lib/python3.8/site-packages/django_celery_beat/models.py", line 594, in save
    self.validate_unique()
  File "/home/aakash/PROJECTS/LOGIN_AUTHENTICATION/myenv/lib/python3.8/site-packages/django_celery_beat/models.py", line 561, in validate_unique
    super().validate_unique(*args, **kwargs)
  File "/home/aakash/PROJECTS/LOGIN_AUTHENTICATION/myenv/lib/python3.8/site-packages/django/db/models/base.py", line 1236, in validate_unique
    raise ValidationError(errors)
django.core.exceptions.ValidationError: {'name': ['Periodic task with this Name already exists.']}
2023-09-13 06:35:33 ERROR "GET /schedulemail/ HTTP/1.1" 500 94941
2023-09-13 06:35:33 ERROR "GET /schedulemail/ HTTP/1.1" 500 94941
2023-09-13 07:33:31 ERROR Internal Server Error: /schedulemail/
Traceback (most recent call last):
  File "/home/aakash/PROJECTS/LOGIN_AUTHENTICATION/myenv/lib/python3.8/site-packages/django/core/handlers/exception.py", line 55, in inner
    response = get_response(request)
  File "/home/aakash/PROJECTS/LOGIN_AUTHENTICATION/myenv/lib/python3.8/site-packages/django/core/handlers/base.py", line 197, in _get_response
    response = wrapped_callback(request, *callback_args, **callback_kwargs)
  File "/home/aakash/PROJECTS/LOGIN_AUTHENTICATION/Authentication_System/myapp/views.py", line 1895, in schedule_mail
    task = PeriodicTask.objects.create(crontab=schedule, name='schedule_mail_task_'+'4', task='send_mail_app.tasks.send_mail_func') #, args=json.dumps([[2,3]]) )
  File "/home/aakash/PROJECTS/LOGIN_AUTHENTICATION/myenv/lib/python3.8/site-packages/django/db/models/manager.py", line 87, in manager_method
    return getattr(self.get_queryset(), name)(*args, **kwargs)
  File "/home/aakash/PROJECTS/LOGIN_AUTHENTICATION/myenv/lib/python3.8/site-packages/django/db/models/query.py", line 658, in create
    obj.save(force_insert=True, using=self.db)
  File "/home/aakash/PROJECTS/LOGIN_AUTHENTICATION/myenv/lib/python3.8/site-packages/django_celery_beat/models.py", line 594, in save
    self.validate_unique()
  File "/home/aakash/PROJECTS/LOGIN_AUTHENTICATION/myenv/lib/python3.8/site-packages/django_celery_beat/models.py", line 561, in validate_unique
    super().validate_unique(*args, **kwargs)
  File "/home/aakash/PROJECTS/LOGIN_AUTHENTICATION/myenv/lib/python3.8/site-packages/django/db/models/base.py", line 1236, in validate_unique
    raise ValidationError(errors)
django.core.exceptions.ValidationError: {'name': ['Periodic task with this Name already exists.']}
2023-09-13 07:33:31 ERROR "GET /schedulemail/ HTTP/1.1" 500 95162
2023-09-13 07:33:31 ERROR "GET /schedulemail/ HTTP/1.1" 500 95162
2023-09-13 07:53:06 ERROR Internal Server Error: /schedulemail/
Traceback (most recent call last):
  File "/home/aakash/PROJECTS/LOGIN_AUTHENTICATION/myenv/lib/python3.8/site-packages/django/core/handlers/exception.py", line 55, in inner
    response = get_response(request)
  File "/home/aakash/PROJECTS/LOGIN_AUTHENTICATION/myenv/lib/python3.8/site-packages/django/core/handlers/base.py", line 197, in _get_response
    response = wrapped_callback(request, *callback_args, **callback_kwargs)
  File "/home/aakash/PROJECTS/LOGIN_AUTHENTICATION/Authentication_System/myapp/views.py", line 1895, in schedule_mail
    task = PeriodicTask.objects.create(crontab=schedule, name='schedule_mail_task_'+'4', task='send_mail_app.tasks.send_mail_func') #, args=json.dumps([[2,3]]) )
  File "/home/aakash/PROJECTS/LOGIN_AUTHENTICATION/myenv/lib/python3.8/site-packages/django/db/models/manager.py", line 87, in manager_method
    return getattr(self.get_queryset(), name)(*args, **kwargs)
  File "/home/aakash/PROJECTS/LOGIN_AUTHENTICATION/myenv/lib/python3.8/site-packages/django/db/models/query.py", line 658, in create
    obj.save(force_insert=True, using=self.db)
  File "/home/aakash/PROJECTS/LOGIN_AUTHENTICATION/myenv/lib/python3.8/site-packages/django_celery_beat/models.py", line 594, in save
    self.validate_unique()
  File "/home/aakash/PROJECTS/LOGIN_AUTHENTICATION/myenv/lib/python3.8/site-packages/django_celery_beat/models.py", line 561, in validate_unique
    super().validate_unique(*args, **kwargs)
  File "/home/aakash/PROJECTS/LOGIN_AUTHENTICATION/myenv/lib/python3.8/site-packages/django/db/models/base.py", line 1236, in validate_unique
    raise ValidationError(errors)
django.core.exceptions.ValidationError: {'name': ['Periodic task with this Name already exists.']}
2023-09-13 07:53:06 ERROR "GET /schedulemail/ HTTP/1.1" 500 95162
2023-09-13 07:53:06 ERROR "GET /schedulemail/ HTTP/1.1" 500 95162
2023-09-13 07:53:07 ERROR Internal Server Error: /schedulemail/
Traceback (most recent call last):
  File "/home/aakash/PROJECTS/LOGIN_AUTHENTICATION/myenv/lib/python3.8/site-packages/django/core/handlers/exception.py", line 55, in inner
    response = get_response(request)
  File "/home/aakash/PROJECTS/LOGIN_AUTHENTICATION/myenv/lib/python3.8/site-packages/django/core/handlers/base.py", line 197, in _get_response
    response = wrapped_callback(request, *callback_args, **callback_kwargs)
  File "/home/aakash/PROJECTS/LOGIN_AUTHENTICATION/Authentication_System/myapp/views.py", line 1895, in schedule_mail
    task = PeriodicTask.objects.create(crontab=schedule, name='schedule_mail_task_'+'4', task='send_mail_app.tasks.send_mail_func') #, args=json.dumps([[2,3]]) )
  File "/home/aakash/PROJECTS/LOGIN_AUTHENTICATION/myenv/lib/python3.8/site-packages/django/db/models/manager.py", line 87, in manager_method
    return getattr(self.get_queryset(), name)(*args, **kwargs)
  File "/home/aakash/PROJECTS/LOGIN_AUTHENTICATION/myenv/lib/python3.8/site-packages/django/db/models/query.py", line 658, in create
    obj.save(force_insert=True, using=self.db)
  File "/home/aakash/PROJECTS/LOGIN_AUTHENTICATION/myenv/lib/python3.8/site-packages/django_celery_beat/models.py", line 594, in save
    self.validate_unique()
  File "/home/aakash/PROJECTS/LOGIN_AUTHENTICATION/myenv/lib/python3.8/site-packages/django_celery_beat/models.py", line 561, in validate_unique
    super().validate_unique(*args, **kwargs)
  File "/home/aakash/PROJECTS/LOGIN_AUTHENTICATION/myenv/lib/python3.8/site-packages/django/db/models/base.py", line 1236, in validate_unique
    raise ValidationError(errors)
django.core.exceptions.ValidationError: {'name': ['Periodic task with this Name already exists.']}
2023-09-13 07:53:07 ERROR "GET /schedulemail/ HTTP/1.1" 500 95162
2023-09-13 07:53:07 ERROR "GET /schedulemail/ HTTP/1.1" 500 95162
2023-09-13 07:53:18 ERROR Internal Server Error: /schedulemail/
Traceback (most recent call last):
  File "/home/aakash/PROJECTS/LOGIN_AUTHENTICATION/myenv/lib/python3.8/site-packages/django/core/handlers/exception.py", line 55, in inner
    response = get_response(request)
  File "/home/aakash/PROJECTS/LOGIN_AUTHENTICATION/myenv/lib/python3.8/site-packages/django/core/handlers/base.py", line 197, in _get_response
    response = wrapped_callback(request, *callback_args, **callback_kwargs)
  File "/home/aakash/PROJECTS/LOGIN_AUTHENTICATION/Authentication_System/myapp/views.py", line 1895, in schedule_mail
    task = PeriodicTask.objects.create(crontab=schedule, name='schedule_mail_task_'+'4', task='send_mail_app.tasks.send_mail_func') #, args=json.dumps([[2,3]]) )
  File "/home/aakash/PROJECTS/LOGIN_AUTHENTICATION/myenv/lib/python3.8/site-packages/django/db/models/manager.py", line 87, in manager_method
    return getattr(self.get_queryset(), name)(*args, **kwargs)
  File "/home/aakash/PROJECTS/LOGIN_AUTHENTICATION/myenv/lib/python3.8/site-packages/django/db/models/query.py", line 658, in create
    obj.save(force_insert=True, using=self.db)
  File "/home/aakash/PROJECTS/LOGIN_AUTHENTICATION/myenv/lib/python3.8/site-packages/django_celery_beat/models.py", line 594, in save
    self.validate_unique()
  File "/home/aakash/PROJECTS/LOGIN_AUTHENTICATION/myenv/lib/python3.8/site-packages/django_celery_beat/models.py", line 561, in validate_unique
    super().validate_unique(*args, **kwargs)
  File "/home/aakash/PROJECTS/LOGIN_AUTHENTICATION/myenv/lib/python3.8/site-packages/django/db/models/base.py", line 1236, in validate_unique
    raise ValidationError(errors)
django.core.exceptions.ValidationError: {'name': ['Periodic task with this Name already exists.']}
2023-09-13 07:53:18 ERROR "GET /schedulemail/ HTTP/1.1" 500 95162
2023-09-13 07:53:18 ERROR "GET /schedulemail/ HTTP/1.1" 500 95162
2023-09-14 07:20:43 ERROR Internal Server Error: /schedulemail/
Traceback (most recent call last):
  File "/home/aakash/PROJECTS/LOGIN_AUTHENTICATION/myenv/lib/python3.8/site-packages/django/core/handlers/exception.py", line 55, in inner
    response = get_response(request)
  File "/home/aakash/PROJECTS/LOGIN_AUTHENTICATION/myenv/lib/python3.8/site-packages/django/core/handlers/base.py", line 197, in _get_response
    response = wrapped_callback(request, *callback_args, **callback_kwargs)
  File "/home/aakash/PROJECTS/LOGIN_AUTHENTICATION/Authentication_System/myapp/views.py", line 1895, in schedule_mail
    task = PeriodicTask.objects.create(crontab=schedule, name='schedule_mail_task_'+'1', task='send_mail_app.tasks.send_mail_func') #, args=json.dumps([[2,3]]) )
  File "/home/aakash/PROJECTS/LOGIN_AUTHENTICATION/myenv/lib/python3.8/site-packages/django/db/models/manager.py", line 87, in manager_method
    return getattr(self.get_queryset(), name)(*args, **kwargs)
  File "/home/aakash/PROJECTS/LOGIN_AUTHENTICATION/myenv/lib/python3.8/site-packages/django/db/models/query.py", line 658, in create
    obj.save(force_insert=True, using=self.db)
  File "/home/aakash/PROJECTS/LOGIN_AUTHENTICATION/myenv/lib/python3.8/site-packages/django_celery_beat/models.py", line 594, in save
    self.validate_unique()
  File "/home/aakash/PROJECTS/LOGIN_AUTHENTICATION/myenv/lib/python3.8/site-packages/django_celery_beat/models.py", line 561, in validate_unique
    super().validate_unique(*args, **kwargs)
  File "/home/aakash/PROJECTS/LOGIN_AUTHENTICATION/myenv/lib/python3.8/site-packages/django/db/models/base.py", line 1236, in validate_unique
    raise ValidationError(errors)
django.core.exceptions.ValidationError: {'name': ['Periodic task with this Name already exists.']}
2023-09-14 07:20:43 ERROR "GET /schedulemail/ HTTP/1.1" 500 94910
2023-09-14 07:20:43 ERROR "GET /schedulemail/ HTTP/1.1" 500 94910
2023-09-14 07:31:54 ERROR Internal Server Error: /schedulemail/
Traceback (most recent call last):
  File "/home/aakash/PROJECTS/LOGIN_AUTHENTICATION/myenv/lib/python3.8/site-packages/django/core/handlers/exception.py", line 55, in inner
    response = get_response(request)
  File "/home/aakash/PROJECTS/LOGIN_AUTHENTICATION/myenv/lib/python3.8/site-packages/django/core/handlers/base.py", line 197, in _get_response
    response = wrapped_callback(request, *callback_args, **callback_kwargs)
  File "/home/aakash/PROJECTS/LOGIN_AUTHENTICATION/Authentication_System/myapp/views.py", line 1895, in schedule_mail
    task = PeriodicTask.objects.create(crontab=schedule, name='schedule_mail_task_'+'3', task='send_mail_app.tasks.send_mail_func') #, args=json.dumps([[2,3]]) )
  File "/home/aakash/PROJECTS/LOGIN_AUTHENTICATION/myenv/lib/python3.8/site-packages/django/db/models/manager.py", line 87, in manager_method
    return getattr(self.get_queryset(), name)(*args, **kwargs)
  File "/home/aakash/PROJECTS/LOGIN_AUTHENTICATION/myenv/lib/python3.8/site-packages/django/db/models/query.py", line 658, in create
    obj.save(force_insert=True, using=self.db)
  File "/home/aakash/PROJECTS/LOGIN_AUTHENTICATION/myenv/lib/python3.8/site-packages/django_celery_beat/models.py", line 594, in save
    self.validate_unique()
  File "/home/aakash/PROJECTS/LOGIN_AUTHENTICATION/myenv/lib/python3.8/site-packages/django_celery_beat/models.py", line 561, in validate_unique
    super().validate_unique(*args, **kwargs)
  File "/home/aakash/PROJECTS/LOGIN_AUTHENTICATION/myenv/lib/python3.8/site-packages/django/db/models/base.py", line 1236, in validate_unique
    raise ValidationError(errors)
django.core.exceptions.ValidationError: {'name': ['Periodic task with this Name already exists.']}
2023-09-14 07:31:54 ERROR "GET /schedulemail/ HTTP/1.1" 500 95069
2023-09-14 07:31:54 ERROR "GET /schedulemail/ HTTP/1.1" 500 95069
2023-09-14 07:31:57 ERROR Internal Server Error: /schedulemail/
Traceback (most recent call last):
  File "/home/aakash/PROJECTS/LOGIN_AUTHENTICATION/myenv/lib/python3.8/site-packages/django/core/handlers/exception.py", line 55, in inner
    response = get_response(request)
  File "/home/aakash/PROJECTS/LOGIN_AUTHENTICATION/myenv/lib/python3.8/site-packages/django/core/handlers/base.py", line 197, in _get_response
    response = wrapped_callback(request, *callback_args, **callback_kwargs)
  File "/home/aakash/PROJECTS/LOGIN_AUTHENTICATION/Authentication_System/myapp/views.py", line 1895, in schedule_mail
    task = PeriodicTask.objects.create(crontab=schedule, name='schedule_mail_task_'+'3', task='send_mail_app.tasks.send_mail_func') #, args=json.dumps([[2,3]]) )
  File "/home/aakash/PROJECTS/LOGIN_AUTHENTICATION/myenv/lib/python3.8/site-packages/django/db/models/manager.py", line 87, in manager_method
    return getattr(self.get_queryset(), name)(*args, **kwargs)
  File "/home/aakash/PROJECTS/LOGIN_AUTHENTICATION/myenv/lib/python3.8/site-packages/django/db/models/query.py", line 658, in create
    obj.save(force_insert=True, using=self.db)
  File "/home/aakash/PROJECTS/LOGIN_AUTHENTICATION/myenv/lib/python3.8/site-packages/django_celery_beat/models.py", line 594, in save
    self.validate_unique()
  File "/home/aakash/PROJECTS/LOGIN_AUTHENTICATION/myenv/lib/python3.8/site-packages/django_celery_beat/models.py", line 561, in validate_unique
    super().validate_unique(*args, **kwargs)
  File "/home/aakash/PROJECTS/LOGIN_AUTHENTICATION/myenv/lib/python3.8/site-packages/django/db/models/base.py", line 1236, in validate_unique
    raise ValidationError(errors)
django.core.exceptions.ValidationError: {'name': ['Periodic task with this Name already exists.']}
2023-09-14 07:31:57 ERROR "GET /schedulemail/ HTTP/1.1" 500 95070
2023-09-14 07:31:57 ERROR "GET /schedulemail/ HTTP/1.1" 500 95070
2023-09-15 10:04:54 ERROR Internal Server Error: /schedule_mail_with_attachment/
Traceback (most recent call last):
  File "/home/aakash/PROJECTS/LOGIN_AUTHENTICATION/myenv/lib/python3.8/site-packages/django/core/handlers/exception.py", line 55, in inner
    response = get_response(request)
  File "/home/aakash/PROJECTS/LOGIN_AUTHENTICATION/myenv/lib/python3.8/site-packages/django/core/handlers/base.py", line 197, in _get_response
    response = wrapped_callback(request, *callback_args, **callback_kwargs)
  File "/home/aakash/PROJECTS/LOGIN_AUTHENTICATION/Authentication_System/myapp/views.py", line 1900, in schedule_mail_with_attachment
    task = PeriodicTask.objects.create(crontab=schedule, name='schedule_mail_with_attachment_'+'1', task='send_mail_app.tasks.generate_pdf_and_send_email') #, args=json.dumps([[2,3]]) )
  File "/home/aakash/PROJECTS/LOGIN_AUTHENTICATION/myenv/lib/python3.8/site-packages/django/db/models/manager.py", line 87, in manager_method
    return getattr(self.get_queryset(), name)(*args, **kwargs)
  File "/home/aakash/PROJECTS/LOGIN_AUTHENTICATION/myenv/lib/python3.8/site-packages/django/db/models/query.py", line 658, in create
    obj.save(force_insert=True, using=self.db)
  File "/home/aakash/PROJECTS/LOGIN_AUTHENTICATION/myenv/lib/python3.8/site-packages/django_celery_beat/models.py", line 594, in save
    self.validate_unique()
  File "/home/aakash/PROJECTS/LOGIN_AUTHENTICATION/myenv/lib/python3.8/site-packages/django_celery_beat/models.py", line 561, in validate_unique
    super().validate_unique(*args, **kwargs)
  File "/home/aakash/PROJECTS/LOGIN_AUTHENTICATION/myenv/lib/python3.8/site-packages/django/db/models/base.py", line 1236, in validate_unique
    raise ValidationError(errors)
django.core.exceptions.ValidationError: {'name': ['Periodic task with this Name already exists.']}
2023-09-15 10:04:54 ERROR "GET /schedule_mail_with_attachment/ HTTP/1.1" 500 95746
2023-09-15 10:04:54 ERROR "GET /schedule_mail_with_attachment/ HTTP/1.1" 500 95746
2023-09-15 10:21:45 ERROR Signal handler <bound method DjangoFixup.on_import_modules of <celery.fixups.django.DjangoFixup object at 0x7f3d870470d0>> raised: SyntaxError('invalid syntax', ('/home/aakash/PROJECTS/LOGIN_AUTHENTICATION/Authentication_System/send_mail_app/tasks.py', 36, 1, 'from django.core.mail import EmailMessage\n'))
Traceback (most recent call last):
  File "/home/aakash/PROJECTS/LOGIN_AUTHENTICATION/myenv/lib/python3.8/site-packages/celery/utils/dispatch/signal.py", line 276, in send
    response = receiver(signal=self, sender=sender, **named)
  File "/home/aakash/PROJECTS/LOGIN_AUTHENTICATION/myenv/lib/python3.8/site-packages/celery/fixups/django.py", line 97, in on_import_modules
    self.worker_fixup.validate_models()
  File "/home/aakash/PROJECTS/LOGIN_AUTHENTICATION/myenv/lib/python3.8/site-packages/celery/fixups/django.py", line 137, in validate_models
    run_checks()
  File "/home/aakash/PROJECTS/LOGIN_AUTHENTICATION/myenv/lib/python3.8/site-packages/django/core/checks/registry.py", line 88, in run_checks
    new_errors = check(app_configs=app_configs, databases=databases)
  File "/home/aakash/PROJECTS/LOGIN_AUTHENTICATION/myenv/lib/python3.8/site-packages/django/core/checks/urls.py", line 14, in check_url_config
    return check_resolver(resolver)
  File "/home/aakash/PROJECTS/LOGIN_AUTHENTICATION/myenv/lib/python3.8/site-packages/django/core/checks/urls.py", line 24, in check_resolver
    return check_method()
  File "/home/aakash/PROJECTS/LOGIN_AUTHENTICATION/myenv/lib/python3.8/site-packages/django/urls/resolvers.py", line 494, in check
    for pattern in self.url_patterns:
  File "/home/aakash/PROJECTS/LOGIN_AUTHENTICATION/myenv/lib/python3.8/site-packages/django/utils/functional.py", line 57, in __get__
    res = instance.__dict__[self.name] = self.func(instance)
  File "/home/aakash/PROJECTS/LOGIN_AUTHENTICATION/myenv/lib/python3.8/site-packages/django/urls/resolvers.py", line 715, in url_patterns
    patterns = getattr(self.urlconf_module, "urlpatterns", self.urlconf_module)
  File "/home/aakash/PROJECTS/LOGIN_AUTHENTICATION/myenv/lib/python3.8/site-packages/django/utils/functional.py", line 57, in __get__
    res = instance.__dict__[self.name] = self.func(instance)
  File "/home/aakash/PROJECTS/LOGIN_AUTHENTICATION/myenv/lib/python3.8/site-packages/django/urls/resolvers.py", line 708, in urlconf_module
    return import_module(self.urlconf_name)
  File "/usr/lib/python3.8/importlib/__init__.py", line 127, in import_module
    return _bootstrap._gcd_import(name[level:], package, level)
  File "<frozen importlib._bootstrap>", line 1014, in _gcd_import
  File "<frozen importlib._bootstrap>", line 991, in _find_and_load
  File "<frozen importlib._bootstrap>", line 975, in _find_and_load_unlocked
  File "<frozen importlib._bootstrap>", line 671, in _load_unlocked
  File "<frozen importlib._bootstrap_external>", line 848, in exec_module
  File "<frozen importlib._bootstrap>", line 219, in _call_with_frames_removed
  File "/home/aakash/PROJECTS/LOGIN_AUTHENTICATION/Authentication_System/Authentication_System/urls.py", line 27, in <module>
    path('',include('myapp.urls')),
  File "/home/aakash/PROJECTS/LOGIN_AUTHENTICATION/myenv/lib/python3.8/site-packages/django/urls/conf.py", line 38, in include
    urlconf_module = import_module(urlconf_module)
  File "/usr/lib/python3.8/importlib/__init__.py", line 127, in import_module
    return _bootstrap._gcd_import(name[level:], package, level)
  File "<frozen importlib._bootstrap>", line 1014, in _gcd_import
  File "<frozen importlib._bootstrap>", line 991, in _find_and_load
  File "<frozen importlib._bootstrap>", line 975, in _find_and_load_unlocked
  File "<frozen importlib._bootstrap>", line 671, in _load_unlocked
  File "<frozen importlib._bootstrap_external>", line 848, in exec_module
  File "<frozen importlib._bootstrap>", line 219, in _call_with_frames_removed
  File "/home/aakash/PROJECTS/LOGIN_AUTHENTICATION/Authentication_System/myapp/urls.py", line 3, in <module>
    from myapp.views import *
  File "/home/aakash/PROJECTS/LOGIN_AUTHENTICATION/Authentication_System/myapp/views.py", line 1883, in <module>
    from send_mail_app.tasks import send_mail_func
  File "/home/aakash/PROJECTS/LOGIN_AUTHENTICATION/Authentication_System/send_mail_app/tasks.py", line 36
    from django.core.mail import EmailMessage
    ^
SyntaxError: invalid syntax
2023-09-15 10:21:45 ERROR Signal handler <promise@0x7f3d870445e0 --> <bound method Celery._autodiscover_tasks of <Celery Authentication_System at 0x7f3d870c9130>>> raised: SyntaxError('invalid syntax', ('/home/aakash/PROJECTS/LOGIN_AUTHENTICATION/Authentication_System/send_mail_app/tasks.py', 36, 1, 'from django.core.mail import EmailMessage\n'))
Traceback (most recent call last):
  File "/home/aakash/PROJECTS/LOGIN_AUTHENTICATION/myenv/lib/python3.8/site-packages/celery/utils/dispatch/signal.py", line 276, in send
    response = receiver(signal=self, sender=sender, **named)
  File "/home/aakash/PROJECTS/LOGIN_AUTHENTICATION/myenv/lib/python3.8/site-packages/vine/promises.py", line 160, in __call__
    return self.throw()
  File "/home/aakash/PROJECTS/LOGIN_AUTHENTICATION/myenv/lib/python3.8/site-packages/vine/promises.py", line 157, in __call__
    retval = fun(*final_args, **final_kwargs)
  File "/home/aakash/PROJECTS/LOGIN_AUTHENTICATION/myenv/lib/python3.8/site-packages/celery/app/base.py", line 691, in _autodiscover_tasks
    return self._autodiscover_tasks_from_fixups(related_name)
  File "/home/aakash/PROJECTS/LOGIN_AUTHENTICATION/myenv/lib/python3.8/site-packages/celery/app/base.py", line 700, in _autodiscover_tasks_from_fixups
    return self._autodiscover_tasks_from_names([
  File "/home/aakash/PROJECTS/LOGIN_AUTHENTICATION/myenv/lib/python3.8/site-packages/celery/app/base.py", line 695, in _autodiscover_tasks_from_names
    return self.loader.autodiscover_tasks(
  File "/home/aakash/PROJECTS/LOGIN_AUTHENTICATION/myenv/lib/python3.8/site-packages/celery/loaders/base.py", line 220, in autodiscover_tasks
    mod.__name__ for mod in autodiscover_tasks(packages or (),
  File "/home/aakash/PROJECTS/LOGIN_AUTHENTICATION/myenv/lib/python3.8/site-packages/celery/loaders/base.py", line 246, in autodiscover_tasks
    return [find_related_module(pkg, related_name) for pkg in packages]
  File "/home/aakash/PROJECTS/LOGIN_AUTHENTICATION/myenv/lib/python3.8/site-packages/celery/loaders/base.py", line 246, in <listcomp>
    return [find_related_module(pkg, related_name) for pkg in packages]
  File "/home/aakash/PROJECTS/LOGIN_AUTHENTICATION/myenv/lib/python3.8/site-packages/celery/loaders/base.py", line 267, in find_related_module
    return importlib.import_module(module_name)
  File "/usr/lib/python3.8/importlib/__init__.py", line 127, in import_module
    return _bootstrap._gcd_import(name[level:], package, level)
  File "<frozen importlib._bootstrap>", line 1014, in _gcd_import
  File "<frozen importlib._bootstrap>", line 991, in _find_and_load
  File "<frozen importlib._bootstrap>", line 975, in _find_and_load_unlocked
  File "<frozen importlib._bootstrap>", line 671, in _load_unlocked
  File "<frozen importlib._bootstrap_external>", line 844, in exec_module
  File "<frozen importlib._bootstrap_external>", line 981, in get_code
  File "<frozen importlib._bootstrap_external>", line 911, in source_to_code
  File "<frozen importlib._bootstrap>", line 219, in _call_with_frames_removed
  File "/home/aakash/PROJECTS/LOGIN_AUTHENTICATION/Authentication_System/send_mail_app/tasks.py", line 36
    from django.core.mail import EmailMessage
    ^
SyntaxError: invalid syntax
2023-09-15 10:42:58 ERROR Internal Server Error: /schedule_mail_with_attachment/
Traceback (most recent call last):
  File "/home/aakash/PROJECTS/LOGIN_AUTHENTICATION/myenv/lib/python3.8/site-packages/django/core/handlers/exception.py", line 55, in inner
    response = get_response(request)
  File "/home/aakash/PROJECTS/LOGIN_AUTHENTICATION/myenv/lib/python3.8/site-packages/django/core/handlers/base.py", line 197, in _get_response
    response = wrapped_callback(request, *callback_args, **callback_kwargs)
  File "/home/aakash/PROJECTS/LOGIN_AUTHENTICATION/Authentication_System/myapp/views.py", line 1900, in schedule_mail_with_attachment
    task = PeriodicTask.objects.create(crontab=schedule, name='schedule_mail_with_attachment_'+'6', task='send_mail_app.tasks.generate_excel_and_send_email')
  File "/home/aakash/PROJECTS/LOGIN_AUTHENTICATION/myenv/lib/python3.8/site-packages/django/db/models/manager.py", line 87, in manager_method
    return getattr(self.get_queryset(), name)(*args, **kwargs)
  File "/home/aakash/PROJECTS/LOGIN_AUTHENTICATION/myenv/lib/python3.8/site-packages/django/db/models/query.py", line 658, in create
    obj.save(force_insert=True, using=self.db)
  File "/home/aakash/PROJECTS/LOGIN_AUTHENTICATION/myenv/lib/python3.8/site-packages/django_celery_beat/models.py", line 594, in save
    self.validate_unique()
  File "/home/aakash/PROJECTS/LOGIN_AUTHENTICATION/myenv/lib/python3.8/site-packages/django_celery_beat/models.py", line 561, in validate_unique
    super().validate_unique(*args, **kwargs)
  File "/home/aakash/PROJECTS/LOGIN_AUTHENTICATION/myenv/lib/python3.8/site-packages/django/db/models/base.py", line 1236, in validate_unique
    raise ValidationError(errors)
django.core.exceptions.ValidationError: {'name': ['Periodic task with this Name already exists.']}
2023-09-15 10:42:58 ERROR "GET /schedule_mail_with_attachment/ HTTP/1.1" 500 96286
2023-09-15 10:42:58 ERROR "GET /schedule_mail_with_attachment/ HTTP/1.1" 500 96286
2023-09-18 07:17:13 ERROR Internal Server Error: /schedule_mail_with_attachment/
Traceback (most recent call last):
  File "/home/aakash/PROJECTS/LOGIN_AUTHENTICATION/myenv/lib/python3.8/site-packages/django/core/handlers/exception.py", line 55, in inner
    response = get_response(request)
  File "/home/aakash/PROJECTS/LOGIN_AUTHENTICATION/myenv/lib/python3.8/site-packages/django/core/handlers/base.py", line 197, in _get_response
    response = wrapped_callback(request, *callback_args, **callback_kwargs)
  File "/home/aakash/PROJECTS/LOGIN_AUTHENTICATION/Authentication_System/myapp/views.py", line 1900, in schedule_mail_with_attachment
    task = PeriodicTask.objects.create(crontab=schedule, name='schedule_mail_with_attachment_'+'9', task='send_mail_app.tasks.generate_excel_and_send_email')
  File "/home/aakash/PROJECTS/LOGIN_AUTHENTICATION/myenv/lib/python3.8/site-packages/django/db/models/manager.py", line 87, in manager_method
    return getattr(self.get_queryset(), name)(*args, **kwargs)
  File "/home/aakash/PROJECTS/LOGIN_AUTHENTICATION/myenv/lib/python3.8/site-packages/django/db/models/query.py", line 658, in create
    obj.save(force_insert=True, using=self.db)
  File "/home/aakash/PROJECTS/LOGIN_AUTHENTICATION/myenv/lib/python3.8/site-packages/django_celery_beat/models.py", line 594, in save
    self.validate_unique()
  File "/home/aakash/PROJECTS/LOGIN_AUTHENTICATION/myenv/lib/python3.8/site-packages/django_celery_beat/models.py", line 561, in validate_unique
    super().validate_unique(*args, **kwargs)
  File "/home/aakash/PROJECTS/LOGIN_AUTHENTICATION/myenv/lib/python3.8/site-packages/django/db/models/base.py", line 1236, in validate_unique
    raise ValidationError(errors)
django.core.exceptions.ValidationError: {'name': ['Periodic task with this Name already exists.']}
2023-09-18 07:17:13 ERROR "GET /schedule_mail_with_attachment/ HTTP/1.1" 500 96435
2023-09-18 07:17:13 ERROR "GET /schedule_mail_with_attachment/ HTTP/1.1" 500 96435
2023-09-19 11:27:56 ERROR Internal Server Error: /schedulemail/
Traceback (most recent call last):
  File "/home/aakash/PROJECTS/LOGIN_AUTHENTICATION/myenv/lib/python3.8/site-packages/django/core/handlers/exception.py", line 55, in inner
    response = get_response(request)
  File "/home/aakash/PROJECTS/LOGIN_AUTHENTICATION/myenv/lib/python3.8/site-packages/django/core/handlers/base.py", line 197, in _get_response
    response = wrapped_callback(request, *callback_args, **callback_kwargs)
  File "/home/aakash/PROJECTS/LOGIN_AUTHENTICATION/Authentication_System/myapp/views.py", line 1895, in schedule_mail
    task = PeriodicTask.objects.create(crontab=schedule, name='schedule_mail_task_'+'1', task='send_mail_app.tasks.send_mail_func') #, args=json.dumps([[2,3]]) )
  File "/home/aakash/PROJECTS/LOGIN_AUTHENTICATION/myenv/lib/python3.8/site-packages/django/db/models/manager.py", line 87, in manager_method
    return getattr(self.get_queryset(), name)(*args, **kwargs)
  File "/home/aakash/PROJECTS/LOGIN_AUTHENTICATION/myenv/lib/python3.8/site-packages/django/db/models/query.py", line 658, in create
    obj.save(force_insert=True, using=self.db)
  File "/home/aakash/PROJECTS/LOGIN_AUTHENTICATION/myenv/lib/python3.8/site-packages/django_celery_beat/models.py", line 594, in save
    self.validate_unique()
  File "/home/aakash/PROJECTS/LOGIN_AUTHENTICATION/myenv/lib/python3.8/site-packages/django_celery_beat/models.py", line 561, in validate_unique
    super().validate_unique(*args, **kwargs)
  File "/home/aakash/PROJECTS/LOGIN_AUTHENTICATION/myenv/lib/python3.8/site-packages/django/db/models/base.py", line 1236, in validate_unique
    raise ValidationError(errors)
django.core.exceptions.ValidationError: {'name': ['Periodic task with this Name already exists.']}
2023-09-19 11:27:56 ERROR "GET /schedulemail/ HTTP/1.1" 500 96595
2023-09-19 11:27:56 ERROR "GET /schedulemail/ HTTP/1.1" 500 96595
2023-09-19 11:27:57 ERROR Internal Server Error: /schedulemail/
Traceback (most recent call last):
  File "/home/aakash/PROJECTS/LOGIN_AUTHENTICATION/myenv/lib/python3.8/site-packages/django/core/handlers/exception.py", line 55, in inner
    response = get_response(request)
  File "/home/aakash/PROJECTS/LOGIN_AUTHENTICATION/myenv/lib/python3.8/site-packages/django/core/handlers/base.py", line 197, in _get_response
    response = wrapped_callback(request, *callback_args, **callback_kwargs)
  File "/home/aakash/PROJECTS/LOGIN_AUTHENTICATION/Authentication_System/myapp/views.py", line 1895, in schedule_mail
    task = PeriodicTask.objects.create(crontab=schedule, name='schedule_mail_task_'+'1', task='send_mail_app.tasks.send_mail_func') #, args=json.dumps([[2,3]]) )
  File "/home/aakash/PROJECTS/LOGIN_AUTHENTICATION/myenv/lib/python3.8/site-packages/django/db/models/manager.py", line 87, in manager_method
    return getattr(self.get_queryset(), name)(*args, **kwargs)
  File "/home/aakash/PROJECTS/LOGIN_AUTHENTICATION/myenv/lib/python3.8/site-packages/django/db/models/query.py", line 658, in create
    obj.save(force_insert=True, using=self.db)
  File "/home/aakash/PROJECTS/LOGIN_AUTHENTICATION/myenv/lib/python3.8/site-packages/django_celery_beat/models.py", line 594, in save
    self.validate_unique()
  File "/home/aakash/PROJECTS/LOGIN_AUTHENTICATION/myenv/lib/python3.8/site-packages/django_celery_beat/models.py", line 561, in validate_unique
    super().validate_unique(*args, **kwargs)
  File "/home/aakash/PROJECTS/LOGIN_AUTHENTICATION/myenv/lib/python3.8/site-packages/django/db/models/base.py", line 1236, in validate_unique
    raise ValidationError(errors)
django.core.exceptions.ValidationError: {'name': ['Periodic task with this Name already exists.']}
2023-09-19 11:27:57 ERROR "GET /schedulemail/ HTTP/1.1" 500 96322
2023-09-19 11:27:57 ERROR "GET /schedulemail/ HTTP/1.1" 500 96322
2023-10-19 07:27:28 ERROR Internal Server Error: /QuestionDetail/2/
Traceback (most recent call last):
  File "/home/aakash/PROJECTS/LOGIN_AUTHENTICATION/myenv/lib/python3.8/site-packages/django/core/handlers/exception.py", line 55, in inner
    response = get_response(request)
  File "/home/aakash/PROJECTS/LOGIN_AUTHENTICATION/myenv/lib/python3.8/site-packages/django/core/handlers/base.py", line 197, in _get_response
    response = wrapped_callback(request, *callback_args, **callback_kwargs)
  File "/home/aakash/PROJECTS/LOGIN_AUTHENTICATION/myenv/lib/python3.8/site-packages/django/views/decorators/csrf.py", line 56, in wrapper_view
    return view_func(*args, **kwargs)
  File "/home/aakash/PROJECTS/LOGIN_AUTHENTICATION/myenv/lib/python3.8/site-packages/django/views/generic/base.py", line 104, in view
    return self.dispatch(request, *args, **kwargs)
  File "/home/aakash/PROJECTS/LOGIN_AUTHENTICATION/myenv/lib/python3.8/site-packages/rest_framework/views.py", line 509, in dispatch
    response = self.handle_exception(exc)
  File "/home/aakash/PROJECTS/LOGIN_AUTHENTICATION/myenv/lib/python3.8/site-packages/rest_framework/views.py", line 469, in handle_exception
    self.raise_uncaught_exception(exc)
  File "/home/aakash/PROJECTS/LOGIN_AUTHENTICATION/myenv/lib/python3.8/site-packages/rest_framework/views.py", line 480, in raise_uncaught_exception
    raise exc
  File "/home/aakash/PROJECTS/LOGIN_AUTHENTICATION/myenv/lib/python3.8/site-packages/rest_framework/views.py", line 506, in dispatch
    response = handler(request, *args, **kwargs)
  File "/home/aakash/PROJECTS/LOGIN_AUTHENTICATION/Authentication_System/myapp/views.py", line 1934, in get
    question = Question.objects.get(id=id)
  File "/home/aakash/PROJECTS/LOGIN_AUTHENTICATION/myenv/lib/python3.8/site-packages/django/db/models/manager.py", line 87, in manager_method
    return getattr(self.get_queryset(), name)(*args, **kwargs)
  File "/home/aakash/PROJECTS/LOGIN_AUTHENTICATION/myenv/lib/python3.8/site-packages/django/db/models/query.py", line 637, in get
    raise self.model.DoesNotExist(
myapp.models.Question.DoesNotExist: Question matching query does not exist.
2023-10-19 07:27:28 ERROR "GET /QuestionDetail/2/ HTTP/1.1" 500 105437
2023-10-19 07:27:28 ERROR "GET /QuestionDetail/2/ HTTP/1.1" 500 105437
2023-10-19 07:29:09 ERROR Internal Server Error: /QuestionDetail/2/
Traceback (most recent call last):
  File "/home/aakash/PROJECTS/LOGIN_AUTHENTICATION/myenv/lib/python3.8/site-packages/django/core/handlers/exception.py", line 55, in inner
    response = get_response(request)
  File "/home/aakash/PROJECTS/LOGIN_AUTHENTICATION/myenv/lib/python3.8/site-packages/django/core/handlers/base.py", line 197, in _get_response
    response = wrapped_callback(request, *callback_args, **callback_kwargs)
  File "/home/aakash/PROJECTS/LOGIN_AUTHENTICATION/myenv/lib/python3.8/site-packages/django/views/decorators/csrf.py", line 56, in wrapper_view
    return view_func(*args, **kwargs)
  File "/home/aakash/PROJECTS/LOGIN_AUTHENTICATION/myenv/lib/python3.8/site-packages/django/views/generic/base.py", line 104, in view
    return self.dispatch(request, *args, **kwargs)
  File "/home/aakash/PROJECTS/LOGIN_AUTHENTICATION/myenv/lib/python3.8/site-packages/rest_framework/views.py", line 509, in dispatch
    response = self.handle_exception(exc)
  File "/home/aakash/PROJECTS/LOGIN_AUTHENTICATION/myenv/lib/python3.8/site-packages/rest_framework/views.py", line 469, in handle_exception
    self.raise_uncaught_exception(exc)
  File "/home/aakash/PROJECTS/LOGIN_AUTHENTICATION/myenv/lib/python3.8/site-packages/rest_framework/views.py", line 480, in raise_uncaught_exception
    raise exc
  File "/home/aakash/PROJECTS/LOGIN_AUTHENTICATION/myenv/lib/python3.8/site-packages/rest_framework/views.py", line 506, in dispatch
    response = handler(request, *args, **kwargs)
  File "/home/aakash/PROJECTS/LOGIN_AUTHENTICATION/Authentication_System/myapp/views.py", line 1939, in get
    return Response(serializer.errors, status=400)
UnboundLocalError: local variable 'serializer' referenced before assignment
2023-10-19 07:29:09 ERROR "GET /QuestionDetail/2/ HTTP/1.1" 500 97012
2023-10-19 07:29:09 ERROR "GET /QuestionDetail/2/ HTTP/1.1" 500 97012
2023-10-19 11:26:06 ERROR Internal Server Error: /answers/
Traceback (most recent call last):
  File "/home/aakash/PROJECTS/LOGIN_AUTHENTICATION/myenv/lib/python3.8/site-packages/django/core/handlers/exception.py", line 55, in inner
    response = get_response(request)
  File "/home/aakash/PROJECTS/LOGIN_AUTHENTICATION/myenv/lib/python3.8/site-packages/django/core/handlers/base.py", line 197, in _get_response
    response = wrapped_callback(request, *callback_args, **callback_kwargs)
  File "/home/aakash/PROJECTS/LOGIN_AUTHENTICATION/myenv/lib/python3.8/site-packages/django/views/decorators/csrf.py", line 56, in wrapper_view
    return view_func(*args, **kwargs)
  File "/home/aakash/PROJECTS/LOGIN_AUTHENTICATION/myenv/lib/python3.8/site-packages/django/views/generic/base.py", line 104, in view
    return self.dispatch(request, *args, **kwargs)
  File "/home/aakash/PROJECTS/LOGIN_AUTHENTICATION/myenv/lib/python3.8/site-packages/rest_framework/views.py", line 509, in dispatch
    response = self.handle_exception(exc)
  File "/home/aakash/PROJECTS/LOGIN_AUTHENTICATION/myenv/lib/python3.8/site-packages/rest_framework/views.py", line 469, in handle_exception
    self.raise_uncaught_exception(exc)
  File "/home/aakash/PROJECTS/LOGIN_AUTHENTICATION/myenv/lib/python3.8/site-packages/rest_framework/views.py", line 480, in raise_uncaught_exception
    raise exc
  File "/home/aakash/PROJECTS/LOGIN_AUTHENTICATION/myenv/lib/python3.8/site-packages/rest_framework/views.py", line 506, in dispatch
    response = handler(request, *args, **kwargs)
  File "/home/aakash/PROJECTS/LOGIN_AUTHENTICATION/Authentication_System/myapp/views.py", line 1989, in get
    return Response({'status':200 , 'payload':serializer.data})
  File "/home/aakash/PROJECTS/LOGIN_AUTHENTICATION/myenv/lib/python3.8/site-packages/rest_framework/serializers.py", line 768, in data
    ret = super().data
  File "/home/aakash/PROJECTS/LOGIN_AUTHENTICATION/myenv/lib/python3.8/site-packages/rest_framework/serializers.py", line 253, in data
    self._data = self.to_representation(self.instance)
  File "/home/aakash/PROJECTS/LOGIN_AUTHENTICATION/myenv/lib/python3.8/site-packages/rest_framework/serializers.py", line 686, in to_representation
    return [
  File "/home/aakash/PROJECTS/LOGIN_AUTHENTICATION/myenv/lib/python3.8/site-packages/rest_framework/serializers.py", line 687, in <listcomp>
    self.child.to_representation(item) for item in iterable
  File "/home/aakash/PROJECTS/LOGIN_AUTHENTICATION/myenv/lib/python3.8/site-packages/rest_framework/serializers.py", line 522, in to_representation
    ret[field.field_name] = field.to_representation(attribute)
  File "/home/aakash/PROJECTS/LOGIN_AUTHENTICATION/myenv/lib/python3.8/site-packages/rest_framework/serializers.py", line 686, in to_representation
    return [
TypeError: 'Question' object is not iterable
2023-10-19 11:26:06 ERROR "GET /answers/ HTTP/1.1" 500 124579
2023-10-19 11:26:06 ERROR "GET /answers/ HTTP/1.1" 500 124579
2023-10-19 11:31:42 ERROR Internal Server Error: /answers/
Traceback (most recent call last):
  File "/home/aakash/PROJECTS/LOGIN_AUTHENTICATION/myenv/lib/python3.8/site-packages/django/core/handlers/exception.py", line 55, in inner
    response = get_response(request)
  File "/home/aakash/PROJECTS/LOGIN_AUTHENTICATION/myenv/lib/python3.8/site-packages/django/core/handlers/base.py", line 197, in _get_response
    response = wrapped_callback(request, *callback_args, **callback_kwargs)
  File "/home/aakash/PROJECTS/LOGIN_AUTHENTICATION/myenv/lib/python3.8/site-packages/django/views/decorators/csrf.py", line 56, in wrapper_view
    return view_func(*args, **kwargs)
  File "/home/aakash/PROJECTS/LOGIN_AUTHENTICATION/myenv/lib/python3.8/site-packages/django/views/generic/base.py", line 104, in view
    return self.dispatch(request, *args, **kwargs)
  File "/home/aakash/PROJECTS/LOGIN_AUTHENTICATION/myenv/lib/python3.8/site-packages/rest_framework/views.py", line 509, in dispatch
    response = self.handle_exception(exc)
  File "/home/aakash/PROJECTS/LOGIN_AUTHENTICATION/myenv/lib/python3.8/site-packages/rest_framework/views.py", line 469, in handle_exception
    self.raise_uncaught_exception(exc)
  File "/home/aakash/PROJECTS/LOGIN_AUTHENTICATION/myenv/lib/python3.8/site-packages/rest_framework/views.py", line 480, in raise_uncaught_exception
    raise exc
  File "/home/aakash/PROJECTS/LOGIN_AUTHENTICATION/myenv/lib/python3.8/site-packages/rest_framework/views.py", line 506, in dispatch
    response = handler(request, *args, **kwargs)
  File "/home/aakash/PROJECTS/LOGIN_AUTHENTICATION/Authentication_System/myapp/views.py", line 1989, in get
    return Response({'status':200 , 'payload':serializer.data})
  File "/home/aakash/PROJECTS/LOGIN_AUTHENTICATION/myenv/lib/python3.8/site-packages/rest_framework/serializers.py", line 768, in data
    ret = super().data
  File "/home/aakash/PROJECTS/LOGIN_AUTHENTICATION/myenv/lib/python3.8/site-packages/rest_framework/serializers.py", line 253, in data
    self._data = self.to_representation(self.instance)
  File "/home/aakash/PROJECTS/LOGIN_AUTHENTICATION/myenv/lib/python3.8/site-packages/rest_framework/serializers.py", line 686, in to_representation
    return [
  File "/home/aakash/PROJECTS/LOGIN_AUTHENTICATION/myenv/lib/python3.8/site-packages/rest_framework/serializers.py", line 687, in <listcomp>
    self.child.to_representation(item) for item in iterable
  File "/home/aakash/PROJECTS/LOGIN_AUTHENTICATION/myenv/lib/python3.8/site-packages/rest_framework/serializers.py", line 522, in to_representation
    ret[field.field_name] = field.to_representation(attribute)
  File "/home/aakash/PROJECTS/LOGIN_AUTHENTICATION/myenv/lib/python3.8/site-packages/rest_framework/serializers.py", line 686, in to_representation
    return [
TypeError: 'Question' object is not iterable
2023-10-19 11:31:42 ERROR "GET /answers/ HTTP/1.1" 500 123566
2023-10-19 11:31:42 ERROR "GET /answers/ HTTP/1.1" 500 123566
2023-10-19 11:32:04 ERROR Internal Server Error: /answers/
Traceback (most recent call last):
  File "/home/aakash/PROJECTS/LOGIN_AUTHENTICATION/myenv/lib/python3.8/site-packages/rest_framework/fields.py", line 446, in get_attribute
    return get_attribute(instance, self.source_attrs)
  File "/home/aakash/PROJECTS/LOGIN_AUTHENTICATION/myenv/lib/python3.8/site-packages/rest_framework/fields.py", line 96, in get_attribute
    instance = getattr(instance, attr)
AttributeError: 'str' object has no attribute 'text'

During handling of the above exception, another exception occurred:

Traceback (most recent call last):
  File "/home/aakash/PROJECTS/LOGIN_AUTHENTICATION/myenv/lib/python3.8/site-packages/django/core/handlers/exception.py", line 55, in inner
    response = get_response(request)
  File "/home/aakash/PROJECTS/LOGIN_AUTHENTICATION/myenv/lib/python3.8/site-packages/django/core/handlers/base.py", line 197, in _get_response
    response = wrapped_callback(request, *callback_args, **callback_kwargs)
  File "/home/aakash/PROJECTS/LOGIN_AUTHENTICATION/myenv/lib/python3.8/site-packages/django/views/decorators/csrf.py", line 56, in wrapper_view
    return view_func(*args, **kwargs)
  File "/home/aakash/PROJECTS/LOGIN_AUTHENTICATION/myenv/lib/python3.8/site-packages/django/views/generic/base.py", line 104, in view
    return self.dispatch(request, *args, **kwargs)
  File "/home/aakash/PROJECTS/LOGIN_AUTHENTICATION/myenv/lib/python3.8/site-packages/rest_framework/views.py", line 509, in dispatch
    response = self.handle_exception(exc)
  File "/home/aakash/PROJECTS/LOGIN_AUTHENTICATION/myenv/lib/python3.8/site-packages/rest_framework/views.py", line 469, in handle_exception
    self.raise_uncaught_exception(exc)
  File "/home/aakash/PROJECTS/LOGIN_AUTHENTICATION/myenv/lib/python3.8/site-packages/rest_framework/views.py", line 480, in raise_uncaught_exception
    raise exc
  File "/home/aakash/PROJECTS/LOGIN_AUTHENTICATION/myenv/lib/python3.8/site-packages/rest_framework/views.py", line 506, in dispatch
    response = handler(request, *args, **kwargs)
  File "/home/aakash/PROJECTS/LOGIN_AUTHENTICATION/Authentication_System/myapp/views.py", line 1989, in get
    return Response({'status':200 , 'payload':serializer.data})
  File "/home/aakash/PROJECTS/LOGIN_AUTHENTICATION/myenv/lib/python3.8/site-packages/rest_framework/serializers.py", line 768, in data
    ret = super().data
  File "/home/aakash/PROJECTS/LOGIN_AUTHENTICATION/myenv/lib/python3.8/site-packages/rest_framework/serializers.py", line 253, in data
    self._data = self.to_representation(self.instance)
  File "/home/aakash/PROJECTS/LOGIN_AUTHENTICATION/myenv/lib/python3.8/site-packages/rest_framework/serializers.py", line 686, in to_representation
    return [
  File "/home/aakash/PROJECTS/LOGIN_AUTHENTICATION/myenv/lib/python3.8/site-packages/rest_framework/serializers.py", line 687, in <listcomp>
    self.child.to_representation(item) for item in iterable
  File "/home/aakash/PROJECTS/LOGIN_AUTHENTICATION/myenv/lib/python3.8/site-packages/rest_framework/serializers.py", line 522, in to_representation
    ret[field.field_name] = field.to_representation(attribute)
  File "/home/aakash/PROJECTS/LOGIN_AUTHENTICATION/myenv/lib/python3.8/site-packages/rest_framework/serializers.py", line 686, in to_representation
    return [
  File "/home/aakash/PROJECTS/LOGIN_AUTHENTICATION/myenv/lib/python3.8/site-packages/rest_framework/serializers.py", line 687, in <listcomp>
    self.child.to_representation(item) for item in iterable
  File "/home/aakash/PROJECTS/LOGIN_AUTHENTICATION/myenv/lib/python3.8/site-packages/rest_framework/serializers.py", line 509, in to_representation
    attribute = field.get_attribute(instance)
  File "/home/aakash/PROJECTS/LOGIN_AUTHENTICATION/myenv/lib/python3.8/site-packages/rest_framework/fields.py", line 479, in get_attribute
    raise type(exc)(msg)
AttributeError: Got AttributeError when attempting to get a value for field `text` on serializer `QuestionSerializer`.
The serializer field might be named incorrectly and not match any attribute or key on the `str` instance.
Original exception text was: 'str' object has no attribute 'text'.
2023-10-19 11:32:04 ERROR "GET /answers/ HTTP/1.1" 500 147054
2023-10-19 11:32:04 ERROR "GET /answers/ HTTP/1.1" 500 147054
