2023-07-17 14:59:00 ERROR please enter valid credentials for logout
2023-07-17 19:59:03 ERROR password and confirm password must be same , please check it and try again
2023-07-17 19:59:52 ERROR An error occurred: Register matching query does not exist.
2023-07-17 19:59:52 ERROR Internal Server Error: /login/
2023-07-17 19:59:52 ERROR "POST /login/ HTTP/1.1" 500 49
2023-07-17 19:59:52 ERROR "POST /login/ HTTP/1.1" 500 49
2023-07-17 20:00:40 ERROR Please enter a valid token
2023-07-17 20:01:22 ERROR please enter valid credentials for logout
2023-07-17 20:01:33 ERROR please enter valid credentials for logout
2023-07-18 18:35:29 ERROR invalid serializer data
2023-07-19 14:39:06 ERROR serializer is not valid , please check the json data
2023-07-19 18:44:47 ERROR An error occurred: Field name `OTP` is not valid for model `Login`.
2023-07-19 18:44:47 ERROR Internal Server Error: /login/
2023-07-19 18:44:47 ERROR "POST /login/ HTTP/1.1" 500 49
2023-07-19 18:44:47 ERROR "POST /login/ HTTP/1.1" 500 49
2023-07-19 18:47:58 ERROR An error occurred: Field name `OTP` is not valid for model `Login`.
2023-07-19 18:47:58 ERROR Internal Server Error: /login/
2023-07-19 18:47:58 ERROR "POST /login/ HTTP/1.1" 500 49
2023-07-19 18:47:58 ERROR "POST /login/ HTTP/1.1" 500 49
2023-07-19 18:51:13 ERROR An error occurred: 'builtin_function_or_method' object is not subscriptable
2023-07-19 18:51:13 ERROR Internal Server Error: /login/
2023-07-19 18:51:13 ERROR "POST /login/ HTTP/1.1" 500 49
2023-07-19 18:51:13 ERROR "POST /login/ HTTP/1.1" 500 49
2023-07-19 19:45:32 ERROR An error occurred: 'builtin_function_or_method' object is not subscriptable
2023-07-19 19:45:32 ERROR Internal Server Error: /login/
2023-07-19 19:45:32 ERROR "POST /login/ HTTP/1.1" 500 49
2023-07-19 19:45:32 ERROR "POST /login/ HTTP/1.1" 500 49
2023-07-19 19:47:23 ERROR An error occurred: 'builtin_function_or_method' object is not subscriptable
2023-07-19 19:47:23 ERROR Internal Server Error: /login/
2023-07-19 19:47:23 ERROR "POST /login/ HTTP/1.1" 500 49
2023-07-19 19:47:23 ERROR "POST /login/ HTTP/1.1" 500 49
2023-07-19 19:53:25 ERROR An error occurred: 'builtin_function_or_method' object is not subscriptable
2023-07-19 19:53:25 ERROR Internal Server Error: /login/
2023-07-19 19:53:25 ERROR "POST /login/ HTTP/1.1" 500 49
2023-07-19 19:53:25 ERROR "POST /login/ HTTP/1.1" 500 49
2023-07-19 19:53:27 ERROR An error occurred: 'builtin_function_or_method' object is not subscriptable
2023-07-19 19:53:27 ERROR Internal Server Error: /login/
2023-07-19 19:53:27 ERROR "POST /login/ HTTP/1.1" 500 49
2023-07-19 19:53:27 ERROR "POST /login/ HTTP/1.1" 500 49
2023-07-19 19:59:17 ERROR An error occurred: 'builtin_function_or_method' object is not subscriptable
2023-07-19 19:59:17 ERROR Internal Server Error: /login/
2023-07-19 19:59:17 ERROR "POST /login/ HTTP/1.1" 500 49
2023-07-19 19:59:17 ERROR "POST /login/ HTTP/1.1" 500 49
2023-07-19 20:05:17 ERROR An error occurred: 'builtin_function_or_method' object is not subscriptable
2023-07-19 20:05:17 ERROR Internal Server Error: /login/
2023-07-19 20:05:17 ERROR "POST /login/ HTTP/1.1" 500 49
2023-07-19 20:05:17 ERROR "POST /login/ HTTP/1.1" 500 49
2023-07-19 20:16:53 ERROR An error occurred: 'builtin_function_or_method' object is not subscriptable
2023-07-19 20:16:53 ERROR Internal Server Error: /login/
2023-07-19 20:16:53 ERROR "POST /login/ HTTP/1.1" 500 49
2023-07-19 20:16:53 ERROR "POST /login/ HTTP/1.1" 500 49
2023-07-19 20:18:24 ERROR An error occurred: 'builtin_function_or_method' object is not subscriptable
2023-07-19 20:18:24 ERROR Internal Server Error: /login/
2023-07-19 20:18:24 ERROR "POST /login/ HTTP/1.1" 500 49
2023-07-19 20:18:24 ERROR "POST /login/ HTTP/1.1" 500 49
2023-07-19 20:18:41 ERROR An error occurred: 'builtin_function_or_method' object is not subscriptable
2023-07-19 20:18:41 ERROR Internal Server Error: /login/
2023-07-19 20:18:41 ERROR "POST /login/ HTTP/1.1" 500 49
2023-07-19 20:18:41 ERROR "POST /login/ HTTP/1.1" 500 49
2023-07-19 20:20:31 ERROR An error occurred: Field name `entered_otp` is not valid for model `Login`.
2023-07-19 20:20:31 ERROR Internal Server Error: /login/
2023-07-19 20:20:31 ERROR "POST /login/ HTTP/1.1" 500 49
2023-07-19 20:20:31 ERROR "POST /login/ HTTP/1.1" 500 49
2023-07-19 20:26:19 ERROR An error occurred: 'builtin_function_or_method' object is not subscriptable
2023-07-19 20:26:19 ERROR Internal Server Error: /login/
2023-07-19 20:26:19 ERROR "POST /login/ HTTP/1.1" 500 49
2023-07-19 20:26:19 ERROR "POST /login/ HTTP/1.1" 500 49
2023-07-19 20:27:13 ERROR An error occurred: Field name `entered_otp` is not valid for model `Login`.
2023-07-19 20:27:13 ERROR Internal Server Error: /login/
2023-07-19 20:27:13 ERROR "POST /login/ HTTP/1.1" 500 49
2023-07-19 20:27:13 ERROR "POST /login/ HTTP/1.1" 500 49
2023-07-21 13:54:34 ERROR An error occurred: Field name `entered_otp` is not valid for model `Login`.
2023-07-21 13:54:34 ERROR Internal Server Error: /login/
2023-07-21 13:54:34 ERROR "POST /login/ HTTP/1.1" 500 49
2023-07-21 13:54:34 ERROR "POST /login/ HTTP/1.1" 500 49
2023-07-21 13:55:48 ERROR An error occurred: 'builtin_function_or_method' object is not subscriptable
2023-07-21 13:55:48 ERROR Internal Server Error: /login/
2023-07-21 13:55:48 ERROR "POST /login/ HTTP/1.1" 500 49
2023-07-21 13:55:48 ERROR "POST /login/ HTTP/1.1" 500 49
2023-07-21 13:55:56 ERROR An error occurred: 'builtin_function_or_method' object is not subscriptable
2023-07-21 13:55:56 ERROR Internal Server Error: /login/
2023-07-21 13:55:56 ERROR "POST /login/ HTTP/1.1" 500 49
2023-07-21 13:55:56 ERROR "POST /login/ HTTP/1.1" 500 49
2023-07-21 13:55:58 ERROR An error occurred: 'builtin_function_or_method' object is not subscriptable
2023-07-21 13:55:58 ERROR Internal Server Error: /login/
2023-07-21 13:55:58 ERROR "POST /login/ HTTP/1.1" 500 49
2023-07-21 13:55:58 ERROR "POST /login/ HTTP/1.1" 500 49
2023-07-21 13:57:07 ERROR An error occurred: 'builtin_function_or_method' object is not subscriptable
2023-07-21 13:57:07 ERROR Internal Server Error: /login/
2023-07-21 13:57:07 ERROR "POST /login/ HTTP/1.1" 500 49
2023-07-21 13:57:07 ERROR "POST /login/ HTTP/1.1" 500 49
2023-07-21 13:59:42 ERROR An error occurred: Register matching query does not exist.
2023-07-21 13:59:42 ERROR Internal Server Error: /login/
2023-07-21 13:59:42 ERROR "POST /login/ HTTP/1.1" 500 49
2023-07-21 13:59:42 ERROR "POST /login/ HTTP/1.1" 500 49
2023-07-21 14:00:44 ERROR An error occurred: Register matching query does not exist.
2023-07-21 14:00:44 ERROR Internal Server Error: /login/
2023-07-21 14:00:44 ERROR "POST /login/ HTTP/1.1" 500 49
2023-07-21 14:00:44 ERROR "POST /login/ HTTP/1.1" 500 49
2023-07-21 14:00:45 ERROR An error occurred: Register matching query does not exist.
2023-07-21 14:00:45 ERROR Internal Server Error: /login/
2023-07-21 14:00:45 ERROR "POST /login/ HTTP/1.1" 500 49
2023-07-21 14:00:45 ERROR "POST /login/ HTTP/1.1" 500 49
2023-07-21 14:02:24 ERROR An error occurred: Register matching query does not exist.
2023-07-21 14:02:24 ERROR Internal Server Error: /login/
2023-07-21 14:02:24 ERROR "POST /login/ HTTP/1.1" 500 49
2023-07-21 14:02:24 ERROR "POST /login/ HTTP/1.1" 500 49
2023-07-21 14:02:48 ERROR An error occurred: Register matching query does not exist.
2023-07-21 14:02:48 ERROR Internal Server Error: /login/
2023-07-21 14:02:48 ERROR "POST /login/ HTTP/1.1" 500 49
2023-07-21 14:02:48 ERROR "POST /login/ HTTP/1.1" 500 49
2023-07-21 14:03:10 ERROR An error occurred: Register matching query does not exist.
2023-07-21 14:03:10 ERROR Internal Server Error: /login/
2023-07-21 14:03:10 ERROR "POST /login/ HTTP/1.1" 500 49
2023-07-21 14:03:10 ERROR "POST /login/ HTTP/1.1" 500 49
2023-07-21 14:04:00 ERROR An error occurred: Register matching query does not exist.
2023-07-21 14:04:00 ERROR Internal Server Error: /login/
2023-07-21 14:04:00 ERROR "POST /login/ HTTP/1.1" 500 49
2023-07-21 14:04:00 ERROR "POST /login/ HTTP/1.1" 500 49
2023-07-21 14:05:38 ERROR An error occurred: Register matching query does not exist.
2023-07-21 14:05:38 ERROR Internal Server Error: /login/
2023-07-21 14:05:38 ERROR "POST /login/ HTTP/1.1" 500 49
2023-07-21 14:05:38 ERROR "POST /login/ HTTP/1.1" 500 49
2023-07-21 14:06:18 ERROR An error occurred: 'QuerySet' object has no attribute 'email'
2023-07-21 14:06:18 ERROR Internal Server Error: /login/
2023-07-21 14:06:18 ERROR "POST /login/ HTTP/1.1" 500 49
2023-07-21 14:06:18 ERROR "POST /login/ HTTP/1.1" 500 49
2023-07-21 14:06:59 ERROR An error occurred: 'QuerySet' object has no attribute 'email'
2023-07-21 14:06:59 ERROR Internal Server Error: /login/
2023-07-21 14:06:59 ERROR "POST /login/ HTTP/1.1" 500 49
2023-07-21 14:06:59 ERROR "POST /login/ HTTP/1.1" 500 49
2023-07-21 14:08:01 ERROR An error occurred: 'QuerySet' object has no attribute 'email'
2023-07-21 14:08:01 ERROR Internal Server Error: /login/
2023-07-21 14:08:01 ERROR "POST /login/ HTTP/1.1" 500 49
2023-07-21 14:08:01 ERROR "POST /login/ HTTP/1.1" 500 49
2023-07-21 14:08:25 ERROR An error occurred: 'QuerySet' object has no attribute 'email'
2023-07-21 14:08:25 ERROR Internal Server Error: /login/
2023-07-21 14:08:25 ERROR "POST /login/ HTTP/1.1" 500 49
2023-07-21 14:08:25 ERROR "POST /login/ HTTP/1.1" 500 49
2023-07-21 14:08:56 ERROR EMAIL OR PASSWORD IS INCORRECT
2023-07-21 14:09:54 ERROR An error occurred: 'QuerySet' object has no attribute 'email'
2023-07-21 14:09:54 ERROR Internal Server Error: /login/
2023-07-21 14:09:54 ERROR "POST /login/ HTTP/1.1" 500 49
2023-07-21 14:09:54 ERROR "POST /login/ HTTP/1.1" 500 49
2023-07-21 14:10:42 ERROR An error occurred: 'QuerySet' object has no attribute 'email'
2023-07-21 14:10:42 ERROR Internal Server Error: /login/
2023-07-21 14:10:42 ERROR "POST /login/ HTTP/1.1" 500 49
2023-07-21 14:10:42 ERROR "POST /login/ HTTP/1.1" 500 49
2023-07-21 14:11:31 ERROR An error occurred: too many values to unpack (expected 2)
2023-07-21 14:11:31 ERROR Internal Server Error: /login/
2023-07-21 14:11:31 ERROR "POST /login/ HTTP/1.1" 500 49
2023-07-21 14:11:31 ERROR "POST /login/ HTTP/1.1" 500 49
2023-07-21 14:12:16 ERROR An error occurred: 'QuerySet' object has no attribute 'email'
2023-07-21 14:12:16 ERROR Internal Server Error: /login/
2023-07-21 14:12:16 ERROR "POST /login/ HTTP/1.1" 500 49
2023-07-21 14:12:16 ERROR "POST /login/ HTTP/1.1" 500 49
2023-07-21 14:13:09 ERROR An error occurred: QuerySet indices must be integers or slices, not str.
2023-07-21 14:13:09 ERROR Internal Server Error: /login/
2023-07-21 14:13:09 ERROR "POST /login/ HTTP/1.1" 500 49
2023-07-21 14:13:09 ERROR "POST /login/ HTTP/1.1" 500 49
2023-07-21 14:15:12 ERROR An error occurred: 'QuerySet' object has no attribute 'email'
2023-07-21 14:15:12 ERROR Internal Server Error: /login/
2023-07-21 14:15:12 ERROR "POST /login/ HTTP/1.1" 500 49
2023-07-21 14:15:12 ERROR "POST /login/ HTTP/1.1" 500 49
2023-07-21 14:16:42 ERROR invalid serializer data
2023-07-21 14:45:22 ERROR An error occurred: 'QuerySet' object has no attribute 'email'
2023-07-21 14:45:22 ERROR Internal Server Error: /login/
2023-07-21 14:45:22 ERROR "POST /login/ HTTP/1.1" 500 49
2023-07-21 14:45:22 ERROR "POST /login/ HTTP/1.1" 500 49
2023-07-21 17:34:08 ERROR invalid serializer data
2023-07-21 17:45:35 ERROR An error occurred: Cannot resolve keyword 'otp' into field. Choices are: OTP, confirm_password, email, first_name, id, last_name, mobile, password, username
2023-07-21 17:45:35 ERROR Internal Server Error: /login/
2023-07-21 17:45:35 ERROR "POST /login/ HTTP/1.1" 500 49
2023-07-21 17:45:35 ERROR "POST /login/ HTTP/1.1" 500 49
2023-07-21 17:52:02 ERROR invalid serializer data
2023-07-21 17:56:30 ERROR An error occurred: QuerySet indices must be integers or slices, not str.
2023-07-21 17:56:30 ERROR Internal Server Error: /login/
2023-07-21 17:56:30 ERROR "POST /login/ HTTP/1.1" 500 49
2023-07-21 17:56:30 ERROR "POST /login/ HTTP/1.1" 500 49
2023-07-21 18:01:29 ERROR An error occurred: too many values to unpack (expected 2)
2023-07-21 18:01:29 ERROR Internal Server Error: /login/
2023-07-21 18:01:29 ERROR "POST /login/ HTTP/1.1" 500 49
2023-07-21 18:01:29 ERROR "POST /login/ HTTP/1.1" 500 49
2023-07-21 18:02:11 ERROR An error occurred: 'Register' object has no attribute 'get'
2023-07-21 18:02:11 ERROR Internal Server Error: /login/
2023-07-21 18:02:11 ERROR "POST /login/ HTTP/1.1" 500 49
2023-07-21 18:02:11 ERROR "POST /login/ HTTP/1.1" 500 49
2023-07-21 18:04:07 ERROR An error occurred: name 'a' is not defined
2023-07-21 18:04:07 ERROR Internal Server Error: /login/
2023-07-21 18:04:07 ERROR "POST /login/ HTTP/1.1" 500 49
2023-07-21 18:04:07 ERROR "POST /login/ HTTP/1.1" 500 49
2023-07-21 18:04:53 ERROR An error occurred: name 'a' is not defined
2023-07-21 18:04:53 ERROR Internal Server Error: /login/
2023-07-21 18:04:53 ERROR "POST /login/ HTTP/1.1" 500 49
2023-07-21 18:04:53 ERROR "POST /login/ HTTP/1.1" 500 49
2023-07-21 18:09:41 ERROR An error occurred: name 'entered_otp' is not defined
2023-07-21 18:09:41 ERROR Internal Server Error: /login/
2023-07-21 18:09:41 ERROR "POST /login/ HTTP/1.1" 500 49
2023-07-21 18:09:41 ERROR "POST /login/ HTTP/1.1" 500 49
2023-07-21 18:29:07 ERROR invalid serializer data
2023-07-21 18:34:20 ERROR invalid credentials
2023-07-21 18:34:57 ERROR An error occurred: Register matching query does not exist.
2023-07-21 18:34:57 ERROR Internal Server Error: /login/
2023-07-21 18:34:57 ERROR "POST /login/ HTTP/1.1" 500 49
2023-07-21 18:34:57 ERROR "POST /login/ HTTP/1.1" 500 49
2023-07-21 18:35:08 ERROR An error occurred: Register matching query does not exist.
2023-07-21 18:35:08 ERROR Internal Server Error: /login/
2023-07-21 18:35:08 ERROR "POST /login/ HTTP/1.1" 500 49
2023-07-21 18:35:08 ERROR "POST /login/ HTTP/1.1" 500 49
2023-07-21 18:37:19 ERROR An error occurred: Register matching query does not exist.
2023-07-21 18:37:19 ERROR Internal Server Error: /login/
2023-07-21 18:37:19 ERROR "POST /login/ HTTP/1.1" 500 49
2023-07-21 18:37:19 ERROR "POST /login/ HTTP/1.1" 500 49
2023-07-21 18:39:03 ERROR An error occurred: Register matching query does not exist.
2023-07-21 18:39:03 ERROR Internal Server Error: /login/
2023-07-21 18:39:03 ERROR "POST /login/ HTTP/1.1" 500 49
2023-07-21 18:39:03 ERROR "POST /login/ HTTP/1.1" 500 49
2023-07-21 18:40:42 ERROR An error occurred: Register matching query does not exist.
2023-07-21 18:40:42 ERROR Internal Server Error: /login/
2023-07-21 18:40:42 ERROR "POST /login/ HTTP/1.1" 500 49
2023-07-21 18:40:42 ERROR "POST /login/ HTTP/1.1" 500 49
2023-07-21 18:42:33 ERROR An error occurred: Register matching query does not exist.
2023-07-21 18:42:33 ERROR Internal Server Error: /login/
2023-07-21 18:42:33 ERROR "POST /login/ HTTP/1.1" 500 49
2023-07-21 18:42:33 ERROR "POST /login/ HTTP/1.1" 500 49
2023-07-21 18:43:47 ERROR EMAIL OR PASSWORD IS INCORRECT
2023-07-21 18:44:44 ERROR An error occurred: 'QuerySet' object has no attribute 'OTP'
2023-07-21 18:44:44 ERROR Internal Server Error: /login/
2023-07-21 18:44:44 ERROR "POST /login/ HTTP/1.1" 500 49
2023-07-21 18:44:44 ERROR "POST /login/ HTTP/1.1" 500 49
2023-07-21 18:44:49 ERROR An error occurred: 'QuerySet' object has no attribute 'OTP'
2023-07-21 18:44:49 ERROR Internal Server Error: /login/
2023-07-21 18:44:49 ERROR "POST /login/ HTTP/1.1" 500 49
2023-07-21 18:44:49 ERROR "POST /login/ HTTP/1.1" 500 49
2023-07-21 18:46:54 ERROR An error occurred: 'QuerySet' object has no attribute 'OTP'
2023-07-21 18:46:54 ERROR Internal Server Error: /login/
2023-07-21 18:46:54 ERROR "POST /login/ HTTP/1.1" 500 49
2023-07-21 18:46:54 ERROR "POST /login/ HTTP/1.1" 500 49
2023-07-21 18:48:38 ERROR An error occurred: tuple indices must be integers or slices, not str
2023-07-21 18:48:38 ERROR Internal Server Error: /login/
2023-07-21 18:48:38 ERROR "POST /login/ HTTP/1.1" 500 49
2023-07-21 18:48:38 ERROR "POST /login/ HTTP/1.1" 500 49
2023-07-21 18:49:44 ERROR An error occurred: 'QuerySet' object has no attribute 'OTP'
2023-07-21 18:49:44 ERROR Internal Server Error: /login/
2023-07-21 18:49:44 ERROR "POST /login/ HTTP/1.1" 500 49
2023-07-21 18:49:44 ERROR "POST /login/ HTTP/1.1" 500 49
2023-07-21 18:50:43 ERROR An error occurred: 2
2023-07-21 18:50:43 ERROR Internal Server Error: /login/
2023-07-21 18:50:43 ERROR "POST /login/ HTTP/1.1" 500 49
2023-07-21 18:50:43 ERROR "POST /login/ HTTP/1.1" 500 49
2023-07-21 18:51:16 ERROR An error occurred: 'QuerySet' object has no attribute 'OTP'
2023-07-21 18:51:16 ERROR Internal Server Error: /login/
2023-07-21 18:51:16 ERROR "POST /login/ HTTP/1.1" 500 49
2023-07-21 18:51:16 ERROR "POST /login/ HTTP/1.1" 500 49
2023-07-21 18:52:25 ERROR An error occurred: 'QuerySet' object has no attribute 'OTP'
2023-07-21 18:52:25 ERROR Internal Server Error: /login/
2023-07-21 18:52:25 ERROR "POST /login/ HTTP/1.1" 500 49
2023-07-21 18:52:25 ERROR "POST /login/ HTTP/1.1" 500 49
2023-07-21 18:54:13 ERROR An error occurred: 'QuerySet' object has no attribute 'email'
2023-07-21 18:54:13 ERROR Internal Server Error: /login/
2023-07-21 18:54:13 ERROR "POST /login/ HTTP/1.1" 500 49
2023-07-21 18:54:13 ERROR "POST /login/ HTTP/1.1" 500 49
2023-07-21 18:56:04 ERROR invalid credentials
2023-07-21 18:56:46 ERROR An error occurred: list index out of range
2023-07-21 18:56:46 ERROR Internal Server Error: /login/
2023-07-21 18:56:46 ERROR "POST /login/ HTTP/1.1" 500 49
2023-07-21 18:56:46 ERROR "POST /login/ HTTP/1.1" 500 49
2023-07-21 18:57:41 ERROR EMAIL OR PASSWORD IS INCORRECT
2023-07-21 18:57:54 ERROR invalid credentials
2023-07-21 18:58:27 ERROR An error occurred: 'QuerySet' object has no attribute 'email'
2023-07-21 18:58:27 ERROR Internal Server Error: /login/
2023-07-21 18:58:27 ERROR "POST /login/ HTTP/1.1" 500 49
2023-07-21 18:58:27 ERROR "POST /login/ HTTP/1.1" 500 49
2023-07-21 18:59:00 ERROR invalid serializer data
2023-07-21 18:59:21 ERROR An error occurred: 'QuerySet' object has no attribute 'email'
2023-07-21 18:59:21 ERROR Internal Server Error: /login/
2023-07-21 18:59:21 ERROR "POST /login/ HTTP/1.1" 500 49
2023-07-21 18:59:21 ERROR "POST /login/ HTTP/1.1" 500 49
2023-07-21 19:00:15 ERROR invalid serializer data
2023-07-21 19:00:28 ERROR An error occurred: 'QuerySet' object has no attribute 'id'
2023-07-21 19:00:28 ERROR Internal Server Error: /login/
2023-07-21 19:00:28 ERROR "POST /login/ HTTP/1.1" 500 49
2023-07-21 19:00:28 ERROR "POST /login/ HTTP/1.1" 500 49
2023-07-21 19:01:45 ERROR An error occurred: 'Login' object has no attribute 'update'
2023-07-21 19:01:45 ERROR Internal Server Error: /login/
2023-07-21 19:01:45 ERROR "POST /login/ HTTP/1.1" 500 49
2023-07-21 19:01:45 ERROR "POST /login/ HTTP/1.1" 500 49
2023-07-21 19:03:34 ERROR invalid serializer data
2023-07-21 19:03:59 ERROR An error occurred: 'QuerySet' object has no attribute 'id'
2023-07-21 19:03:59 ERROR Internal Server Error: /login/
2023-07-21 19:03:59 ERROR "POST /login/ HTTP/1.1" 500 49
2023-07-21 19:03:59 ERROR "POST /login/ HTTP/1.1" 500 49
2023-07-21 19:05:30 ERROR invalid serializer data
2023-07-21 19:05:43 ERROR An error occurred: 'QuerySet' object has no attribute 'id'
2023-07-21 19:05:43 ERROR Internal Server Error: /login/
2023-07-21 19:05:43 ERROR "POST /login/ HTTP/1.1" 500 49
2023-07-21 19:05:43 ERROR "POST /login/ HTTP/1.1" 500 49
2023-07-21 19:06:35 ERROR invalid serializer data
2023-07-21 19:06:48 ERROR An error occurred: 'Login' object has no attribute 'values'
2023-07-21 19:06:48 ERROR Internal Server Error: /login/
2023-07-21 19:06:48 ERROR "POST /login/ HTTP/1.1" 500 49
2023-07-21 19:06:48 ERROR "POST /login/ HTTP/1.1" 500 49
2023-07-21 19:07:31 ERROR invalid serializer data
2023-07-21 19:08:14 ERROR An error occurred: 'Login' object has no attribute 'values'
2023-07-21 19:08:14 ERROR Internal Server Error: /login/
2023-07-21 19:08:14 ERROR "POST /login/ HTTP/1.1" 500 49
2023-07-21 19:08:14 ERROR "POST /login/ HTTP/1.1" 500 49
2023-07-21 19:15:36 ERROR invalid serializer data
2023-07-21 19:16:08 ERROR An error occurred: 'Login' object has no attribute 'update'
2023-07-21 19:16:08 ERROR Internal Server Error: /login/
2023-07-21 19:16:08 ERROR "POST /login/ HTTP/1.1" 500 49
2023-07-21 19:16:08 ERROR "POST /login/ HTTP/1.1" 500 49
2023-07-21 19:17:31 ERROR invalid serializer data
2023-07-21 19:17:52 ERROR An error occurred: 'Login' object has no attribute 'update'
2023-07-21 19:17:52 ERROR Internal Server Error: /login/
2023-07-21 19:17:52 ERROR "POST /login/ HTTP/1.1" 500 49
2023-07-21 19:17:52 ERROR "POST /login/ HTTP/1.1" 500 49
2023-07-21 19:18:16 ERROR An error occurred: 'QuerySet' object has no attribute 'id'
2023-07-21 19:18:16 ERROR Internal Server Error: /login/
2023-07-21 19:18:16 ERROR "POST /login/ HTTP/1.1" 500 49
2023-07-21 19:18:16 ERROR "POST /login/ HTTP/1.1" 500 49
2023-07-21 19:20:55 ERROR An error occurred: 'str' object has no attribute 'id'
2023-07-21 19:20:55 ERROR Internal Server Error: /login/
2023-07-21 19:20:55 ERROR "POST /login/ HTTP/1.1" 500 49
2023-07-21 19:20:55 ERROR "POST /login/ HTTP/1.1" 500 49
2023-07-21 19:23:00 ERROR invalid serializer data
2023-07-21 19:25:09 ERROR EMAIL OR PASSWORD IS INCORRECT
2023-07-21 19:25:53 ERROR invalid credentials
2023-07-21 19:28:05 ERROR please enter valid credentials for logout
2023-07-21 19:28:22 ERROR Invalid token.
2023-07-21 19:30:35 ERROR password and confirm password must be same , please check it and try again
2023-07-21 19:31:41 ERROR EMAIL OR PASSWORD IS INCORRECT
2023-07-21 19:31:51 ERROR invalid credentials
2023-07-24 13:39:13 ERROR serializer is not valid , please check the json data
2023-07-24 13:39:23 ERROR password and confirm password must be same , please check it and try again
2023-07-24 13:48:03 ERROR EMAIL OR PASSWORD IS INCORRECT
2023-07-24 13:48:33 ERROR invalid credentials
2023-07-24 13:50:49 ERROR Invalid token.
2023-07-24 13:51:22 ERROR please enter valid credentials for logout
2023-07-24 13:51:31 ERROR please enter valid credentials for logout
2023-07-24 13:51:39 ERROR please enter valid credentials for logout
2023-07-25 13:02:17 ERROR Internal Server Error: /orm_implementation/
Traceback (most recent call last):
  File "/home/aakash/PROJECTS/LOGIN_AUTHENTICATION/myenv/lib/python3.8/site-packages/django/core/handlers/exception.py", line 55, in inner
    response = get_response(request)
  File "/home/aakash/PROJECTS/LOGIN_AUTHENTICATION/myenv/lib/python3.8/site-packages/django/core/handlers/base.py", line 220, in _get_response
    response = response.render()
  File "/home/aakash/PROJECTS/LOGIN_AUTHENTICATION/myenv/lib/python3.8/site-packages/django/template/response.py", line 114, in render
    self.content = self.rendered_content
  File "/home/aakash/PROJECTS/LOGIN_AUTHENTICATION/myenv/lib/python3.8/site-packages/rest_framework/response.py", line 70, in rendered_content
    ret = renderer.render(self.data, accepted_media_type, context)
  File "/home/aakash/PROJECTS/LOGIN_AUTHENTICATION/myenv/lib/python3.8/site-packages/rest_framework/renderers.py", line 99, in render
    ret = json.dumps(
  File "/home/aakash/PROJECTS/LOGIN_AUTHENTICATION/myenv/lib/python3.8/site-packages/rest_framework/utils/json.py", line 25, in dumps
    return json.dumps(*args, **kwargs)
  File "/usr/lib/python3.8/json/__init__.py", line 234, in dumps
    return cls(
  File "/usr/lib/python3.8/json/encoder.py", line 199, in encode
    chunks = self.iterencode(o, _one_shot=True)
  File "/usr/lib/python3.8/json/encoder.py", line 257, in iterencode
    return _iterencode(o, 0)
  File "/home/aakash/PROJECTS/LOGIN_AUTHENTICATION/myenv/lib/python3.8/site-packages/rest_framework/utils/encoders.py", line 67, in default
    return super().default(obj)
  File "/usr/lib/python3.8/json/encoder.py", line 179, in default
    raise TypeError(f'Object of type {o.__class__.__name__} '
TypeError: Object of type Register is not JSON serializable
2023-07-25 13:02:17 ERROR "GET /orm_implementation/ HTTP/1.1" 500 108844
2023-07-25 13:02:17 ERROR "GET /orm_implementation/ HTTP/1.1" 500 108844
2023-07-25 13:02:41 ERROR Internal Server Error: /orm_implementation/
Traceback (most recent call last):
  File "/home/aakash/PROJECTS/LOGIN_AUTHENTICATION/myenv/lib/python3.8/site-packages/django/core/handlers/exception.py", line 55, in inner
    response = get_response(request)
  File "/home/aakash/PROJECTS/LOGIN_AUTHENTICATION/myenv/lib/python3.8/site-packages/django/core/handlers/base.py", line 220, in _get_response
    response = response.render()
  File "/home/aakash/PROJECTS/LOGIN_AUTHENTICATION/myenv/lib/python3.8/site-packages/django/template/response.py", line 114, in render
    self.content = self.rendered_content
  File "/home/aakash/PROJECTS/LOGIN_AUTHENTICATION/myenv/lib/python3.8/site-packages/rest_framework/response.py", line 70, in rendered_content
    ret = renderer.render(self.data, accepted_media_type, context)
  File "/home/aakash/PROJECTS/LOGIN_AUTHENTICATION/myenv/lib/python3.8/site-packages/rest_framework/renderers.py", line 99, in render
    ret = json.dumps(
  File "/home/aakash/PROJECTS/LOGIN_AUTHENTICATION/myenv/lib/python3.8/site-packages/rest_framework/utils/json.py", line 25, in dumps
    return json.dumps(*args, **kwargs)
  File "/usr/lib/python3.8/json/__init__.py", line 234, in dumps
    return cls(
  File "/usr/lib/python3.8/json/encoder.py", line 199, in encode
    chunks = self.iterencode(o, _one_shot=True)
  File "/usr/lib/python3.8/json/encoder.py", line 257, in iterencode
    return _iterencode(o, 0)
  File "/home/aakash/PROJECTS/LOGIN_AUTHENTICATION/myenv/lib/python3.8/site-packages/rest_framework/utils/encoders.py", line 67, in default
    return super().default(obj)
  File "/usr/lib/python3.8/json/encoder.py", line 179, in default
    raise TypeError(f'Object of type {o.__class__.__name__} '
TypeError: Object of type Register is not JSON serializable
2023-07-25 13:02:41 ERROR "GET /orm_implementation/ HTTP/1.1" 500 108844
2023-07-25 13:02:41 ERROR "GET /orm_implementation/ HTTP/1.1" 500 108844
2023-07-25 13:22:41 ERROR Internal Server Error: /orm_implementation/
Traceback (most recent call last):
  File "/home/aakash/PROJECTS/LOGIN_AUTHENTICATION/myenv/lib/python3.8/site-packages/django/core/handlers/exception.py", line 55, in inner
    response = get_response(request)
  File "/home/aakash/PROJECTS/LOGIN_AUTHENTICATION/myenv/lib/python3.8/site-packages/django/core/handlers/base.py", line 220, in _get_response
    response = response.render()
  File "/home/aakash/PROJECTS/LOGIN_AUTHENTICATION/myenv/lib/python3.8/site-packages/django/template/response.py", line 114, in render
    self.content = self.rendered_content
  File "/home/aakash/PROJECTS/LOGIN_AUTHENTICATION/myenv/lib/python3.8/site-packages/rest_framework/response.py", line 70, in rendered_content
    ret = renderer.render(self.data, accepted_media_type, context)
  File "/home/aakash/PROJECTS/LOGIN_AUTHENTICATION/myenv/lib/python3.8/site-packages/rest_framework/renderers.py", line 99, in render
    ret = json.dumps(
  File "/home/aakash/PROJECTS/LOGIN_AUTHENTICATION/myenv/lib/python3.8/site-packages/rest_framework/utils/json.py", line 25, in dumps
    return json.dumps(*args, **kwargs)
  File "/usr/lib/python3.8/json/__init__.py", line 234, in dumps
    return cls(
  File "/usr/lib/python3.8/json/encoder.py", line 199, in encode
    chunks = self.iterencode(o, _one_shot=True)
  File "/usr/lib/python3.8/json/encoder.py", line 257, in iterencode
    return _iterencode(o, 0)
  File "/home/aakash/PROJECTS/LOGIN_AUTHENTICATION/myenv/lib/python3.8/site-packages/rest_framework/utils/encoders.py", line 67, in default
    return super().default(obj)
  File "/usr/lib/python3.8/json/encoder.py", line 179, in default
    raise TypeError(f'Object of type {o.__class__.__name__} '
TypeError: Object of type Register is not JSON serializable
2023-07-25 13:22:41 ERROR "GET /orm_implementation/ HTTP/1.1" 500 106876
2023-07-25 13:22:41 ERROR "GET /orm_implementation/ HTTP/1.1" 500 106876
2023-07-25 13:32:59 ERROR Internal Server Error: /orm_implementation/
Traceback (most recent call last):
  File "/home/aakash/PROJECTS/LOGIN_AUTHENTICATION/myenv/lib/python3.8/site-packages/django/core/handlers/exception.py", line 55, in inner
    response = get_response(request)
  File "/home/aakash/PROJECTS/LOGIN_AUTHENTICATION/myenv/lib/python3.8/site-packages/django/core/handlers/base.py", line 197, in _get_response
    response = wrapped_callback(request, *callback_args, **callback_kwargs)
  File "/home/aakash/PROJECTS/LOGIN_AUTHENTICATION/myenv/lib/python3.8/site-packages/django/views/decorators/csrf.py", line 56, in wrapper_view
    return view_func(*args, **kwargs)
  File "/home/aakash/PROJECTS/LOGIN_AUTHENTICATION/myenv/lib/python3.8/site-packages/django/views/generic/base.py", line 104, in view
    return self.dispatch(request, *args, **kwargs)
  File "/home/aakash/PROJECTS/LOGIN_AUTHENTICATION/myenv/lib/python3.8/site-packages/rest_framework/views.py", line 509, in dispatch
    response = self.handle_exception(exc)
  File "/home/aakash/PROJECTS/LOGIN_AUTHENTICATION/myenv/lib/python3.8/site-packages/rest_framework/views.py", line 469, in handle_exception
    self.raise_uncaught_exception(exc)
  File "/home/aakash/PROJECTS/LOGIN_AUTHENTICATION/myenv/lib/python3.8/site-packages/rest_framework/views.py", line 480, in raise_uncaught_exception
    raise exc
  File "/home/aakash/PROJECTS/LOGIN_AUTHENTICATION/myenv/lib/python3.8/site-packages/rest_framework/views.py", line 506, in dispatch
    response = handler(request, *args, **kwargs)
  File "/home/aakash/PROJECTS/LOGIN_AUTHENTICATION/Authentication_System/myapp/views.py", line 374, in get
    return JsonResponse(
  File "/home/aakash/PROJECTS/LOGIN_AUTHENTICATION/myenv/lib/python3.8/site-packages/django/http/response.py", line 731, in __init__
    data = json.dumps(data, cls=encoder, **json_dumps_params)
  File "/usr/lib/python3.8/json/__init__.py", line 234, in dumps
    return cls(
TypeError: 'int' object is not callable
2023-07-25 13:32:59 ERROR "GET /orm_implementation/ HTTP/1.1" 500 104677
2023-07-25 13:32:59 ERROR "GET /orm_implementation/ HTTP/1.1" 500 104677
2023-07-25 13:37:50 ERROR Internal Server Error: /orm_implementation/
Traceback (most recent call last):
  File "/home/aakash/PROJECTS/LOGIN_AUTHENTICATION/myenv/lib/python3.8/site-packages/django/core/handlers/exception.py", line 55, in inner
    response = get_response(request)
  File "/home/aakash/PROJECTS/LOGIN_AUTHENTICATION/myenv/lib/python3.8/site-packages/django/core/handlers/base.py", line 197, in _get_response
    response = wrapped_callback(request, *callback_args, **callback_kwargs)
  File "/home/aakash/PROJECTS/LOGIN_AUTHENTICATION/myenv/lib/python3.8/site-packages/django/views/decorators/csrf.py", line 56, in wrapper_view
    return view_func(*args, **kwargs)
  File "/home/aakash/PROJECTS/LOGIN_AUTHENTICATION/myenv/lib/python3.8/site-packages/django/views/generic/base.py", line 104, in view
    return self.dispatch(request, *args, **kwargs)
  File "/home/aakash/PROJECTS/LOGIN_AUTHENTICATION/myenv/lib/python3.8/site-packages/rest_framework/views.py", line 509, in dispatch
    response = self.handle_exception(exc)
  File "/home/aakash/PROJECTS/LOGIN_AUTHENTICATION/myenv/lib/python3.8/site-packages/rest_framework/views.py", line 469, in handle_exception
    self.raise_uncaught_exception(exc)
  File "/home/aakash/PROJECTS/LOGIN_AUTHENTICATION/myenv/lib/python3.8/site-packages/rest_framework/views.py", line 480, in raise_uncaught_exception
    raise exc
  File "/home/aakash/PROJECTS/LOGIN_AUTHENTICATION/myenv/lib/python3.8/site-packages/rest_framework/views.py", line 506, in dispatch
    response = handler(request, *args, **kwargs)
  File "/home/aakash/PROJECTS/LOGIN_AUTHENTICATION/Authentication_System/myapp/views.py", line 374, in get
    return JsonResponse(all_registered_users, safe=False)
  File "/home/aakash/PROJECTS/LOGIN_AUTHENTICATION/myenv/lib/python3.8/site-packages/django/http/response.py", line 731, in __init__
    data = json.dumps(data, cls=encoder, **json_dumps_params)
  File "/usr/lib/python3.8/json/__init__.py", line 234, in dumps
    return cls(
  File "/usr/lib/python3.8/json/encoder.py", line 199, in encode
    chunks = self.iterencode(o, _one_shot=True)
  File "/usr/lib/python3.8/json/encoder.py", line 257, in iterencode
    return _iterencode(o, 0)
  File "/home/aakash/PROJECTS/LOGIN_AUTHENTICATION/myenv/lib/python3.8/site-packages/django/core/serializers/json.py", line 106, in default
    return super().default(o)
  File "/usr/lib/python3.8/json/encoder.py", line 179, in default
    raise TypeError(f'Object of type {o.__class__.__name__} '
TypeError: Object of type QuerySet is not JSON serializable
2023-07-25 13:37:50 ERROR "GET /orm_implementation/ HTTP/1.1" 500 122219
2023-07-25 13:37:50 ERROR "GET /orm_implementation/ HTTP/1.1" 500 122219
2023-07-25 13:39:59 ERROR Internal Server Error: /orm_implementation/
Traceback (most recent call last):
  File "/home/aakash/PROJECTS/LOGIN_AUTHENTICATION/myenv/lib/python3.8/site-packages/django/core/handlers/exception.py", line 55, in inner
    response = get_response(request)
  File "/home/aakash/PROJECTS/LOGIN_AUTHENTICATION/myenv/lib/python3.8/site-packages/django/core/handlers/base.py", line 197, in _get_response
    response = wrapped_callback(request, *callback_args, **callback_kwargs)
  File "/home/aakash/PROJECTS/LOGIN_AUTHENTICATION/myenv/lib/python3.8/site-packages/django/views/decorators/csrf.py", line 56, in wrapper_view
    return view_func(*args, **kwargs)
  File "/home/aakash/PROJECTS/LOGIN_AUTHENTICATION/myenv/lib/python3.8/site-packages/django/views/generic/base.py", line 104, in view
    return self.dispatch(request, *args, **kwargs)
  File "/home/aakash/PROJECTS/LOGIN_AUTHENTICATION/myenv/lib/python3.8/site-packages/rest_framework/views.py", line 509, in dispatch
    response = self.handle_exception(exc)
  File "/home/aakash/PROJECTS/LOGIN_AUTHENTICATION/myenv/lib/python3.8/site-packages/rest_framework/views.py", line 469, in handle_exception
    self.raise_uncaught_exception(exc)
  File "/home/aakash/PROJECTS/LOGIN_AUTHENTICATION/myenv/lib/python3.8/site-packages/rest_framework/views.py", line 480, in raise_uncaught_exception
    raise exc
  File "/home/aakash/PROJECTS/LOGIN_AUTHENTICATION/myenv/lib/python3.8/site-packages/rest_framework/views.py", line 506, in dispatch
    response = handler(request, *args, **kwargs)
  File "/home/aakash/PROJECTS/LOGIN_AUTHENTICATION/Authentication_System/myapp/views.py", line 375, in get
    return JsonResponse(data, safe=False)
  File "/home/aakash/PROJECTS/LOGIN_AUTHENTICATION/myenv/lib/python3.8/site-packages/django/http/response.py", line 731, in __init__
    data = json.dumps(data, cls=encoder, **json_dumps_params)
  File "/usr/lib/python3.8/json/__init__.py", line 234, in dumps
    return cls(
  File "/usr/lib/python3.8/json/encoder.py", line 199, in encode
    chunks = self.iterencode(o, _one_shot=True)
  File "/usr/lib/python3.8/json/encoder.py", line 257, in iterencode
    return _iterencode(o, 0)
  File "/home/aakash/PROJECTS/LOGIN_AUTHENTICATION/myenv/lib/python3.8/site-packages/django/core/serializers/json.py", line 106, in default
    return super().default(o)
  File "/usr/lib/python3.8/json/encoder.py", line 179, in default
    raise TypeError(f'Object of type {o.__class__.__name__} '
TypeError: Object of type Register is not JSON serializable
2023-07-25 13:39:59 ERROR "GET /orm_implementation/ HTTP/1.1" 500 122185
2023-07-25 13:39:59 ERROR "GET /orm_implementation/ HTTP/1.1" 500 122185
2023-07-25 13:40:01 ERROR Internal Server Error: /orm_implementation/
Traceback (most recent call last):
  File "/home/aakash/PROJECTS/LOGIN_AUTHENTICATION/myenv/lib/python3.8/site-packages/django/core/handlers/exception.py", line 55, in inner
    response = get_response(request)
  File "/home/aakash/PROJECTS/LOGIN_AUTHENTICATION/myenv/lib/python3.8/site-packages/django/core/handlers/base.py", line 197, in _get_response
    response = wrapped_callback(request, *callback_args, **callback_kwargs)
  File "/home/aakash/PROJECTS/LOGIN_AUTHENTICATION/myenv/lib/python3.8/site-packages/django/views/decorators/csrf.py", line 56, in wrapper_view
    return view_func(*args, **kwargs)
  File "/home/aakash/PROJECTS/LOGIN_AUTHENTICATION/myenv/lib/python3.8/site-packages/django/views/generic/base.py", line 104, in view
    return self.dispatch(request, *args, **kwargs)
  File "/home/aakash/PROJECTS/LOGIN_AUTHENTICATION/myenv/lib/python3.8/site-packages/rest_framework/views.py", line 509, in dispatch
    response = self.handle_exception(exc)
  File "/home/aakash/PROJECTS/LOGIN_AUTHENTICATION/myenv/lib/python3.8/site-packages/rest_framework/views.py", line 469, in handle_exception
    self.raise_uncaught_exception(exc)
  File "/home/aakash/PROJECTS/LOGIN_AUTHENTICATION/myenv/lib/python3.8/site-packages/rest_framework/views.py", line 480, in raise_uncaught_exception
    raise exc
  File "/home/aakash/PROJECTS/LOGIN_AUTHENTICATION/myenv/lib/python3.8/site-packages/rest_framework/views.py", line 506, in dispatch
    response = handler(request, *args, **kwargs)
  File "/home/aakash/PROJECTS/LOGIN_AUTHENTICATION/Authentication_System/myapp/views.py", line 375, in get
    return JsonResponse(data, safe=False)
  File "/home/aakash/PROJECTS/LOGIN_AUTHENTICATION/myenv/lib/python3.8/site-packages/django/http/response.py", line 731, in __init__
    data = json.dumps(data, cls=encoder, **json_dumps_params)
  File "/usr/lib/python3.8/json/__init__.py", line 234, in dumps
    return cls(
  File "/usr/lib/python3.8/json/encoder.py", line 199, in encode
    chunks = self.iterencode(o, _one_shot=True)
  File "/usr/lib/python3.8/json/encoder.py", line 257, in iterencode
    return _iterencode(o, 0)
  File "/home/aakash/PROJECTS/LOGIN_AUTHENTICATION/myenv/lib/python3.8/site-packages/django/core/serializers/json.py", line 106, in default
    return super().default(o)
  File "/usr/lib/python3.8/json/encoder.py", line 179, in default
    raise TypeError(f'Object of type {o.__class__.__name__} '
TypeError: Object of type Register is not JSON serializable
2023-07-25 13:40:01 ERROR "GET /orm_implementation/ HTTP/1.1" 500 122185
2023-07-25 13:40:01 ERROR "GET /orm_implementation/ HTTP/1.1" 500 122185
2023-07-25 13:43:59 ERROR Internal Server Error: /orm_implementation/
Traceback (most recent call last):
  File "/home/aakash/PROJECTS/LOGIN_AUTHENTICATION/myenv/lib/python3.8/site-packages/django/core/handlers/exception.py", line 55, in inner
    response = get_response(request)
  File "/home/aakash/PROJECTS/LOGIN_AUTHENTICATION/myenv/lib/python3.8/site-packages/django/core/handlers/base.py", line 197, in _get_response
    response = wrapped_callback(request, *callback_args, **callback_kwargs)
  File "/home/aakash/PROJECTS/LOGIN_AUTHENTICATION/myenv/lib/python3.8/site-packages/django/views/decorators/csrf.py", line 56, in wrapper_view
    return view_func(*args, **kwargs)
  File "/home/aakash/PROJECTS/LOGIN_AUTHENTICATION/myenv/lib/python3.8/site-packages/django/views/generic/base.py", line 104, in view
    return self.dispatch(request, *args, **kwargs)
  File "/home/aakash/PROJECTS/LOGIN_AUTHENTICATION/myenv/lib/python3.8/site-packages/rest_framework/views.py", line 509, in dispatch
    response = self.handle_exception(exc)
  File "/home/aakash/PROJECTS/LOGIN_AUTHENTICATION/myenv/lib/python3.8/site-packages/rest_framework/views.py", line 469, in handle_exception
    self.raise_uncaught_exception(exc)
  File "/home/aakash/PROJECTS/LOGIN_AUTHENTICATION/myenv/lib/python3.8/site-packages/rest_framework/views.py", line 480, in raise_uncaught_exception
    raise exc
  File "/home/aakash/PROJECTS/LOGIN_AUTHENTICATION/myenv/lib/python3.8/site-packages/rest_framework/views.py", line 506, in dispatch
    response = handler(request, *args, **kwargs)
  File "/home/aakash/PROJECTS/LOGIN_AUTHENTICATION/Authentication_System/myapp/views.py", line 375, in get
    return JsonResponse(data, safe=False)
  File "/home/aakash/PROJECTS/LOGIN_AUTHENTICATION/myenv/lib/python3.8/site-packages/django/http/response.py", line 731, in __init__
    data = json.dumps(data, cls=encoder, **json_dumps_params)
  File "/usr/lib/python3.8/json/__init__.py", line 234, in dumps
    return cls(
  File "/usr/lib/python3.8/json/encoder.py", line 199, in encode
    chunks = self.iterencode(o, _one_shot=True)
  File "/usr/lib/python3.8/json/encoder.py", line 257, in iterencode
    return _iterencode(o, 0)
  File "/home/aakash/PROJECTS/LOGIN_AUTHENTICATION/myenv/lib/python3.8/site-packages/django/core/serializers/json.py", line 106, in default
    return super().default(o)
  File "/usr/lib/python3.8/json/encoder.py", line 179, in default
    raise TypeError(f'Object of type {o.__class__.__name__} '
TypeError: Object of type QuerySet is not JSON serializable
2023-07-25 13:43:59 ERROR "GET /orm_implementation/ HTTP/1.1" 500 122615
2023-07-25 13:43:59 ERROR "GET /orm_implementation/ HTTP/1.1" 500 122615
2023-07-25 13:46:03 ERROR Internal Server Error: /orm_implementation/
Traceback (most recent call last):
  File "/home/aakash/PROJECTS/LOGIN_AUTHENTICATION/myenv/lib/python3.8/site-packages/django/core/handlers/exception.py", line 55, in inner
    response = get_response(request)
  File "/home/aakash/PROJECTS/LOGIN_AUTHENTICATION/myenv/lib/python3.8/site-packages/django/core/handlers/base.py", line 197, in _get_response
    response = wrapped_callback(request, *callback_args, **callback_kwargs)
  File "/home/aakash/PROJECTS/LOGIN_AUTHENTICATION/myenv/lib/python3.8/site-packages/django/views/decorators/csrf.py", line 56, in wrapper_view
    return view_func(*args, **kwargs)
  File "/home/aakash/PROJECTS/LOGIN_AUTHENTICATION/myenv/lib/python3.8/site-packages/django/views/generic/base.py", line 104, in view
    return self.dispatch(request, *args, **kwargs)
  File "/home/aakash/PROJECTS/LOGIN_AUTHENTICATION/myenv/lib/python3.8/site-packages/rest_framework/views.py", line 509, in dispatch
    response = self.handle_exception(exc)
  File "/home/aakash/PROJECTS/LOGIN_AUTHENTICATION/myenv/lib/python3.8/site-packages/rest_framework/views.py", line 469, in handle_exception
    self.raise_uncaught_exception(exc)
  File "/home/aakash/PROJECTS/LOGIN_AUTHENTICATION/myenv/lib/python3.8/site-packages/rest_framework/views.py", line 480, in raise_uncaught_exception
    raise exc
  File "/home/aakash/PROJECTS/LOGIN_AUTHENTICATION/myenv/lib/python3.8/site-packages/rest_framework/views.py", line 506, in dispatch
    response = handler(request, *args, **kwargs)
  File "/home/aakash/PROJECTS/LOGIN_AUTHENTICATION/Authentication_System/myapp/views.py", line 375, in get
    return JsonResponse('list of all registered users', data, safe=False)
  File "/home/aakash/PROJECTS/LOGIN_AUTHENTICATION/myenv/lib/python3.8/site-packages/django/http/response.py", line 731, in __init__
    data = json.dumps(data, cls=encoder, **json_dumps_params)
  File "/usr/lib/python3.8/json/__init__.py", line 234, in dumps
    return cls(
TypeError: 'list' object is not callable
2023-07-25 13:46:03 ERROR "GET /orm_implementation/ HTTP/1.1" 500 104459
2023-07-25 13:46:03 ERROR "GET /orm_implementation/ HTTP/1.1" 500 104459
2023-07-25 13:47:24 ERROR Internal Server Error: /orm_implementation/
Traceback (most recent call last):
  File "/home/aakash/PROJECTS/LOGIN_AUTHENTICATION/myenv/lib/python3.8/site-packages/django/core/handlers/exception.py", line 55, in inner
    response = get_response(request)
  File "/home/aakash/PROJECTS/LOGIN_AUTHENTICATION/myenv/lib/python3.8/site-packages/django/core/handlers/base.py", line 197, in _get_response
    response = wrapped_callback(request, *callback_args, **callback_kwargs)
  File "/home/aakash/PROJECTS/LOGIN_AUTHENTICATION/myenv/lib/python3.8/site-packages/django/views/decorators/csrf.py", line 56, in wrapper_view
    return view_func(*args, **kwargs)
  File "/home/aakash/PROJECTS/LOGIN_AUTHENTICATION/myenv/lib/python3.8/site-packages/django/views/generic/base.py", line 104, in view
    return self.dispatch(request, *args, **kwargs)
  File "/home/aakash/PROJECTS/LOGIN_AUTHENTICATION/myenv/lib/python3.8/site-packages/rest_framework/views.py", line 509, in dispatch
    response = self.handle_exception(exc)
  File "/home/aakash/PROJECTS/LOGIN_AUTHENTICATION/myenv/lib/python3.8/site-packages/rest_framework/views.py", line 469, in handle_exception
    self.raise_uncaught_exception(exc)
  File "/home/aakash/PROJECTS/LOGIN_AUTHENTICATION/myenv/lib/python3.8/site-packages/rest_framework/views.py", line 480, in raise_uncaught_exception
    raise exc
  File "/home/aakash/PROJECTS/LOGIN_AUTHENTICATION/myenv/lib/python3.8/site-packages/rest_framework/views.py", line 506, in dispatch
    response = handler(request, *args, **kwargs)
  File "/home/aakash/PROJECTS/LOGIN_AUTHENTICATION/Authentication_System/myapp/views.py", line 374, in get
    return JsonResponse(
  File "/home/aakash/PROJECTS/LOGIN_AUTHENTICATION/myenv/lib/python3.8/site-packages/django/http/response.py", line 731, in __init__
    data = json.dumps(data, cls=encoder, **json_dumps_params)
  File "/usr/lib/python3.8/json/__init__.py", line 234, in dumps
    return cls(
TypeError: 'int' object is not callable
2023-07-25 13:47:24 ERROR "GET /orm_implementation/ HTTP/1.1" 500 104677
2023-07-25 13:47:24 ERROR "GET /orm_implementation/ HTTP/1.1" 500 104677
2023-07-25 13:53:31 ERROR Internal Server Error: /orm_implementation/
Traceback (most recent call last):
  File "/home/aakash/PROJECTS/LOGIN_AUTHENTICATION/myenv/lib/python3.8/site-packages/django/core/handlers/exception.py", line 55, in inner
    response = get_response(request)
  File "/home/aakash/PROJECTS/LOGIN_AUTHENTICATION/myenv/lib/python3.8/site-packages/django/core/handlers/base.py", line 197, in _get_response
    response = wrapped_callback(request, *callback_args, **callback_kwargs)
  File "/home/aakash/PROJECTS/LOGIN_AUTHENTICATION/myenv/lib/python3.8/site-packages/django/views/decorators/csrf.py", line 56, in wrapper_view
    return view_func(*args, **kwargs)
  File "/home/aakash/PROJECTS/LOGIN_AUTHENTICATION/myenv/lib/python3.8/site-packages/django/views/generic/base.py", line 104, in view
    return self.dispatch(request, *args, **kwargs)
  File "/home/aakash/PROJECTS/LOGIN_AUTHENTICATION/myenv/lib/python3.8/site-packages/rest_framework/views.py", line 509, in dispatch
    response = self.handle_exception(exc)
  File "/home/aakash/PROJECTS/LOGIN_AUTHENTICATION/myenv/lib/python3.8/site-packages/rest_framework/views.py", line 469, in handle_exception
    self.raise_uncaught_exception(exc)
  File "/home/aakash/PROJECTS/LOGIN_AUTHENTICATION/myenv/lib/python3.8/site-packages/rest_framework/views.py", line 480, in raise_uncaught_exception
    raise exc
  File "/home/aakash/PROJECTS/LOGIN_AUTHENTICATION/myenv/lib/python3.8/site-packages/rest_framework/views.py", line 506, in dispatch
    response = handler(request, *args, **kwargs)
  File "/home/aakash/PROJECTS/LOGIN_AUTHENTICATION/Authentication_System/myapp/views.py", line 373, in get
    inactive_users = Register.objects.filter(is_active='False').values_list('email')
  File "/home/aakash/PROJECTS/LOGIN_AUTHENTICATION/myenv/lib/python3.8/site-packages/django/db/models/manager.py", line 87, in manager_method
    return getattr(self.get_queryset(), name)(*args, **kwargs)
  File "/home/aakash/PROJECTS/LOGIN_AUTHENTICATION/myenv/lib/python3.8/site-packages/django/db/models/query.py", line 1436, in filter
    return self._filter_or_exclude(False, args, kwargs)
  File "/home/aakash/PROJECTS/LOGIN_AUTHENTICATION/myenv/lib/python3.8/site-packages/django/db/models/query.py", line 1454, in _filter_or_exclude
    clone._filter_or_exclude_inplace(negate, args, kwargs)
  File "/home/aakash/PROJECTS/LOGIN_AUTHENTICATION/myenv/lib/python3.8/site-packages/django/db/models/query.py", line 1461, in _filter_or_exclude_inplace
    self._query.add_q(Q(*args, **kwargs))
  File "/home/aakash/PROJECTS/LOGIN_AUTHENTICATION/myenv/lib/python3.8/site-packages/django/db/models/sql/query.py", line 1534, in add_q
    clause, _ = self._add_q(q_object, self.used_aliases)
  File "/home/aakash/PROJECTS/LOGIN_AUTHENTICATION/myenv/lib/python3.8/site-packages/django/db/models/sql/query.py", line 1565, in _add_q
    child_clause, needed_inner = self.build_filter(
  File "/home/aakash/PROJECTS/LOGIN_AUTHENTICATION/myenv/lib/python3.8/site-packages/django/db/models/sql/query.py", line 1415, in build_filter
    lookups, parts, reffed_expression = self.solve_lookup_type(arg, summarize)
  File "/home/aakash/PROJECTS/LOGIN_AUTHENTICATION/myenv/lib/python3.8/site-packages/django/db/models/sql/query.py", line 1225, in solve_lookup_type
    _, field, _, lookup_parts = self.names_to_path(lookup_splitted, self.get_meta())
  File "/home/aakash/PROJECTS/LOGIN_AUTHENTICATION/myenv/lib/python3.8/site-packages/django/db/models/sql/query.py", line 1713, in names_to_path
    raise FieldError(
django.core.exceptions.FieldError: Cannot resolve keyword 'is_active' into field. Choices are: OTP, confirm_password, email, first_name, id, last_name, mobile, password, username
2023-07-25 13:53:31 ERROR "GET /orm_implementation/ HTTP/1.1" 500 141024
2023-07-25 13:53:31 ERROR "GET /orm_implementation/ HTTP/1.1" 500 141024
2023-07-25 14:17:58 ERROR Internal Server Error: /orm_implementation/
Traceback (most recent call last):
  File "/home/aakash/PROJECTS/LOGIN_AUTHENTICATION/myenv/lib/python3.8/site-packages/django/core/handlers/exception.py", line 55, in inner
    response = get_response(request)
  File "/home/aakash/PROJECTS/LOGIN_AUTHENTICATION/myenv/lib/python3.8/site-packages/django/core/handlers/base.py", line 197, in _get_response
    response = wrapped_callback(request, *callback_args, **callback_kwargs)
  File "/home/aakash/PROJECTS/LOGIN_AUTHENTICATION/myenv/lib/python3.8/site-packages/django/views/decorators/csrf.py", line 56, in wrapper_view
    return view_func(*args, **kwargs)
  File "/home/aakash/PROJECTS/LOGIN_AUTHENTICATION/myenv/lib/python3.8/site-packages/django/views/generic/base.py", line 104, in view
    return self.dispatch(request, *args, **kwargs)
  File "/home/aakash/PROJECTS/LOGIN_AUTHENTICATION/myenv/lib/python3.8/site-packages/rest_framework/views.py", line 509, in dispatch
    response = self.handle_exception(exc)
  File "/home/aakash/PROJECTS/LOGIN_AUTHENTICATION/myenv/lib/python3.8/site-packages/rest_framework/views.py", line 469, in handle_exception
    self.raise_uncaught_exception(exc)
  File "/home/aakash/PROJECTS/LOGIN_AUTHENTICATION/myenv/lib/python3.8/site-packages/rest_framework/views.py", line 480, in raise_uncaught_exception
    raise exc
  File "/home/aakash/PROJECTS/LOGIN_AUTHENTICATION/myenv/lib/python3.8/site-packages/rest_framework/views.py", line 506, in dispatch
    response = handler(request, *args, **kwargs)
  File "/home/aakash/PROJECTS/LOGIN_AUTHENTICATION/Authentication_System/myapp/views.py", line 374, in get
    return JsonResponse(
  File "/home/aakash/PROJECTS/LOGIN_AUTHENTICATION/myenv/lib/python3.8/site-packages/django/http/response.py", line 731, in __init__
    data = json.dumps(data, cls=encoder, **json_dumps_params)
  File "/usr/lib/python3.8/json/__init__.py", line 234, in dumps
    return cls(
  File "/usr/lib/python3.8/json/encoder.py", line 199, in encode
    chunks = self.iterencode(o, _one_shot=True)
  File "/usr/lib/python3.8/json/encoder.py", line 257, in iterencode
    return _iterencode(o, 0)
  File "/home/aakash/PROJECTS/LOGIN_AUTHENTICATION/myenv/lib/python3.8/site-packages/django/core/serializers/json.py", line 106, in default
    return super().default(o)
  File "/usr/lib/python3.8/json/encoder.py", line 179, in default
    raise TypeError(f'Object of type {o.__class__.__name__} '
TypeError: Object of type QuerySet is not JSON serializable
2023-07-25 14:17:58 ERROR "GET /orm_implementation/ HTTP/1.1" 500 125281
2023-07-25 14:17:58 ERROR "GET /orm_implementation/ HTTP/1.1" 500 125281
2023-07-25 14:35:19 ERROR Internal Server Error: /orm_implementation/
Traceback (most recent call last):
  File "/home/aakash/PROJECTS/LOGIN_AUTHENTICATION/myenv/lib/python3.8/site-packages/django/core/handlers/exception.py", line 55, in inner
    response = get_response(request)
  File "/home/aakash/PROJECTS/LOGIN_AUTHENTICATION/myenv/lib/python3.8/site-packages/django/core/handlers/base.py", line 197, in _get_response
    response = wrapped_callback(request, *callback_args, **callback_kwargs)
  File "/home/aakash/PROJECTS/LOGIN_AUTHENTICATION/myenv/lib/python3.8/site-packages/django/views/decorators/csrf.py", line 56, in wrapper_view
    return view_func(*args, **kwargs)
  File "/home/aakash/PROJECTS/LOGIN_AUTHENTICATION/myenv/lib/python3.8/site-packages/django/views/generic/base.py", line 104, in view
    return self.dispatch(request, *args, **kwargs)
  File "/home/aakash/PROJECTS/LOGIN_AUTHENTICATION/myenv/lib/python3.8/site-packages/rest_framework/views.py", line 509, in dispatch
    response = self.handle_exception(exc)
  File "/home/aakash/PROJECTS/LOGIN_AUTHENTICATION/myenv/lib/python3.8/site-packages/rest_framework/views.py", line 469, in handle_exception
    self.raise_uncaught_exception(exc)
  File "/home/aakash/PROJECTS/LOGIN_AUTHENTICATION/myenv/lib/python3.8/site-packages/rest_framework/views.py", line 480, in raise_uncaught_exception
    raise exc
  File "/home/aakash/PROJECTS/LOGIN_AUTHENTICATION/myenv/lib/python3.8/site-packages/rest_framework/views.py", line 506, in dispatch
    response = handler(request, *args, **kwargs)
  File "/home/aakash/PROJECTS/LOGIN_AUTHENTICATION/Authentication_System/myapp/views.py", line 388, in get
    'first_user': list(first_user),
TypeError: 'Register' object is not iterable
2023-07-25 14:35:19 ERROR "GET /orm_implementation/ HTTP/1.1" 500 94903
2023-07-25 14:35:19 ERROR "GET /orm_implementation/ HTTP/1.1" 500 94903
2023-07-25 14:36:43 ERROR Internal Server Error: /orm_implementation/
Traceback (most recent call last):
  File "/home/aakash/PROJECTS/LOGIN_AUTHENTICATION/myenv/lib/python3.8/site-packages/django/core/handlers/exception.py", line 55, in inner
    response = get_response(request)
  File "/home/aakash/PROJECTS/LOGIN_AUTHENTICATION/myenv/lib/python3.8/site-packages/django/core/handlers/base.py", line 197, in _get_response
    response = wrapped_callback(request, *callback_args, **callback_kwargs)
  File "/home/aakash/PROJECTS/LOGIN_AUTHENTICATION/myenv/lib/python3.8/site-packages/django/views/decorators/csrf.py", line 56, in wrapper_view
    return view_func(*args, **kwargs)
  File "/home/aakash/PROJECTS/LOGIN_AUTHENTICATION/myenv/lib/python3.8/site-packages/django/views/generic/base.py", line 104, in view
    return self.dispatch(request, *args, **kwargs)
  File "/home/aakash/PROJECTS/LOGIN_AUTHENTICATION/myenv/lib/python3.8/site-packages/rest_framework/views.py", line 509, in dispatch
    response = self.handle_exception(exc)
  File "/home/aakash/PROJECTS/LOGIN_AUTHENTICATION/myenv/lib/python3.8/site-packages/rest_framework/views.py", line 469, in handle_exception
    self.raise_uncaught_exception(exc)
  File "/home/aakash/PROJECTS/LOGIN_AUTHENTICATION/myenv/lib/python3.8/site-packages/rest_framework/views.py", line 480, in raise_uncaught_exception
    raise exc
  File "/home/aakash/PROJECTS/LOGIN_AUTHENTICATION/myenv/lib/python3.8/site-packages/rest_framework/views.py", line 506, in dispatch
    response = handler(request, *args, **kwargs)
  File "/home/aakash/PROJECTS/LOGIN_AUTHENTICATION/Authentication_System/myapp/views.py", line 388, in get
    'first_user': list(first_user.values()),
AttributeError: 'Register' object has no attribute 'values'
2023-07-25 14:36:43 ERROR "GET /orm_implementation/ HTTP/1.1" 500 95090
2023-07-25 14:36:43 ERROR "GET /orm_implementation/ HTTP/1.1" 500 95090
2023-07-25 14:37:20 ERROR Internal Server Error: /orm_implementation/
Traceback (most recent call last):
  File "/home/aakash/PROJECTS/LOGIN_AUTHENTICATION/myenv/lib/python3.8/site-packages/django/core/handlers/exception.py", line 55, in inner
    response = get_response(request)
  File "/home/aakash/PROJECTS/LOGIN_AUTHENTICATION/myenv/lib/python3.8/site-packages/django/core/handlers/base.py", line 197, in _get_response
    response = wrapped_callback(request, *callback_args, **callback_kwargs)
  File "/home/aakash/PROJECTS/LOGIN_AUTHENTICATION/myenv/lib/python3.8/site-packages/django/views/decorators/csrf.py", line 56, in wrapper_view
    return view_func(*args, **kwargs)
  File "/home/aakash/PROJECTS/LOGIN_AUTHENTICATION/myenv/lib/python3.8/site-packages/django/views/generic/base.py", line 104, in view
    return self.dispatch(request, *args, **kwargs)
  File "/home/aakash/PROJECTS/LOGIN_AUTHENTICATION/myenv/lib/python3.8/site-packages/rest_framework/views.py", line 509, in dispatch
    response = self.handle_exception(exc)
  File "/home/aakash/PROJECTS/LOGIN_AUTHENTICATION/myenv/lib/python3.8/site-packages/rest_framework/views.py", line 469, in handle_exception
    self.raise_uncaught_exception(exc)
  File "/home/aakash/PROJECTS/LOGIN_AUTHENTICATION/myenv/lib/python3.8/site-packages/rest_framework/views.py", line 480, in raise_uncaught_exception
    raise exc
  File "/home/aakash/PROJECTS/LOGIN_AUTHENTICATION/myenv/lib/python3.8/site-packages/rest_framework/views.py", line 506, in dispatch
    response = handler(request, *args, **kwargs)
  File "/home/aakash/PROJECTS/LOGIN_AUTHENTICATION/Authentication_System/myapp/views.py", line 388, in get
    'first_user': list(first_user.values_list('email')),
AttributeError: 'Register' object has no attribute 'values_list'
2023-07-25 14:37:20 ERROR "GET /orm_implementation/ HTTP/1.1" 500 95164
2023-07-25 14:37:20 ERROR "GET /orm_implementation/ HTTP/1.1" 500 95164
2023-07-25 14:38:29 ERROR Internal Server Error: /orm_implementation/
Traceback (most recent call last):
  File "/home/aakash/PROJECTS/LOGIN_AUTHENTICATION/myenv/lib/python3.8/site-packages/django/core/handlers/exception.py", line 55, in inner
    response = get_response(request)
  File "/home/aakash/PROJECTS/LOGIN_AUTHENTICATION/myenv/lib/python3.8/site-packages/django/core/handlers/base.py", line 197, in _get_response
    response = wrapped_callback(request, *callback_args, **callback_kwargs)
  File "/home/aakash/PROJECTS/LOGIN_AUTHENTICATION/myenv/lib/python3.8/site-packages/django/views/decorators/csrf.py", line 56, in wrapper_view
    return view_func(*args, **kwargs)
  File "/home/aakash/PROJECTS/LOGIN_AUTHENTICATION/myenv/lib/python3.8/site-packages/django/views/generic/base.py", line 104, in view
    return self.dispatch(request, *args, **kwargs)
  File "/home/aakash/PROJECTS/LOGIN_AUTHENTICATION/myenv/lib/python3.8/site-packages/rest_framework/views.py", line 509, in dispatch
    response = self.handle_exception(exc)
  File "/home/aakash/PROJECTS/LOGIN_AUTHENTICATION/myenv/lib/python3.8/site-packages/rest_framework/views.py", line 469, in handle_exception
    self.raise_uncaught_exception(exc)
  File "/home/aakash/PROJECTS/LOGIN_AUTHENTICATION/myenv/lib/python3.8/site-packages/rest_framework/views.py", line 480, in raise_uncaught_exception
    raise exc
  File "/home/aakash/PROJECTS/LOGIN_AUTHENTICATION/myenv/lib/python3.8/site-packages/rest_framework/views.py", line 506, in dispatch
    response = handler(request, *args, **kwargs)
  File "/home/aakash/PROJECTS/LOGIN_AUTHENTICATION/Authentication_System/myapp/views.py", line 389, in get
    'last_user': list(last_user.values())
AttributeError: 'Register' object has no attribute 'values'
2023-07-25 14:38:29 ERROR "GET /orm_implementation/ HTTP/1.1" 500 94933
2023-07-25 14:38:29 ERROR "GET /orm_implementation/ HTTP/1.1" 500 94933
2023-07-25 14:43:09 ERROR Internal Server Error: /orm_implementation/
Traceback (most recent call last):
  File "/home/aakash/PROJECTS/LOGIN_AUTHENTICATION/myenv/lib/python3.8/site-packages/django/core/handlers/exception.py", line 55, in inner
    response = get_response(request)
  File "/home/aakash/PROJECTS/LOGIN_AUTHENTICATION/myenv/lib/python3.8/site-packages/django/core/handlers/base.py", line 197, in _get_response
    response = wrapped_callback(request, *callback_args, **callback_kwargs)
  File "/home/aakash/PROJECTS/LOGIN_AUTHENTICATION/myenv/lib/python3.8/site-packages/django/views/decorators/csrf.py", line 56, in wrapper_view
    return view_func(*args, **kwargs)
  File "/home/aakash/PROJECTS/LOGIN_AUTHENTICATION/myenv/lib/python3.8/site-packages/django/views/generic/base.py", line 104, in view
    return self.dispatch(request, *args, **kwargs)
  File "/home/aakash/PROJECTS/LOGIN_AUTHENTICATION/myenv/lib/python3.8/site-packages/rest_framework/views.py", line 509, in dispatch
    response = self.handle_exception(exc)
  File "/home/aakash/PROJECTS/LOGIN_AUTHENTICATION/myenv/lib/python3.8/site-packages/rest_framework/views.py", line 469, in handle_exception
    self.raise_uncaught_exception(exc)
  File "/home/aakash/PROJECTS/LOGIN_AUTHENTICATION/myenv/lib/python3.8/site-packages/rest_framework/views.py", line 480, in raise_uncaught_exception
    raise exc
  File "/home/aakash/PROJECTS/LOGIN_AUTHENTICATION/myenv/lib/python3.8/site-packages/rest_framework/views.py", line 506, in dispatch
    response = handler(request, *args, **kwargs)
  File "/home/aakash/PROJECTS/LOGIN_AUTHENTICATION/Authentication_System/myapp/views.py", line 388, in get
    'first_user': list(first_user.values('email')),
AttributeError: 'Register' object has no attribute 'values'
2023-07-25 14:43:09 ERROR "GET /orm_implementation/ HTTP/1.1" 500 95156
2023-07-25 14:43:09 ERROR "GET /orm_implementation/ HTTP/1.1" 500 95156
2023-07-25 14:45:49 ERROR Internal Server Error: /orm_implementation/
Traceback (most recent call last):
  File "/home/aakash/PROJECTS/LOGIN_AUTHENTICATION/myenv/lib/python3.8/site-packages/django/core/handlers/exception.py", line 55, in inner
    response = get_response(request)
  File "/home/aakash/PROJECTS/LOGIN_AUTHENTICATION/myenv/lib/python3.8/site-packages/django/core/handlers/base.py", line 197, in _get_response
    response = wrapped_callback(request, *callback_args, **callback_kwargs)
  File "/home/aakash/PROJECTS/LOGIN_AUTHENTICATION/myenv/lib/python3.8/site-packages/django/views/decorators/csrf.py", line 56, in wrapper_view
    return view_func(*args, **kwargs)
  File "/home/aakash/PROJECTS/LOGIN_AUTHENTICATION/myenv/lib/python3.8/site-packages/django/views/generic/base.py", line 104, in view
    return self.dispatch(request, *args, **kwargs)
  File "/home/aakash/PROJECTS/LOGIN_AUTHENTICATION/myenv/lib/python3.8/site-packages/rest_framework/views.py", line 509, in dispatch
    response = self.handle_exception(exc)
  File "/home/aakash/PROJECTS/LOGIN_AUTHENTICATION/myenv/lib/python3.8/site-packages/rest_framework/views.py", line 469, in handle_exception
    self.raise_uncaught_exception(exc)
  File "/home/aakash/PROJECTS/LOGIN_AUTHENTICATION/myenv/lib/python3.8/site-packages/rest_framework/views.py", line 480, in raise_uncaught_exception
    raise exc
  File "/home/aakash/PROJECTS/LOGIN_AUTHENTICATION/myenv/lib/python3.8/site-packages/rest_framework/views.py", line 506, in dispatch
    response = handler(request, *args, **kwargs)
  File "/home/aakash/PROJECTS/LOGIN_AUTHENTICATION/Authentication_System/myapp/views.py", line 389, in get
    'first_user': list(first_user.values()),
AttributeError: 'tuple' object has no attribute 'values'
2023-07-25 14:45:49 ERROR "GET /orm_implementation/ HTTP/1.1" 500 95110
2023-07-25 14:45:49 ERROR "GET /orm_implementation/ HTTP/1.1" 500 95110
2023-07-25 14:52:45 ERROR Internal Server Error: /orm_implementation/
Traceback (most recent call last):
  File "/home/aakash/PROJECTS/LOGIN_AUTHENTICATION/myenv/lib/python3.8/site-packages/django/core/handlers/exception.py", line 55, in inner
    response = get_response(request)
  File "/home/aakash/PROJECTS/LOGIN_AUTHENTICATION/myenv/lib/python3.8/site-packages/django/core/handlers/base.py", line 197, in _get_response
    response = wrapped_callback(request, *callback_args, **callback_kwargs)
  File "/home/aakash/PROJECTS/LOGIN_AUTHENTICATION/myenv/lib/python3.8/site-packages/django/views/decorators/csrf.py", line 56, in wrapper_view
    return view_func(*args, **kwargs)
  File "/home/aakash/PROJECTS/LOGIN_AUTHENTICATION/myenv/lib/python3.8/site-packages/django/views/generic/base.py", line 104, in view
    return self.dispatch(request, *args, **kwargs)
  File "/home/aakash/PROJECTS/LOGIN_AUTHENTICATION/myenv/lib/python3.8/site-packages/rest_framework/views.py", line 509, in dispatch
    response = self.handle_exception(exc)
  File "/home/aakash/PROJECTS/LOGIN_AUTHENTICATION/myenv/lib/python3.8/site-packages/rest_framework/views.py", line 469, in handle_exception
    self.raise_uncaught_exception(exc)
  File "/home/aakash/PROJECTS/LOGIN_AUTHENTICATION/myenv/lib/python3.8/site-packages/rest_framework/views.py", line 480, in raise_uncaught_exception
    raise exc
  File "/home/aakash/PROJECTS/LOGIN_AUTHENTICATION/myenv/lib/python3.8/site-packages/rest_framework/views.py", line 506, in dispatch
    response = handler(request, *args, **kwargs)
  File "/home/aakash/PROJECTS/LOGIN_AUTHENTICATION/Authentication_System/myapp/views.py", line 388, in get
    last_five_users = Register.objects.all().values_list('email')[-1:-6]
  File "/home/aakash/PROJECTS/LOGIN_AUTHENTICATION/myenv/lib/python3.8/site-packages/django/db/models/query.py", line 429, in __getitem__
    raise ValueError("Negative indexing is not supported.")
ValueError: Negative indexing is not supported.
2023-07-25 14:52:45 ERROR "GET /orm_implementation/ HTTP/1.1" 500 99962
2023-07-25 14:52:45 ERROR "GET /orm_implementation/ HTTP/1.1" 500 99962
2023-07-25 16:45:53 ERROR invalid serializer data
2023-07-25 17:32:18 ERROR invalid serializer data
2023-07-25 17:39:13 ERROR invalid serializer data
2023-07-25 18:09:24 ERROR invalid serializer data
2023-07-25 18:46:04 ERROR invalid serializer data
2023-07-25 18:51:06 ERROR Internal Server Error: /orm_implementation/
Traceback (most recent call last):
  File "/home/aakash/PROJECTS/LOGIN_AUTHENTICATION/myenv/lib/python3.8/site-packages/django/core/handlers/exception.py", line 55, in inner
    response = get_response(request)
  File "/home/aakash/PROJECTS/LOGIN_AUTHENTICATION/myenv/lib/python3.8/site-packages/django/core/handlers/base.py", line 197, in _get_response
    response = wrapped_callback(request, *callback_args, **callback_kwargs)
  File "/home/aakash/PROJECTS/LOGIN_AUTHENTICATION/myenv/lib/python3.8/site-packages/django/views/decorators/csrf.py", line 56, in wrapper_view
    return view_func(*args, **kwargs)
  File "/home/aakash/PROJECTS/LOGIN_AUTHENTICATION/myenv/lib/python3.8/site-packages/django/views/generic/base.py", line 104, in view
    return self.dispatch(request, *args, **kwargs)
  File "/home/aakash/PROJECTS/LOGIN_AUTHENTICATION/myenv/lib/python3.8/site-packages/rest_framework/views.py", line 509, in dispatch
    response = self.handle_exception(exc)
  File "/home/aakash/PROJECTS/LOGIN_AUTHENTICATION/myenv/lib/python3.8/site-packages/rest_framework/views.py", line 469, in handle_exception
    self.raise_uncaught_exception(exc)
  File "/home/aakash/PROJECTS/LOGIN_AUTHENTICATION/myenv/lib/python3.8/site-packages/rest_framework/views.py", line 480, in raise_uncaught_exception
    raise exc
  File "/home/aakash/PROJECTS/LOGIN_AUTHENTICATION/myenv/lib/python3.8/site-packages/rest_framework/views.py", line 506, in dispatch
    response = handler(request, *args, **kwargs)
  File "/home/aakash/PROJECTS/LOGIN_AUTHENTICATION/Authentication_System/myapp/views.py", line 421, in get
    return JsonResponse(
  File "/home/aakash/PROJECTS/LOGIN_AUTHENTICATION/myenv/lib/python3.8/site-packages/django/http/response.py", line 731, in __init__
    data = json.dumps(data, cls=encoder, **json_dumps_params)
  File "/usr/lib/python3.8/json/__init__.py", line 234, in dumps
    return cls(
  File "/usr/lib/python3.8/json/encoder.py", line 199, in encode
    chunks = self.iterencode(o, _one_shot=True)
  File "/usr/lib/python3.8/json/encoder.py", line 257, in iterencode
    return _iterencode(o, 0)
  File "/home/aakash/PROJECTS/LOGIN_AUTHENTICATION/myenv/lib/python3.8/site-packages/django/core/serializers/json.py", line 106, in default
    return super().default(o)
  File "/usr/lib/python3.8/json/encoder.py", line 179, in default
    raise TypeError(f'Object of type {o.__class__.__name__} '
TypeError: Object of type coroutine is not JSON serializable
2023-07-25 18:51:06 ERROR "GET /orm_implementation/ HTTP/1.1" 500 149812
2023-07-25 18:51:06 ERROR "GET /orm_implementation/ HTTP/1.1" 500 149812
2023-07-25 18:51:55 ERROR Internal Server Error: /orm_implementation/
Traceback (most recent call last):
  File "/home/aakash/PROJECTS/LOGIN_AUTHENTICATION/myenv/lib/python3.8/site-packages/django/core/handlers/exception.py", line 55, in inner
    response = get_response(request)
  File "/home/aakash/PROJECTS/LOGIN_AUTHENTICATION/myenv/lib/python3.8/site-packages/django/core/handlers/base.py", line 197, in _get_response
    response = wrapped_callback(request, *callback_args, **callback_kwargs)
  File "/home/aakash/PROJECTS/LOGIN_AUTHENTICATION/myenv/lib/python3.8/site-packages/django/views/decorators/csrf.py", line 56, in wrapper_view
    return view_func(*args, **kwargs)
  File "/home/aakash/PROJECTS/LOGIN_AUTHENTICATION/myenv/lib/python3.8/site-packages/django/views/generic/base.py", line 104, in view
    return self.dispatch(request, *args, **kwargs)
  File "/home/aakash/PROJECTS/LOGIN_AUTHENTICATION/myenv/lib/python3.8/site-packages/rest_framework/views.py", line 509, in dispatch
    response = self.handle_exception(exc)
  File "/home/aakash/PROJECTS/LOGIN_AUTHENTICATION/myenv/lib/python3.8/site-packages/rest_framework/views.py", line 469, in handle_exception
    self.raise_uncaught_exception(exc)
  File "/home/aakash/PROJECTS/LOGIN_AUTHENTICATION/myenv/lib/python3.8/site-packages/rest_framework/views.py", line 480, in raise_uncaught_exception
    raise exc
  File "/home/aakash/PROJECTS/LOGIN_AUTHENTICATION/myenv/lib/python3.8/site-packages/rest_framework/views.py", line 506, in dispatch
    response = handler(request, *args, **kwargs)
  File "/home/aakash/PROJECTS/LOGIN_AUTHENTICATION/Authentication_System/myapp/views.py", line 418, in get
    minimum_id = Register.objects.aaggregate(min('id')).values_list('email')
AttributeError: 'coroutine' object has no attribute 'values_list'
2023-07-25 18:51:55 ERROR "GET /orm_implementation/ HTTP/1.1" 500 99980
2023-07-25 18:51:55 ERROR "GET /orm_implementation/ HTTP/1.1" 500 99980
2023-07-25 18:52:23 ERROR Internal Server Error: /orm_implementation/
Traceback (most recent call last):
  File "/home/aakash/PROJECTS/LOGIN_AUTHENTICATION/myenv/lib/python3.8/site-packages/django/core/handlers/exception.py", line 55, in inner
    response = get_response(request)
  File "/home/aakash/PROJECTS/LOGIN_AUTHENTICATION/myenv/lib/python3.8/site-packages/django/core/handlers/base.py", line 197, in _get_response
    response = wrapped_callback(request, *callback_args, **callback_kwargs)
  File "/home/aakash/PROJECTS/LOGIN_AUTHENTICATION/myenv/lib/python3.8/site-packages/django/views/decorators/csrf.py", line 56, in wrapper_view
    return view_func(*args, **kwargs)
  File "/home/aakash/PROJECTS/LOGIN_AUTHENTICATION/myenv/lib/python3.8/site-packages/django/views/generic/base.py", line 104, in view
    return self.dispatch(request, *args, **kwargs)
  File "/home/aakash/PROJECTS/LOGIN_AUTHENTICATION/myenv/lib/python3.8/site-packages/rest_framework/views.py", line 509, in dispatch
    response = self.handle_exception(exc)
  File "/home/aakash/PROJECTS/LOGIN_AUTHENTICATION/myenv/lib/python3.8/site-packages/rest_framework/views.py", line 469, in handle_exception
    self.raise_uncaught_exception(exc)
  File "/home/aakash/PROJECTS/LOGIN_AUTHENTICATION/myenv/lib/python3.8/site-packages/rest_framework/views.py", line 480, in raise_uncaught_exception
    raise exc
  File "/home/aakash/PROJECTS/LOGIN_AUTHENTICATION/myenv/lib/python3.8/site-packages/rest_framework/views.py", line 506, in dispatch
    response = handler(request, *args, **kwargs)
  File "/home/aakash/PROJECTS/LOGIN_AUTHENTICATION/Authentication_System/myapp/views.py", line 418, in get
    minimum_id = Register.objects.aggregate(min('id')).values_list('email')
  File "/home/aakash/PROJECTS/LOGIN_AUTHENTICATION/myenv/lib/python3.8/site-packages/django/db/models/manager.py", line 87, in manager_method
    return getattr(self.get_queryset(), name)(*args, **kwargs)
  File "/home/aakash/PROJECTS/LOGIN_AUTHENTICATION/myenv/lib/python3.8/site-packages/django/db/models/query.py", line 579, in aggregate
    self._validate_values_are_expressions(
  File "/home/aakash/PROJECTS/LOGIN_AUTHENTICATION/myenv/lib/python3.8/site-packages/django/db/models/query.py", line 1950, in _validate_values_are_expressions
    raise TypeError(
TypeError: QuerySet.aggregate() received non-expression(s): d.
2023-07-25 18:52:23 ERROR "GET /orm_implementation/ HTTP/1.1" 500 112775
2023-07-25 18:52:23 ERROR "GET /orm_implementation/ HTTP/1.1" 500 112775
2023-07-25 18:52:55 ERROR Internal Server Error: /orm_implementation/
Traceback (most recent call last):
  File "/home/aakash/PROJECTS/LOGIN_AUTHENTICATION/myenv/lib/python3.8/site-packages/django/core/handlers/exception.py", line 55, in inner
    response = get_response(request)
  File "/home/aakash/PROJECTS/LOGIN_AUTHENTICATION/myenv/lib/python3.8/site-packages/django/core/handlers/base.py", line 197, in _get_response
    response = wrapped_callback(request, *callback_args, **callback_kwargs)
  File "/home/aakash/PROJECTS/LOGIN_AUTHENTICATION/myenv/lib/python3.8/site-packages/django/views/decorators/csrf.py", line 56, in wrapper_view
    return view_func(*args, **kwargs)
  File "/home/aakash/PROJECTS/LOGIN_AUTHENTICATION/myenv/lib/python3.8/site-packages/django/views/generic/base.py", line 104, in view
    return self.dispatch(request, *args, **kwargs)
  File "/home/aakash/PROJECTS/LOGIN_AUTHENTICATION/myenv/lib/python3.8/site-packages/rest_framework/views.py", line 509, in dispatch
    response = self.handle_exception(exc)
  File "/home/aakash/PROJECTS/LOGIN_AUTHENTICATION/myenv/lib/python3.8/site-packages/rest_framework/views.py", line 469, in handle_exception
    self.raise_uncaught_exception(exc)
  File "/home/aakash/PROJECTS/LOGIN_AUTHENTICATION/myenv/lib/python3.8/site-packages/rest_framework/views.py", line 480, in raise_uncaught_exception
    raise exc
  File "/home/aakash/PROJECTS/LOGIN_AUTHENTICATION/myenv/lib/python3.8/site-packages/rest_framework/views.py", line 506, in dispatch
    response = handler(request, *args, **kwargs)
  File "/home/aakash/PROJECTS/LOGIN_AUTHENTICATION/Authentication_System/myapp/views.py", line 418, in get
    minimum_id = Register.objects.aggregate(min('id'))
  File "/home/aakash/PROJECTS/LOGIN_AUTHENTICATION/myenv/lib/python3.8/site-packages/django/db/models/manager.py", line 87, in manager_method
    return getattr(self.get_queryset(), name)(*args, **kwargs)
  File "/home/aakash/PROJECTS/LOGIN_AUTHENTICATION/myenv/lib/python3.8/site-packages/django/db/models/query.py", line 579, in aggregate
    self._validate_values_are_expressions(
  File "/home/aakash/PROJECTS/LOGIN_AUTHENTICATION/myenv/lib/python3.8/site-packages/django/db/models/query.py", line 1950, in _validate_values_are_expressions
    raise TypeError(
TypeError: QuerySet.aggregate() received non-expression(s): d.
2023-07-25 18:52:55 ERROR "GET /orm_implementation/ HTTP/1.1" 500 112713
2023-07-25 18:52:55 ERROR "GET /orm_implementation/ HTTP/1.1" 500 112713
2023-07-25 18:56:21 ERROR Internal Server Error: /orm_implementation/
Traceback (most recent call last):
  File "/home/aakash/PROJECTS/LOGIN_AUTHENTICATION/myenv/lib/python3.8/site-packages/django/core/handlers/exception.py", line 55, in inner
    response = get_response(request)
  File "/home/aakash/PROJECTS/LOGIN_AUTHENTICATION/myenv/lib/python3.8/site-packages/django/core/handlers/base.py", line 197, in _get_response
    response = wrapped_callback(request, *callback_args, **callback_kwargs)
  File "/home/aakash/PROJECTS/LOGIN_AUTHENTICATION/myenv/lib/python3.8/site-packages/django/views/decorators/csrf.py", line 56, in wrapper_view
    return view_func(*args, **kwargs)
  File "/home/aakash/PROJECTS/LOGIN_AUTHENTICATION/myenv/lib/python3.8/site-packages/django/views/generic/base.py", line 104, in view
    return self.dispatch(request, *args, **kwargs)
  File "/home/aakash/PROJECTS/LOGIN_AUTHENTICATION/myenv/lib/python3.8/site-packages/rest_framework/views.py", line 509, in dispatch
    response = self.handle_exception(exc)
  File "/home/aakash/PROJECTS/LOGIN_AUTHENTICATION/myenv/lib/python3.8/site-packages/rest_framework/views.py", line 469, in handle_exception
    self.raise_uncaught_exception(exc)
  File "/home/aakash/PROJECTS/LOGIN_AUTHENTICATION/myenv/lib/python3.8/site-packages/rest_framework/views.py", line 480, in raise_uncaught_exception
    raise exc
  File "/home/aakash/PROJECTS/LOGIN_AUTHENTICATION/myenv/lib/python3.8/site-packages/rest_framework/views.py", line 506, in dispatch
    response = handler(request, *args, **kwargs)
  File "/home/aakash/PROJECTS/LOGIN_AUTHENTICATION/Authentication_System/myapp/views.py", line 418, in get
    minimum_id = Register.objects.all().aggregate(min('id'))
  File "/home/aakash/PROJECTS/LOGIN_AUTHENTICATION/myenv/lib/python3.8/site-packages/django/db/models/query.py", line 579, in aggregate
    self._validate_values_are_expressions(
  File "/home/aakash/PROJECTS/LOGIN_AUTHENTICATION/myenv/lib/python3.8/site-packages/django/db/models/query.py", line 1950, in _validate_values_are_expressions
    raise TypeError(
TypeError: QuerySet.aggregate() received non-expression(s): d.
2023-07-25 18:56:21 ERROR "GET /orm_implementation/ HTTP/1.1" 500 108533
2023-07-25 18:56:21 ERROR "GET /orm_implementation/ HTTP/1.1" 500 108533
2023-07-25 18:58:12 ERROR Internal Server Error: /orm_implementation/
Traceback (most recent call last):
  File "/home/aakash/PROJECTS/LOGIN_AUTHENTICATION/myenv/lib/python3.8/site-packages/django/core/handlers/exception.py", line 55, in inner
    response = get_response(request)
  File "/home/aakash/PROJECTS/LOGIN_AUTHENTICATION/myenv/lib/python3.8/site-packages/django/core/handlers/base.py", line 197, in _get_response
    response = wrapped_callback(request, *callback_args, **callback_kwargs)
  File "/home/aakash/PROJECTS/LOGIN_AUTHENTICATION/myenv/lib/python3.8/site-packages/django/views/decorators/csrf.py", line 56, in wrapper_view
    return view_func(*args, **kwargs)
  File "/home/aakash/PROJECTS/LOGIN_AUTHENTICATION/myenv/lib/python3.8/site-packages/django/views/generic/base.py", line 104, in view
    return self.dispatch(request, *args, **kwargs)
  File "/home/aakash/PROJECTS/LOGIN_AUTHENTICATION/myenv/lib/python3.8/site-packages/rest_framework/views.py", line 509, in dispatch
    response = self.handle_exception(exc)
  File "/home/aakash/PROJECTS/LOGIN_AUTHENTICATION/myenv/lib/python3.8/site-packages/rest_framework/views.py", line 469, in handle_exception
    self.raise_uncaught_exception(exc)
  File "/home/aakash/PROJECTS/LOGIN_AUTHENTICATION/myenv/lib/python3.8/site-packages/rest_framework/views.py", line 480, in raise_uncaught_exception
    raise exc
  File "/home/aakash/PROJECTS/LOGIN_AUTHENTICATION/myenv/lib/python3.8/site-packages/rest_framework/views.py", line 506, in dispatch
    response = handler(request, *args, **kwargs)
  File "/home/aakash/PROJECTS/LOGIN_AUTHENTICATION/Authentication_System/myapp/views.py", line 418, in get
    minimum_id = Register.objects.all().aggregate(min('id'))
  File "/home/aakash/PROJECTS/LOGIN_AUTHENTICATION/myenv/lib/python3.8/site-packages/django/db/models/query.py", line 579, in aggregate
    self._validate_values_are_expressions(
  File "/home/aakash/PROJECTS/LOGIN_AUTHENTICATION/myenv/lib/python3.8/site-packages/django/db/models/query.py", line 1950, in _validate_values_are_expressions
    raise TypeError(
TypeError: QuerySet.aggregate() received non-expression(s): d.
2023-07-25 18:58:12 ERROR "GET /orm_implementation/ HTTP/1.1" 500 108533
2023-07-25 18:58:12 ERROR "GET /orm_implementation/ HTTP/1.1" 500 108533
2023-07-25 18:59:51 ERROR Internal Server Error: /orm_implementation/
Traceback (most recent call last):
  File "/home/aakash/PROJECTS/LOGIN_AUTHENTICATION/myenv/lib/python3.8/site-packages/django/core/handlers/exception.py", line 55, in inner
    response = get_response(request)
  File "/home/aakash/PROJECTS/LOGIN_AUTHENTICATION/myenv/lib/python3.8/site-packages/django/core/handlers/base.py", line 197, in _get_response
    response = wrapped_callback(request, *callback_args, **callback_kwargs)
  File "/home/aakash/PROJECTS/LOGIN_AUTHENTICATION/myenv/lib/python3.8/site-packages/django/views/decorators/csrf.py", line 56, in wrapper_view
    return view_func(*args, **kwargs)
  File "/home/aakash/PROJECTS/LOGIN_AUTHENTICATION/myenv/lib/python3.8/site-packages/django/views/generic/base.py", line 104, in view
    return self.dispatch(request, *args, **kwargs)
  File "/home/aakash/PROJECTS/LOGIN_AUTHENTICATION/myenv/lib/python3.8/site-packages/rest_framework/views.py", line 509, in dispatch
    response = self.handle_exception(exc)
  File "/home/aakash/PROJECTS/LOGIN_AUTHENTICATION/myenv/lib/python3.8/site-packages/rest_framework/views.py", line 469, in handle_exception
    self.raise_uncaught_exception(exc)
  File "/home/aakash/PROJECTS/LOGIN_AUTHENTICATION/myenv/lib/python3.8/site-packages/rest_framework/views.py", line 480, in raise_uncaught_exception
    raise exc
  File "/home/aakash/PROJECTS/LOGIN_AUTHENTICATION/myenv/lib/python3.8/site-packages/rest_framework/views.py", line 506, in dispatch
    response = handler(request, *args, **kwargs)
  File "/home/aakash/PROJECTS/LOGIN_AUTHENTICATION/Authentication_System/myapp/views.py", line 419, in get
    minimum_id = Register.objects.all().aggregate(Min('id')).values_list('email')
AttributeError: 'dict' object has no attribute 'values_list'
2023-07-25 18:59:51 ERROR "GET /orm_implementation/ HTTP/1.1" 500 99924
2023-07-25 18:59:51 ERROR "GET /orm_implementation/ HTTP/1.1" 500 99924
2023-07-25 19:00:16 ERROR Internal Server Error: /orm_implementation/
Traceback (most recent call last):
  File "/home/aakash/PROJECTS/LOGIN_AUTHENTICATION/myenv/lib/python3.8/site-packages/django/core/handlers/exception.py", line 55, in inner
    response = get_response(request)
  File "/home/aakash/PROJECTS/LOGIN_AUTHENTICATION/myenv/lib/python3.8/site-packages/django/core/handlers/base.py", line 197, in _get_response
    response = wrapped_callback(request, *callback_args, **callback_kwargs)
  File "/home/aakash/PROJECTS/LOGIN_AUTHENTICATION/myenv/lib/python3.8/site-packages/django/views/decorators/csrf.py", line 56, in wrapper_view
    return view_func(*args, **kwargs)
  File "/home/aakash/PROJECTS/LOGIN_AUTHENTICATION/myenv/lib/python3.8/site-packages/django/views/generic/base.py", line 104, in view
    return self.dispatch(request, *args, **kwargs)
  File "/home/aakash/PROJECTS/LOGIN_AUTHENTICATION/myenv/lib/python3.8/site-packages/rest_framework/views.py", line 509, in dispatch
    response = self.handle_exception(exc)
  File "/home/aakash/PROJECTS/LOGIN_AUTHENTICATION/myenv/lib/python3.8/site-packages/rest_framework/views.py", line 469, in handle_exception
    self.raise_uncaught_exception(exc)
  File "/home/aakash/PROJECTS/LOGIN_AUTHENTICATION/myenv/lib/python3.8/site-packages/rest_framework/views.py", line 480, in raise_uncaught_exception
    raise exc
  File "/home/aakash/PROJECTS/LOGIN_AUTHENTICATION/myenv/lib/python3.8/site-packages/rest_framework/views.py", line 506, in dispatch
    response = handler(request, *args, **kwargs)
  File "/home/aakash/PROJECTS/LOGIN_AUTHENTICATION/Authentication_System/myapp/views.py", line 419, in get
    minimum_id = Register.objects.all().aggregate(Min('id')).values('email')
TypeError: values() takes no arguments (1 given)
2023-07-25 19:00:16 ERROR "GET /orm_implementation/ HTTP/1.1" 500 99712
2023-07-25 19:00:16 ERROR "GET /orm_implementation/ HTTP/1.1" 500 99712
2023-07-25 19:00:37 ERROR Internal Server Error: /orm_implementation/
Traceback (most recent call last):
  File "/home/aakash/PROJECTS/LOGIN_AUTHENTICATION/myenv/lib/python3.8/site-packages/django/core/handlers/exception.py", line 55, in inner
    response = get_response(request)
  File "/home/aakash/PROJECTS/LOGIN_AUTHENTICATION/myenv/lib/python3.8/site-packages/django/core/handlers/base.py", line 197, in _get_response
    response = wrapped_callback(request, *callback_args, **callback_kwargs)
  File "/home/aakash/PROJECTS/LOGIN_AUTHENTICATION/myenv/lib/python3.8/site-packages/django/views/decorators/csrf.py", line 56, in wrapper_view
    return view_func(*args, **kwargs)
  File "/home/aakash/PROJECTS/LOGIN_AUTHENTICATION/myenv/lib/python3.8/site-packages/django/views/generic/base.py", line 104, in view
    return self.dispatch(request, *args, **kwargs)
  File "/home/aakash/PROJECTS/LOGIN_AUTHENTICATION/myenv/lib/python3.8/site-packages/rest_framework/views.py", line 509, in dispatch
    response = self.handle_exception(exc)
  File "/home/aakash/PROJECTS/LOGIN_AUTHENTICATION/myenv/lib/python3.8/site-packages/rest_framework/views.py", line 469, in handle_exception
    self.raise_uncaught_exception(exc)
  File "/home/aakash/PROJECTS/LOGIN_AUTHENTICATION/myenv/lib/python3.8/site-packages/rest_framework/views.py", line 480, in raise_uncaught_exception
    raise exc
  File "/home/aakash/PROJECTS/LOGIN_AUTHENTICATION/myenv/lib/python3.8/site-packages/rest_framework/views.py", line 506, in dispatch
    response = handler(request, *args, **kwargs)
  File "/home/aakash/PROJECTS/LOGIN_AUTHENTICATION/Authentication_System/myapp/views.py", line 423, in get
    return JsonResponse(
  File "/home/aakash/PROJECTS/LOGIN_AUTHENTICATION/myenv/lib/python3.8/site-packages/django/http/response.py", line 731, in __init__
    data = json.dumps(data, cls=encoder, **json_dumps_params)
  File "/usr/lib/python3.8/json/__init__.py", line 234, in dumps
    return cls(
  File "/usr/lib/python3.8/json/encoder.py", line 199, in encode
    chunks = self.iterencode(o, _one_shot=True)
  File "/usr/lib/python3.8/json/encoder.py", line 257, in iterencode
    return _iterencode(o, 0)
  File "/home/aakash/PROJECTS/LOGIN_AUTHENTICATION/myenv/lib/python3.8/site-packages/django/core/serializers/json.py", line 106, in default
    return super().default(o)
  File "/usr/lib/python3.8/json/encoder.py", line 179, in default
    raise TypeError(f'Object of type {o.__class__.__name__} '
TypeError: Object of type dict_values is not JSON serializable
2023-07-25 19:00:37 ERROR "GET /orm_implementation/ HTTP/1.1" 500 149684
2023-07-25 19:00:37 ERROR "GET /orm_implementation/ HTTP/1.1" 500 149684
2023-07-25 19:44:41 ERROR invalid serializer data
2023-07-25 19:47:15 ERROR invalid serializer data
